Workbook

Sheet 对比上月表
A1: 加拿大-各门店2025年6月10日环比数据-星期二
A2: 项目 | B2: 内容 | C2: 加拿大一店 | D2: 加拿大二店 | E2: 加拿大三店 | F2: 加拿大四店 | G2: 加拿大五店 | H2: 加拿大六店 | I2: 加拿大七店 | J2: 加拿大片区
A3: 桌数 （考核） | B3: 今日总桌数 | C3: 188.8 | D3: 76 | E3: 190.8 | F3: 166 | G3: 248.9 | H3: 136.4 | I3: 177.2 | J3: =SUM(C3:I3) -> 1184.1
B4: 今日外卖桌数 | C4: 2.7 | D4: 2 | E4: 1 | F4: 0.7 | G4: 1 | H4: 0 | I4: 0 | J4: =SUM(C4:I4) -> 7.4
B5: 今日未计入考核桌数 | C5: 10.2 | D5: 8 | E5: 7.2 | F5: 4 | G5: 9.1 | H5: 10.6 | I5: 8.8 | J5: =SUM(C5:I5) -> 57.9
B6: 6月总桌数 | C6: 2009.9 | D6: 1032.7 | E6: 2339 | F6: 2361.5 | G6: 2425 | H6: 1667.8 | I6: 1915.8 | J6: =SUM(C6:I6) -> 13751.7
B7: 上月同期总桌数 | C7: 2219.4 | D7: 1213.9 | E7: 2433.9 | F7: 2766.2 | G7: 2725.6 | H7: 2038.5 | I7: 2192.4 | J7: =SUM(C7:I7) -> 15589.9
B8: 对比上月同期总桌数 | C8: 下降209.5桌 | D8: 下降181.2桌 | E8: 下降94.9桌 | F8: 下降404.7桌 | G8: 下降300.6桌 | H8: 下降370.7桌 | I8: 下降276.6桌 | J8: 下降1838.2桌
A9: 收入 （不含税-万加元） | B9: 今日营业收入 | C9: 2.614664 | D9: 1.097667 | E9: 2.405718 | F9: 1.961853 | G9: 3.301498 | H9: 1.606719 | I9: 2.334567 | J9: =SUM(C9:I9) -> 15.322686
B10: 本月截止目前营业收入 | C10: 31.209183 | D10: 15.025883 | E10: 30.108325 | F10: 30.659877 | G10: 33.479293 | H10: 21.640455 | I10: 27.499755 | J10: =SUM(C10:I10) -> 189.62277
B11: 上月截止目前营业收入 | C11: 33.740449 | D11: 17.148154 | E11: 31.631194 | F11: 38.194233 | G11: 39.59826 | H11: 26.588432 | I11: 32.873486 | J11: =SUM(C11:I11) -> 219.77421
B12: 环比营业收入变化 | C12: =C10-C11 -> -2.531266 | D12: =D10-D11 -> -2.122271 | E12: =E10-E11 -> -1.522869 | F12: =F10-F11 -> -7.534356 | G12: =G10-G11 -> -6.118967 | H12: =H10-H11 -> -4.947977 | I12: =I10-I11 -> -5.373731 | J12: =SUM(C12:I12) -> -30.151437
B13: 本月营业收入目标 | C13: 101.49 | D13: 53 | E13: 92.85 | F13: 110 | G13: 114.4 | H13: 71 | I13: 98 | J13: =SUM(C13:I13) -> 640.74
B14: 本月截止目标完成率 | C14: =IFERROR(C10/C13,0) -> 0.30750993 | D14: =IFERROR(D10/D13,0) -> 0.28350723 | E14: =IFERROR(E10/E13,0) -> 0.32426844 | F14: =IFERROR(F10/F13,0) -> 0.27872615 | G14: =IFERROR(G10/G13,0) -> 0.29265116 | H14: =IFERROR(H10/H13,0) -> 0.30479514 | I14: =IFERROR(I10/I13,0) -> 0.28060974 | J14: =IFERROR(J10/J13,0) -> 0.2959434
B15: 标准时间进度 | C15: 0.33333333 | D15: 0.33333333 | E15: 0.33333333 | F15: 0.33333333 | G15: 0.33333333 | H15: 0.33333333 | I15: 0.33333333 | J15: 0.33333333
B16: 优惠总金额 | C16: 2.470407 | D16: 1.482385 | E16: 2.073459 | F16: 1.720996 | G16: 2.142662 | H16: 1.069269 | I16: 2.128414 | J16: 13.087592
B17: 优惠占比 | C17: =C16/C10 -> 0.079156414 | D17: =D16/D10 -> 0.098655433 | E17: =E16/E10 -> 0.068866634 | F17: =F16/F10 -> 0.056131862 | G17: =G16/G10 -> 0.063999619 | H17: =H16/H10 -> 0.049410652 | I17: =I16/I10 -> 0.077397562 | J17: =J16/J10 -> 0.069019095
A18: 单桌消费 （不含税） | B18: 今日人均消费 | C18: =IFERROR(C9/C19*10000,0) -> 43.505225 | D18: =IFERROR(D9/D19*10000,0) -> 48.355374 | E18: =IFERROR(E9/E19*10000,0) -> 40.0953 | F18: =IFERROR(F9/F19*10000,0) -> 42.372635 | G18: =IFERROR(G9/G19*10000,0) -> 47.096976 | H18: =IFERROR(H9/H19*10000,0) -> 42.618541 | I18: =IFERROR(I9/I19*10000,0) -> 45.068861 | J18: =IFERROR(J9/J19*10000,0) -> 43.942317
B19: 今日消费客数 | C19: 601 | D19: 227 | E19: 600 | F19: 463 | G19: 701 | H19: 377 | I19: 518 | J19: =SUM(C19:I19) -> 3487
B20: 今日单桌消费 | C20: 131.39015 | D20: 130.67464 | E20: 121.50091 | F20: 115.40312 | G20: 127.96504 | H20: 109.30061 | I20: 125.51435 | J20: 123.37106
B21: 截止今日单桌消费 | C21: 148.19175 | D21: 135.73517 | E21: 124.466 | F21: 125.91325 | G21: 132.69637 | H21: 120.49251 | I21: 137.22433 | J21: 131.77399
B22: 上月单桌消费 | C22: 147.36359 | D22: 140.39085 | E22: 126.06659 | F22: 134.17736 | G22: 137.78599 | H22: 126.16302 | I22: 144.23054 | J22: 136.38968
B23: 环比上月变化 | C23: =C21-C22 -> 0.82815858 | D23: =D21-D22 -> -4.6556787 | E23: =E21-E22 -> -1.6005933 | F23: =F21-F22 -> -8.2641064 | G23: =G21-G22 -> -5.0896229 | H23: =H21-H22 -> -5.670504 | I23: =I21-I22 -> -7.0062106 | J23: =J21-J22 -> -4.6156872
A24: 翻台率 | B24: 名次 | C24: 第1名 | D24: 第2名 | E24: 第3名 | F24: 第4名 | G24: 第5名 | H24: 第6名 | I24: 第7名 | J24: 当月累计平均翻台率
B25: 6月10日翻台率排名 | C25: 加拿大五店 | D25: 加拿大三店 | E25: 加拿大一店 | F25: 加拿大七店 | G25: 加拿大六店 | H25: 加拿大四店 | I25: 加拿大二店 | J25: 3.67
C26: 4.53 | D26: 3.98 | E26: 3.56 | F26: 3.11 | G26: 2.44 | H26: 2.37 | I26: 2.11
B27: 6月平均翻台率排名 | C27: 加拿大三店 | D27: 加拿大五店 | E27: 加拿大一店 | F27: 加拿大四店 | G27: 加拿大七店 | H27: 加拿大六店 | I27: 加拿大二店
C28: 4.87 | D28: 4.41 | E28: 3.79 | F28: 3.37 | G28: 3.36 | H28: 2.98 | I28: 2.87

Sheet 对比去年同期表
A1: 加拿大-各门店2025年6月10日同比数据-星期二 | L1: 海外区域2025年6月份截至10日星期二翻台率前50%排名
A2: 分类 | B2: 内容 | C2: 西部 | F2: 东部 | J2: 加拿大片区 | L2: 排名 | M2: 国家 | N2: 翻台率（考核） | O2: 国家经理
C3: 加拿大一店 | D3: 加拿大二店 | E3: 加拿大七店 | F3: 加拿大三店 | G3: 加拿大四店 | H3: 加拿大五店 | I3: 加拿大六店 | L3: 1 | M3: 韩国 | N3: 5.57 | O3: 尹大进
A4: 桌数 对比同期数据 | B4: 本月截止目前 | C4: =对比上月表!C6 -> 2009.9 | D4: =对比上月表!D6 -> 1032.7 | E4: =对比上月表!I6 -> 1915.8 | F4: =对比上月表!E6 -> 2339 | G4: =对比上月表!F6 -> 2361.5 | H4: =对比上月表!G6 -> 2425 | I4: =对比上月表!H6 -> 1667.8 | J4: =SUM(C4:E4,F4:I4) -> 13751.7 | L4: 2 | M4: 越南（7家） | N4: 5.03 | O4: TRAN THUY TIEN
B5: 去年截止同期 | C5: 2382 | D5: 1224 | E5: 1962 | F5: 2856 | G5: 3111 | H5: 2813 | I5: 1482 | J5: =SUM(C5:E5,F5:I5) -> 15830 | L5: 3 | M5: 印度尼西亚 | N5: 4.53 | O5: 糜学征
B6: 对比去年同期 | C6: =C4-C5 -> -372.1 | D6: =D4-D5 -> -191.3 | E6: =E4-E5 -> -46.2 | F6: =F4-F5 -> -517 | G6: =G4-G5 -> -749.5 | H6: =H4-H5 -> -388 | I6: =I4-I5 -> 185.8 | J6: =SUM(C6:I6) -> -2078.3 | L6: 4 | M6: 阿联酋 | N6: 4.46 | O6: 李俊文
B7: 桌数增长率 | C7: =C6/C5 -> -0.15621327 | D7: =D6/D5 -> -0.15629085 | E7: =E6/E5 -> -0.023547401 | F7: =F6/F5 -> -0.18102241 | G7: =G6/G5 -> -0.24091932 | H7: =H6/H5 -> -0.13793103 | I7: =I6/I5 -> 0.12537112 | J7: =J6/J5 -> -0.13128869 | L7: 5 | M7: 澳大利亚 | N7: 3.97 | O7: 顾天辰
A8: 翻台率 对比同期数据 | B8: 本月截止目前 | C8: 3.7922642 | D8: 2.8686111 | E8: 3.3610526 | F8: 4.8729167 | G8: 3.3735714 | H8: 4.4090909 | I8: 2.9782143 | J8: 3.67 | L8: 6 | M8: 越南（9家） | N8: 3.91 | O8: 宁美雪
B9: 去年截止同期 | C9: 4.4943396 | D9: 3.4 | E9: 3.4421053 | F9: 5.95 | G9: 4.4442857 | H9: 5.1145455 | I9: 3.0619835 | J9: 4.3086554 | L9: 7 | M9: 加拿大 | N9: 3.84 | O9: 蒋冰遇
B10: 对比去年同期 | C10: =C8-C9 -> -0.70207547 | D10: =D8-D9 -> -0.53138889 | E10: =E8-E9 -> -0.081052632 | F10: =F8-F9 -> -1.0770833 | G10: =G8-G9 -> -1.0707143 | H10: =H8-H9 -> -0.70545455 | I10: =I8-I9 -> -0.083769185 | J10: =J8-J9 -> -0.63865542 | L10: 8 | M10: 日本 | N10: 3.83 | O10: 曲笑辰
B11: 翻台率增长率 | C11: =C10/C9 -> -0.15621327 | D11: =D10/D9 -> -0.15629085 | E11: =E10/E9 -> -0.023547401 | F11: =F10/F9 -> -0.18102241 | G11: =G10/G9 -> -0.24091932 | H11: =H10/H9 -> -0.13793103 | I11: =I10/I9 -> -0.027357818 | J11: =J10/J9 -> -0.14822615
A12: 营业收入 （不含税-万加元） | B12: 本月截止目前 | C12: =对比上月表!C10 -> 31.209183 | D12: =对比上月表!D10 -> 15.025883 | E12: =对比上月表!I10 -> 27.499755 | F12: =对比上月表!E10 -> 30.108325 | G12: =对比上月表!F10 -> 30.659877 | H12: =对比上月表!G10 -> 33.479293 | I12: =对比上月表!H10 -> 21.640455 | J12: =SUM(C12:E12,F12:I12) -> 189.62277 | O12: 日本 | P12: 3.88 | Q12: 曲笑辰
B13: 去年截止同期 | C13: 34.835776 | D13: 17.026405 | E13: 31.444181 | F13: 33.978298 | G13: 36.481554 | H13: 32.519742 | I13: 18.544788 | J13: 204.83074 | O13: 英国 | P13: 3.98 | Q13: LI WEIQI
B14: 对比去年同期 | C14: =C12-C13 -> -3.6265932 | D14: =D12-D13 -> -2.0005218 | E14: =E12-E13 -> -3.944426 | F14: =F12-F13 -> -3.8699732 | G14: =G12-G13 -> -5.821677 | H14: =H12-H13 -> 0.95955052 | I14: =I12-I13 -> 3.095667 | J14: =J12-J13 -> -15.207974 | O14: 马来西亚（8家） | P14: 3.93 | Q14: 朱国庆
B15: 收入增长率 | C15: =C14/C13 -> -0.10410542 | D15: =D14/D13 -> -0.11749525 | E15: =E14/E13 -> -0.12544216 | F15: =F14/F13 -> -0.11389544 | G15: =G14/G13 -> -0.15957865 | H15: =H14/H13 -> 0.029506707 | I15: =I14/I13 -> 0.16692922 | J15: =J14/J13 -> -0.074246538 | O15: 澳大利亚 | P15: 3.94 | Q15: 刘丽
A16: 单桌消费 对比同期数据 | B16: 本月截止目前 | C16: =对比上月表!C21 -> 148.19175 | D16: =对比上月表!D21 -> 135.73517 | E16: =对比上月表!I21 -> 137.22433 | F16: =对比上月表!E21 -> 124.466 | G16: =对比上月表!F21 -> 125.91325 | H16: =对比上月表!G21 -> 132.69637 | I16: =对比上月表!H21 -> 120.49251 | J16: =对比上月表!J21 -> 131.77399 | O16: 印度尼西亚 | P16: 6.75 | Q16: 糜学征
B17: 去年截止同期 | C17: 140.97845 | D17: 133.43577 | E17: 157.77311 | F17: 117.04546 | G17: 115.52107 | H17: 112.68102 | I17: 121.28704 | J17: 126.15392 | O17: 越南（7家） | P17: 6.72 | Q17: TRAN THUY TIEN
B18: 对比去年同期 | C18: =C16-C17 -> 7.2132973 | D18: =D16-D17 -> 2.2993931 | E18: =E16-E17 -> -20.548784 | F18: =F16-F17 -> 7.4205342 | G18: =G16-G17 -> 10.392182 | H18: =H16-H17 -> 20.015345 | I18: =I16-I17 -> -0.79452613 | J18: =J16-J17 -> 5.620067 | O18: 韩国 | P18: 6.44 | Q18: 尹大进
B19: 单桌消费增长率 | C19: =C18/C17 -> 0.051165955 | D19: =D18/D17 -> 0.017232209 | E19: =E18/E17 -> -0.13024263 | F19: =F18/F17 -> 0.063398734 | G19: =G18/G17 -> 0.089959194 | H19: =H18/H17 -> 0.17762836 | I19: =I18/I17 -> -0.0065507918 | J19: =J18/J17 -> 0.044549284 | O19: 越南（9家） | P19: 6.3 | Q19: 宁美雪
O20: 马来西亚（10家） | P20: 6.01 | Q20: 杜莹琦
O21: 加拿大 | P21: 5.93 | Q21: 蒋冰遇
B22: 校对 | C22: =C9-'分时段-上报'!D8 -> 0 | D22: =D9-'分时段-上报'!D13 -> 0 | E22: =E9-'分时段-上报'!D38 -> 0 | F22: =F9-'分时段-上报'!D18 -> 0 | G22: =G9-'分时段-上报'!D23 -> 0 | H22: =H9-'分时段-上报'!D28 -> 0 | I22: =I9-'分时段-上报'!D33 -> 0 | O22: 越南（1家） | P22: 5.6 | Q22: 郭淦
O23: 美国（7家） | P23: 4.66 | Q23: 王海锋
O24: 美国（6家） | P24: 4.47 | Q24: 王天龙
O25: 阿联酋 | P25: 6.04 | Q25: 李俊文
O26: 澳大利亚 | P26: 3.94 | Q26: 顾天辰
O27: 新加坡 | P27: 4.52 | Q27: 张涵之

Sheet 分时段-上报
A1: 门店分时段经营数据2025年6月vs2024年6月截至10日-星期二（考核）
A2: 门店名称 | B2: 分时段 | C2: 翻台率（考核） | E2: 本月目标 | F2: 目标差异 | G2: 同比差异 | H2: 45818 | I2: 45818 | J2: 桌数（考核） | L2: 同比差异
C3: 今年 | D3: 去年 | H3: 翻台率（考核） | I3: 桌数（考核） | J3: 今年 | K3: 去年
A4: 加拿大一店 | B4: 08:00-13:59 | C4: 0.72245283 | D4: 0.81698113 | E4: 0.85 | F4: =C4-E4 -> -0.12754717 | G4: =C4-D4 -> -0.094528302 | H4: 0.61509434 | I4: 32.6 | J4: 382.9 | K4: 433 | L4: =J4-K4 -> -50.1
A5: 加拿大一店 | B5: 14:00-16:59 | C5: 0.46320755 | D5: 0.57358491 | E5: 0.6 | F5: =C5-E5 -> -0.13679245 | G5: =C5-D5 -> -0.11037736 | H5: 0.49622642 | I5: 26.3 | J5: 245.5 | K5: 304 | L5: =J5-K5 -> -58.5
A6: 加拿大一店 | B6: 17:00-21:59 | C6: 1.850566 | D6: 2.1415094 | E6: 1.97 | F6: =C6-E6 -> -0.11943396 | G6: =C6-D6 -> -0.2909434 | H6: 1.6245283 | I6: 86.1 | J6: 980.8 | K6: 1135 | L6: =J6-K6 -> -154.2
A7: 加拿大一店 | B7: 22:00-(次)07:59 | C7: 0.75603774 | D7: 0.96226415 | E7: 0.78 | F7: =C7-E7 -> -0.023962264 | G7: =C7-D7 -> -0.20622642 | H7: 0.82641509 | I7: 43.8 | J7: 400.7 | K7: 510 | L7: =J7-K7 -> -109.3
A8: 加拿大一店汇总 | C8: 3.7922642 | D8: 4.4943396 | E8: 4.2 | F8: =C8-E8 -> -0.40773585 | G8: =C8-D8 -> -0.70207547 | H8: 3.5622642 | I8: 188.8 | J8: 2009.9 | K8: 2382 | L8: =J8-K8 -> -372.1
A9: 加拿大二店 | B9: 08:00-13:59 | C9: 0.51583333 | D9: 0.69444444 | E9: 0.5 | F9: =C9-E9 -> 0.015833333 | G9: =C9-D9 -> -0.17861111 | H9: 0.32777778 | I9: 11.8 | J9: 185.7 | K9: 250 | L9: =J9-K9 -> -64.3
A10: 加拿大二店 | B10: 14:00-16:59 | C10: 0.40861111 | D10: 0.45 | E10: 0.5 | F10: =C10-E10 -> -0.091388889 | G10: =C10-D10 -> -0.041388889 | H10: 0.45555556 | I10: 16.4 | J10: 147.1 | K10: 162 | L10: =J10-K10 -> -14.9
A11: 加拿大二店 | B11: 17:00-21:59 | C11: 1.5313889 | D11: 1.8694444 | E11: 1.8 | F11: =C11-E11 -> -0.26861111 | G11: =C11-D11 -> -0.33805556 | H11: 1.2277778 | I11: 44.2 | J11: 551.3 | K11: 673 | L11: =J11-K11 -> -121.7
A12: 加拿大二店 | B12: 22:00-(次)07:59 | C12: 0.41277778 | D12: 0.38611111 | E12: 0.7 | F12: =C12-E12 -> -0.28722222 | G12: =C12-D12 -> 0.026666667 | H12: 0.1 | I12: 3.6 | J12: 148.6 | K12: 139 | L12: =J12-K12 -> 9.6
A13: 加拿大二店汇总 | C13: 2.8686111 | D13: 3.4 | E13: 3.5 | F13: =C13-E13 -> -0.63138889 | G13: =C13-D13 -> -0.53138889 | H13: 2.1111111 | I13: 76 | J13: 1032.7 | K13: 1224 | L13: =J13-K13 -> -191.3
A14: 加拿大三店 | B14: 08:00-13:59 | C14: 1.055625 | D14: 1.5854167 | E14: 1.2 | F14: =C14-E14 -> -0.144375 | G14: =C14-D14 -> -0.52979167 | H14: 0.76458333 | I14: 36.7 | J14: 506.7 | K14: 761 | L14: =J14-K14 -> -254.3
A15: 加拿大三店 | B15: 14:00-16:59 | C15: 0.80291667 | D15: 1.28125 | E15: 1 | F15: =C15-E15 -> -0.19708333 | G15: =C15-D15 -> -0.47833333 | H15: 0.6625 | I15: 31.8 | J15: 385.4 | K15: 615 | L15: =J15-K15 -> -229.6
A16: 加拿大三店 | B16: 17:00-21:59 | C16: 2.2102083 | D16: 2.4479167 | E16: 2.2 | F16: =C16-E16 -> 0.010208333 | G16: =C16-D16 -> -0.23770833 | H16: 2.0708333 | I16: 99.4 | J16: 1060.9 | K16: 1175 | L16: =J16-K16 -> -114.1
A17: 加拿大三店 | B17: 22:00-(次)07:59 | C17: 0.80416667 | D17: 0.63541667 | E17: 0.8 | F17: =C17-E17 -> 0.0041666667 | G17: =C17-D17 -> 0.16875 | H17: 0.47708333 | I17: 22.9 | J17: 386 | K17: 305 | L17: =J17-K17 -> 81
A18: 加拿大三店汇总 | C18: 4.8729167 | D18: 5.95 | E18: 5.2 | F18: =C18-E18 -> -0.32708333 | G18: =C18-D18 -> -1.0770833 | H18: 3.975 | I18: 190.8 | J18: 2339 | K18: 2856 | L18: =J18-K18 -> -517
A19: 加拿大四店 | B19: 08:00-13:59 | C19: 0.60971429 | D19: 0.91571429 | E19: 0.61 | F19: =C19-E19 -> -0.00028571429 | G19: =C19-D19 -> -0.306 | H19: 0.56285714 | I19: 39.4 | J19: 426.8 | K19: 641 | L19: =J19-K19 -> -214.2
A20: 加拿大四店 | B20: 14:00-16:59 | C20: 0.43757143 | D20: 0.69285714 | E20: 0.53 | F20: =C20-E20 -> -0.092428571 | G20: =C20-D20 -> -0.25528571 | H20: 0.35285714 | I20: 24.7 | J20: 306.3 | K20: 485 | L20: =J20-K20 -> -178.7
A21: 加拿大四店 | B21: 17:00-21:59 | C21: 1.537 | D21: 1.8442857 | E21: 1.85 | F21: =C21-E21 -> -0.313 | G21: =C21-D21 -> -0.30728571 | H21: 0.84428571 | I21: 59.1 | J21: 1075.9 | K21: 1291 | L21: =J21-K21 -> -215.1
A22: 加拿大四店 | B22: 22:00-(次)07:59 | C22: 0.78928571 | D22: 0.99142857 | E22: 1.01 | F22: =C22-E22 -> -0.22071429 | G22: =C22-D22 -> -0.20214286 | H22: 0.61142857 | I22: 42.8 | J22: 552.5 | K22: 694 | L22: =J22-K22 -> -141.5
A23: 加拿大四店汇总 | C23: 3.3735714 | D23: 4.4442857 | E23: 4 | F23: =C23-E23 -> -0.62642857 | G23: =C23-D23 -> -1.0707143 | H23: 2.3714286 | I23: 166 | J23: 2361.5 | K23: 3111 | L23: =J23-K23 -> -749.5
A24: 加拿大五店 | B24: 08:00-13:59 | C24: 0.67018182 | D24: 0.86363636 | E24: 0.85 | F24: =C24-E24 -> -0.17981818 | G24: =C24-D24 -> -0.19345455 | H24: 0.66181818 | I24: 36.4 | J24: 368.6 | K24: 475 | L24: =J24-K24 -> -106.4
A25: 加拿大五店 | B25: 14:00-16:59 | C25: 0.66854545 | D25: 0.86363636 | E25: 0.75 | F25: =C25-E25 -> -0.081454545 | G25: =C25-D25 -> -0.19509091 | H25: 0.58181818 | I25: 32 | J25: 367.7 | K25: 475 | L25: =J25-K25 -> -107.3
A26: 加拿大五店 | B26: 17:00-21:59 | C26: 2.2325455 | D26: 2.5272727 | E26: 2.4 | F26: =C26-E26 -> -0.16745455 | G26: =C26-D26 -> -0.29472727 | H26: 2.4672727 | I26: 135.7 | J26: 1227.9 | K26: 1390 | L26: =J26-K26 -> -162.1
A27: 加拿大五店 | B27: 22:00-(次)07:59 | C27: 0.83781818 | D27: 0.86 | E27: 1.1 | F27: =C27-E27 -> -0.26218182 | G27: =C27-D27 -> -0.022181818 | H27: 0.81454545 | I27: 44.8 | J27: 460.8 | K27: 473 | L27: =J27-K27 -> -12.2
A28: 加拿大五店汇总 | C28: 4.4090909 | D28: 5.1145455 | E28: 5.1 | F28: =C28-E28 -> -0.69090909 | G28: =C28-D28 -> -0.70545455 | H28: 4.5254545 | I28: 248.9 | J28: 2425 | K28: 2813 | L28: =J28-K28 -> -388
A29: 加拿大六店 | B29: 08:00-13:59 | C29: 0.59875 | D29: 0.59504132 | E29: 0.6 | F29: =C29-E29 -> -0.00125 | G29: =C29-D29 -> 0.0037086777 | H29: 0.6375 | I29: 35.7 | J29: 335.3 | K29: 288 | L29: =J29-K29 -> 47.3
A30: 加拿大六店 | B30: 14:00-16:59 | C30: 0.34875 | D30: 0.3946281 | E30: 0.5 | F30: =C30-E30 -> -0.15125 | G30: =C30-D30 -> -0.045878099 | H30: 0.33392857 | I30: 18.7 | J30: 195.3 | K30: 191 | L30: =J30-K30 -> 4.3
A31: 加拿大六店 | B31: 17:00-21:59 | C31: 1.4880357 | D31: 1.6528926 | E31: 1.8 | F31: =C31-E31 -> -0.31196429 | G31: =C31-D31 -> -0.16485685 | H31: 1.0464286 | I31: 58.6 | J31: 833.3 | K31: 800 | L31: =J31-K31 -> 33.3
A32: 加拿大六店 | B32: 22:00-(次)07:59 | C32: 0.54267857 | D32: 0.41942149 | E32: 0.7 | F32: =C32-E32 -> -0.15732143 | G32: =C32-D32 -> 0.12325708 | H32: 0.41785714 | I32: 23.4 | J32: 303.9 | K32: 203 | L32: =J32-K32 -> 100.9
A33: 加拿大六店汇总 | C33: 2.9782143 | D33: 3.0619835 | E33: 3.6 | F33: =C33-E33 -> -0.62178571 | G33: =C33-D33 -> -0.083769185 | H33: 2.4357143 | I33: 136.4 | J33: 1667.8 | K33: 1482 | L33: =J33-K33 -> 185.8
A34: 加拿大七店 | B34: 08:00-13:59 | C34: 0.74298246 | D34: 0.67894737 | E34: 0.65 | F34: =C34-E34 -> 0.092982456 | G34: =C34-D34 -> 0.064035088 | H34: 0.85087719 | I34: 48.5 | J34: 423.5 | K34: 387 | L34: =J34-K34 -> 36.5
A35: 加拿大七店 | B35: 14:00-16:59 | C35: 0.4454386 | D35: 0.61052632 | E35: 0.65 | F35: =C35-E35 -> -0.2045614 | G35: =C35-D35 -> -0.16508772 | H35: 0.31403509 | I35: 17.9 | J35: 253.9 | K35: 348 | L35: =J35-K35 -> -94.1
A36: 加拿大七店 | B36: 17:00-21:59 | C36: 1.6221053 | D36: 1.9298246 | E36: 1.85 | F36: =C36-E36 -> -0.22789474 | G36: =C36-D36 -> -0.3077193 | H36: 1.5491228 | I36: 88.3 | J36: 924.6 | K36: 1100 | L36: =J36-K36 -> -175.4
A37: 加拿大七店 | B37: 22:00-(次)07:59 | C37: 0.55052632 | D37: 0.22280702 | E37: 0.7 | F37: =C37-E37 -> -0.14947368 | G37: =C37-D37 -> 0.3277193 | H37: 0.39473684 | I37: 22.5 | J37: 313.8 | K37: 127 | L37: =J37-K37 -> 186.8
A38: 加拿大七店汇总 | C38: 3.3610526 | D38: 3.4421053 | E38: 3.85 | F38: =C38-E38 -> -0.48894737 | G38: =C38-D38 -> -0.081052632 | H38: 3.1087719 | I38: 177.2 | J38: 1915.8 | K38: 1962 | L38: =J38-K38 -> -46.2
A39: 区域整体 | C39: 3.67 | D39: 4.3086554 | E39: 4.21 | F39: =C39-E39 -> -0.54 | G39: =C39-D39 -> -0.63865542 | H39: 3.1576 | I39: 1184.1 | J39: 13751.7 | K39: 15830 | L39: =J39-K39 -> -2078.3

Sheet 营业透视
A1: 日期 | B1: (全部)
B3: 列标签
B4: 5 | G4: 6 | L4: 求和项:营业桌数(考核)汇总 | M4: 求和项:营业桌数(考核)(外卖)汇总 | N4: 求和项:营业桌数汇总 | O4: 求和项:就餐人数汇总 | P4: 求和项:所有餐位数汇总
A5: 行标签 | B5: 求和项:营业桌数(考核) | C5: 求和项:营业桌数(考核)(外卖) | D5: 求和项:营业桌数 | E5: 求和项:就餐人数 | F5: 求和项:所有餐位数 | G5: 求和项:营业桌数(考核) | H5: 求和项:营业桌数(考核)(外卖) | I5: 求和项:营业桌数 | J5: 求和项:就餐人数 | K5: 求和项:所有餐位数
A6: 加拿大一店 | B6: 2219.4 | C6: 35.8 | D6: 2308 | E6: 7099 | F6: 530 | G6: 2009.9 | H6: 26.7 | I6: 2106 | J6: 6601 | K6: 530 | L6: 4229.3 | M6: 62.5 | N6: 4414 | O6: 13700 | P6: 1060
A7: 加拿大二店 | B7: 1213.9 | C7: 76.6 | D7: 1280 | E7: 3662 | F7: 360 | G7: 1032.7 | H7: 69 | I7: 1107 | J7: 3192 | K7: 360 | L7: 2246.6 | M7: 145.6 | N7: 2387 | O7: 6854 | P7: 720
A8: 加拿大三店 | B8: 2433.9 | C8: 24.8 | D8: 2537 | E8: 7998 | F8: 480 | G8: 2339 | H8: 24.9 | I8: 2419 | J8: 7783 | K8: 480 | L8: 4772.9 | M8: 49.7 | N8: 4956 | O8: 15781 | P8: 960
A9: 加拿大四店 | B9: 2766.2 | C9: 40.1 | D9: 2846 | E9: 8591 | F9: 700 | G9: 2361.5 | H9: 23 | I9: 2435 | J9: 7371 | K9: 700 | L9: 5127.7 | M9: 63.1 | N9: 5281 | O9: 15962 | P9: 1400
A10: 加拿大五店 | B10: 2725.6 | C10: 18 | D10: 2819 | E10: 7583 | F10: 550 | G10: 2425 | H10: 13 | I10: 2523 | J10: 6759 | K10: 550 | L10: 5150.6 | M10: 31 | N10: 5342 | O10: 14342 | P10: 1100
A11: 加拿大六店 | B11: 2038.5 | C11: 11 | D11: 2111 | E11: 6107 | F11: 560 | G11: 1667.8 | H11: 1 | I11: 1796 | J11: 5188 | K11: 560 | L11: 3706.3 | M11: 12 | N11: 3907 | O11: 11295 | P11: 1120
A12: 加拿大七店 | B12: 2192.4 | C12: 0.9 | D12: 2274 | E12: 7129 | F12: 570 | G12: 1915.8 | H12: 2 | I12: 2004 | J12: 6149 | K12: 570 | L12: 4108.2 | M12: 2.9 | N12: 4278 | O12: 13278 | P12: 1140
A13: 总计 | B13: 15589.9 | C13: 207.2 | D13: 16175 | E13: 48169 | F13: 3750 | G13: 13751.7 | H13: 159.6 | I13: 14390 | J13: 43043 | K13: 3750 | L13: 29341.6 | M13: 366.8 | N13: 30565 | O13: 91212 | P13: 7500
A26: 行标签 | B26: 求和项:营业桌数(考核) | C26: 求和项:营业桌数 | D26: 今日未计入考核桌数
A27: 加拿大一店 | B27: 188.8 | C27: 199 | D27: =C27-B27 -> 10.2
A28: 加拿大二店 | B28: 76 | C28: 84 | D28: =C28-B28 -> 8
A29: 加拿大三店 | B29: 190.8 | C29: 198 | D29: =C29-B29 -> 7.2
A30: 加拿大四店 | B30: 166 | C30: 170 | D30: =C30-B30 -> 4
A31: 加拿大五店 | B31: 248.9 | C31: 258 | D31: =C31-B31 -> 9.1
A32: 加拿大六店 | B32: 136.4 | C32: 147 | D32: =C32-B32 -> 10.6
A33: 加拿大七店 | B33: 177.2 | C33: 186 | D33: =C33-B33 -> 8.8
A34: 总计 | B34: 1184.1 | C34: 1242 | D34: =C34-B34 -> 57.9
A40: 行标签 | B40: 求和项:营业桌数(考核) | C40: 求和项:所有餐位数 | D40: 本月截至目前翻台率
A41: 加拿大一店 | B41: 2009.9 | C41: 530 | D41: =B41/C41 -> 3.7922642
A42: 加拿大二店 | B42: 1032.7 | C42: 360 | D42: =B42/C42 -> 2.8686111
A43: 加拿大三店 | B43: 2339 | C43: 480 | D43: =B43/C43 -> 4.8729167
A44: 加拿大四店 | B44: 2361.5 | C44: 700 | D44: =B44/C44 -> 3.3735714
A45: 加拿大五店 | B45: 2425 | C45: 550 | D45: =B45/C45 -> 4.4090909
A46: 加拿大六店 | B46: 1667.8 | C46: 560 | D46: =B46/C46 -> 2.9782143
A47: 加拿大七店 | B47: 1915.8 | C47: 570 | D47: =B47/C47 -> 3.3610526
A48: 总计 | B48: 13751.7 | C48: 3750 | D48: =B48/C48 -> 3.66712
A52: 行标签 | B52: 求和项:营业桌数(考核) | C52: 求和项:所有餐位数 | D52: 今日翻台率
A53: 加拿大一店 | B53: 188.8 | C53: 53 | D53: =B53/C53 -> 3.5622642
A54: 加拿大二店 | B54: 76 | C54: 36 | D54: =B54/C54 -> 2.1111111
A55: 加拿大三店 | B55: 190.8 | C55: 48 | D55: =B55/C55 -> 3.975
A56: 加拿大四店 | B56: 166 | C56: 70 | D56: =B56/C56 -> 2.3714286
A57: 加拿大五店 | B57: 248.9 | C57: 55 | D57: =B57/C57 -> 4.5254545
A58: 加拿大六店 | B58: 136.4 | C58: 56 | D58: =B58/C58 -> 2.4357143
A59: 加拿大七店 | B59: 177.2 | C59: 57 | D59: =B59/C59 -> 3.1087719
A60: 总计 | B60: 1184.1 | C60: 375 | D60: =B60/C60 -> 3.1576

Sheet 营业基础表
A1: 日期 | B1: 国家 | C1: 国家负责人 | D1: 门店名称 | E1: 开业时间 | F1: 节假日 | G1: 所有餐位数 | H1: 营业桌数 | I1: 营业桌数(考核) | J1: 翻台率(考核) | K1: 营业收入(不含税) | L1: 营业桌数(考核)(外卖) | M1: 就餐人数 | N1: 优惠总金额(不含税)
A2: 20250501 | B2: 加拿大 | C2: 蒋冰遇 | D2: 加拿大一店 | E2: 2018-12-18 | F2: 工作日 | G2: 53 | H2: 212 | I2: 205.3 | J2: 3.8735849 | K2: 29331.97 | L2: 0.9 | M2: 594 | N2: 2411.14
A3: 20250501 | B3: 加拿大 | C3: 蒋冰遇 | D3: 加拿大七店 | E3: 2024-05-01 | F3: 工作日 | G3: 57 | H3: 201 | I3: 196.5 | J3: 3.4473684 | K3: 28801.23 | L3: 0 | M3: 601 | N3: 1745.48
A4: 20250501 | B4: 加拿大 | C4: 蒋冰遇 | D4: 加拿大三店 | E4: 2020-08-17 | F4: 工作日 | G4: 48 | H4: 255 | I4: 242.4 | J4: 5.05 | K4: 27904.87 | L4: 4 | M4: 713 | N4: 1748.7
A5: 20250501 | B5: 加拿大 | C5: 蒋冰遇 | D5: 加拿大二店 | E5: 2020-07-27 | F5: 工作日 | G5: 36 | H5: 110 | I5: 102.2 | J5: 2.8388889 | K5: 13944.36 | L5: 6 | M5: 292 | N5: 1395.05
A6: 20250501 | B6: 加拿大 | C6: 蒋冰遇 | D6: 加拿大五店 | E6: 2022-10-03 | F6: 工作日 | G6: 55 | H6: 295 | I6: 287.1 | J6: 5.22 | K6: 54076.58 | L6: 0 | M6: 779 | N6: 1593.83
A7: 20250501 | B7: 加拿大 | C7: 蒋冰遇 | D7: 加拿大六店 | E7: 2024-01-09 | F7: 工作日 | G7: 56 | H7: 200 | I7: 195.6 | J7: 3.4928571 | K7: 26001.47 | L7: 3 | M7: 518 | N7: 1528.31
A8: 20250501 | B8: 加拿大 | C8: 蒋冰遇 | D8: 加拿大四店 | E8: 2020-10-30 | F8: 工作日 | G8: 70 | H8: 228 | I8: 221.4 | J8: 3.1628571 | K8: 32862.57 | L8: 0 | M8: 631 | N8: 1644.41
A9: 20250601 | B9: 加拿大 | C9: 蒋冰遇 | D9: 加拿大一店 | E9: 2018-12-18 | F9: 节假日 | G9: 53 | H9: 250 | I9: 239.4 | J9: 4.5169811 | K9: 41008.44 | L9: 3.6 | M9: 859 | N9: 2998.22
A10: 20250601 | B10: 加拿大 | C10: 蒋冰遇 | D10: 加拿大七店 | E10: 2024-05-01 | F10: 节假日 | G10: 57 | H10: 256 | I10: 247.1 | J10: 4.3350877 | K10: 39810.55 | L10: 1 | M10: 884 | N10: 2335.82
A11: 20250601 | B11: 加拿大 | C11: 蒋冰遇 | D11: 加拿大三店 | E11: 2020-08-17 | F11: 节假日 | G11: 48 | H11: 311 | I11: 300.7 | J11: 6.2645833 | K11: 44370.46 | L11: 5.5 | M11: 1068 | N11: 2457.75
A12: 20250601 | B12: 加拿大 | C12: 蒋冰遇 | D12: 加拿大二店 | E12: 2020-07-27 | F12: 节假日 | G12: 36 | H12: 131 | I12: 125.8 | J12: 3.4944444 | K12: 19405.98 | L12: 10 | M12: 391 | N12: 1364.34
A13: 20250601 | B13: 加拿大 | C13: 蒋冰遇 | D13: 加拿大五店 | E13: 2022-10-03 | F13: 节假日 | G13: 55 | H13: 270 | I13: 259.5 | J13: 4.7181818 | K13: 37907.32 | L13: 3 | M13: 731 | N13: 2167.77
... A211: 20240610 | B211: 加拿大 | C211: 蒋冰遇 | D211: 加拿大四店 | E211: 2020-10-30 | F211: 工作日 | G211: 70 | H211: 285 | I211: 280 | J211: 4 | K211: 32281.25 | L211: 4 | M211: 764 | N211: 1912.48
K216: =SUM(K142,K149,K156,K163,K170,K177,K184,K191,K198,K205)/10000 -> 36.577565

Sheet 去年营业基础表
A1: 日期 | B1: 国家 | C1: 国家负责人 | D1: 门店名称 | E1: 开业日期 | F1: 节假日 | G1: 所有餐位数 | H1: 营业桌数 | I1: 营业桌数(不含员工餐) | J1: 营业桌数(考核) | K1: 翻台率(不含员工餐) | L1: 翻台率(考核) | M1: 营业收入(含税) | N1: 营业桌数(考核)(外卖) | O1: 就餐人数 | P1: 优惠总金额(含税) | R1: 行标签 | S1: 求和项:营业桌数(考核) | T1: 求和项:所有餐位数 | U1: 去年同期翻台率（不含员工餐）
A2: 20240601 | B2: 加拿大 | C2: 蒋冰遇 | D2: 加拿大一店 | E2: 2018-12-18 | F2: 节假日 | G2: 53 | H2: 316 | I2: 311 | J2: 303 | K2: 5.8679245 | L2: 5.7169811 | M2: 50041.3 | N2: 6 | O2: 902 | P2: 2651.49 | R2: 加拿大一店 | S2: 2382 | T2: 530 | U2: =S2/T2 -> 4.4943396
A3: 20240601 | B3: 加拿大 | C3: 蒋冰遇 | D3: 加拿大七店 | E3: 2024-05-01 | F3: 节假日 | G3: 57 | H3: 244 | I3: 243 | J3: 242 | K3: 4.2631579 | L3: 4.245614 | M3: 43588.68 | N3: 0 | O3: 731 | P3: 1221.71 | R3: 加拿大二店 | S3: 1224 | T3: 360 | U3: =S3/T3 -> 3.4
A4: 20240601 | B4: 加拿大 | C4: 蒋冰遇 | D4: 加拿大三店 | E4: 2020-08-17 | F4: 节假日 | G4: 48 | H4: 318 | I4: 314 | J4: 311 | K4: 6.5416667 | L4: 6.4791667 | M4: 51319.64 | N4: 4 | O4: 1051 | P4: 2360.52 | R4: 加拿大三店 | S4: 2856 | T4: 480 | U4: =S4/T4 -> 5.95
A5: 20240601 | B5: 加拿大 | C5: 蒋冰遇 | D5: 加拿大二店 | E5: 2020-07-27 | F5: 节假日 | G5: 36 | H5: 172 | I5: 172 | J5: 171 | K5: 4.7777778 | L5: 4.75 | M5: 25872 | N5: 12 | O5: 455 | P5: 1276.87 | R5: 加拿大四店 | S5: 3111 | T5: 700 | U5: =S5/T5 -> 4.4442857
A6: 20240601 | B6: 加拿大 | C6: 蒋冰遇 | D6: 加拿大五店 | E6: 2022-10-03 | F6: 节假日 | G6: 55 | H6: 329 | I6: 327 | J6: 325 | K6: 5.9454545 | L6: 5.9090909 | M6: 48799.96 | N6: 10 | O6: 821 | P6: 1546.99 | R6: 加拿大五店 | S6: 2813 | T6: 550 | U6: =S6/T6 -> 5.1145455
A7: 20240601 | B7: 加拿大 | C7: 蒋冰遇 | D7: 加拿大六店 | E7: 2024-01-09 | F7: 节假日 | G7: 37 | H7: 189 | I7: 187 | J7: 186 | K7: 5.0540541 | L7: 5.027027 | M7: 29668.1 | N7: 0 | O7: 573 | P7: 1561.61 | R7: 加拿大六店 | S7: 1482 | T7: 484 | U7: =S7/T7 -> 3.0619835
A8: 20240601 | B8: 加拿大 | C8: 蒋冰遇 | D8: 加拿大四店 | E8: 2020-10-30 | F8: 节假日 | G8: 70 | H8: 381 | I8: 374 | J8: 377 | K8: 5.3428571 | L8: 5.3857143 | M8: 59782 | N8: 9 | O8: 1097 | P8: 2838.53 | R8: 加拿大七店 | S8: 1962 | T8: 570 | U8: =S8/T8 -> 3.4421053
A9: 20240602 | B9: 加拿大 | C9: 蒋冰遇 | D9: 加拿大一店 | E9: 2018-12-18 | F9: 节假日 | G9: 53 | H9: 286 | I9: 280 | J9: 279 | K9: 5.2830189 | L9: 5.2641509 | M9: 47106.75 | N9: 6 | O9: 860 | P9: 2304.16 | R9: 总计 | S9: 15830 | T9: 3674 | U9: =S9/T9 -> 4.3086554
A10: 20240602 | B10: 加拿大 | C10: 蒋冰遇 | D10: 加拿大七店 | E10: 2024-05-01 | F10: 节假日 | G10: 57 | H10: 242 | I10: 239 | J10: 240 | K10: 4.1929825 | L10: 4.2105263 | M10: 42293.05 | N10: 0 | O10: 748 | P10: 1152.85
A11: 20240602 | B11: 加拿大 | C11: 蒋冰遇 | D11: 加拿大三店 | E11: 2020-08-17 | F11: 节假日 | G11: 48 | H11: 307 | I11: 304 | J11: 305 | K11: 6.3333333 | L11: 6.3541667 | M11: 46521.45 | N11: 9 | O11: 955 | P11: 2107.64
A12: 20240602 | B12: 加拿大 | C12: 蒋冰遇 | D12: 加拿大二店 | E12: 2020-07-27 | F12: 节假日 | G12: 36 | H12: 163 | I12: 159 | J12: 157 | K12: 4.4166667 | L12: 4.3611111 | M12: 25565.15 | N12: 18 | O12: 417 | P12: 1453.92
A13: 20240602 | B13: 加拿大 | C13: 蒋冰遇 | D13: 加拿大五店 | E13: 2022-10-03 | F13: 节假日 | G13: 55 | H13: 293 | I13: 289 | J13: 282 | K13: 5.2545455 | L13: 5.1272727 | M13: 36903.2 | N13: 14 | O13: 666 | P13: 1594.68
A14: 20240602 | B14: 加拿大 | C14: 蒋冰遇 | D14: 加拿大六店 | E14: 2024-01-09 | F14: 节假日 | G14: 37 | H14: 170 | I14: 168 | J14: 167 | K14: 4.5405405 | L14: 4.5135135 | M14: 24357.9 | N14: 1 | O14: 513 | P14: 1496.06
A15: 20240602 | B15: 加拿大 | C15: 蒋冰遇 | D15: 加拿大四店 | E15: 2020-10-30 | F15: 节假日 | G15: 70 | H15: 345 | I15: 338 | J15: 338 | K15: 4.8285714 | L15: 4.8285714 | M15: 50368.04 | N15: 11 | O15: 943 | P15: 2189.03
A16: 20240603 | B16: 加拿大 | C16: 蒋冰遇 | D16: 加拿大一店 | E16: 2018-12-18 | F16: 工作日 | G16: 53 | H16: 204 | I16: 201 | J16: 199 | K16: 3.7924528 | L16: 3.754717 | M16: 27535.6 | N16: 5 | O16: 585 | P16: 1109.98
A17: 20240603 | B17: 加拿大 | C17: 蒋冰遇 | D17: 加拿大七店 | E17: 2024-05-01 | F17: 工作日 | G17: 57 | H17: 160 | I17: 157 | J17: 155 | K17: 2.754386 | L17: 2.7192982 | M17: 23839.93 | N17: 0 | O17: 393 | P17: 1808.53
A18: 20240603 | B18: 加拿大 | C18: 蒋冰遇 | D18: 加拿大三店 | E18: 2020-08-17 | F18: 工作日 | G18: 48 | H18: 248 | I18: 244 | J18: 244 | K18: 5.0833333 | L18: 5.0833333 | M18: 28390.31 | N18: 2 | O18: 720 | P18: 1407.66
A19: 20240603 | B19: 加拿大 | C19: 蒋冰遇 | D19: 加拿大二店 | E19: 2020-07-27 | F19: 工作日 | G19: 36 | H19: 112 | I19: 108 | J19: 107 | K19: 3 | L19: 2.9722222 | M19: 14192.4 | N19: 16 | O19: 249 | P19: 736.62
A20: 20240603 | B20: 加拿大 | C20: 蒋冰遇 | D20: 加拿大五店 | E20: 2022-10-03 | F20: 工作日 | G20: 55 | H20: 219 | I20: 217 | J20: 211 | K20: 3.9454545 | L20: 3.8363636 | M20: 27688.31 | N20: 13 | O20: 518 | P20: 1606.72
A21: 20240603 | B21: 加拿大 | C21: 蒋冰遇 | D21: 加拿大六店 | E21: 2024-01-09 | F21: 工作日 | G21: 37 | H21: 120 | I21: 112 | J21: 115 | K21: 3.027027 | L21: 3.1081081 | M21: 17030.6 | N21: 0 | O21: 364 | P21: 1041.14
... A71: 20240610 | B71: 加拿大 | C71: 蒋冰遇 | D71: 加拿大四店 | E71: 2020-10-30 | F71: 工作日 | G71: 70 | H71: 285 | I71: 279 | J71: 280 | K71: 3.9857143 | L71: 4 | M71: 32281.25 | N71: 4 | O71: 764 | P71: 1912.48

Sheet 去年同期
A1: 日期 | B1: 国家 | C1: 大区经理 | D1: 门店名称 | E1: 开业日期 | F1: 节假日 | G1: 所有餐位数 | H1: 营业桌数 | I1: 营业桌数(不含员工餐) | J1: 营业桌数(考核) | K1: 翻台率(不含员工餐) | L1: 翻台率(考核) | M1: 营业收入(含税) | N1: 营业桌数(考核)(外卖) | O1: 就餐人数 | P1: 优惠总金额(含税) | R1: 行标签 | S1: 求和项:营业桌数(不含员工餐) | T1: 求和项:营业收入(含税)
A2: 20240630 | B2: 加拿大 | C2: 蒋冰遇 | D2: 加拿大一店 | E2: 2018-12-18 | F2: 节假日 | G2: 53 | H2: 282 | I2: 281 | J2: 271 | K2: 5.3018868 | L2: 5.1132075 | M2: 49406.3 | N2: 1 | O2: 867 | P2: 2879.85 | R2: 加拿大一店 | S2: 7476 | T2: 1130854.9
A3: 20240630 | B3: 加拿大 | C3: 蒋冰遇 | D3: 加拿大七店 | E3: 2024-05-01 | F3: 节假日 | G3: 57 | H3: 243 | I3: 241 | J3: 237 | K3: 4.2280702 | L3: 4.1578947 | M3: 42560.88 | N3: 0 | O3: 784 | P3: 1868.26 | R3: 加拿大二店 | S3: 4012 | T3: 569212.95
A4: 20240630 | B4: 加拿大 | C4: 蒋冰遇 | D4: 加拿大三店 | E4: 2020-08-17 | F4: 节假日 | G4: 48 | H4: 324 | I4: 322 | J4: 321 | K4: 6.7083333 | L4: 6.6875 | M4: 48882.75 | N4: 7 | O4: 1056 | P4: 1602.82 | R4: 加拿大三店 | S4: 8903 | T4: 1165041.5
A5: 20240630 | B5: 加拿大 | C5: 蒋冰遇 | D5: 加拿大二店 | E5: 2020-07-27 | F5: 节假日 | G5: 36 | H5: 150 | I5: 150 | J5: 147 | K5: 4.1666667 | L5: 4.0833333 | M5: 22729.75 | N5: 18 | O5: 370 | P5: 738.92 | R5: 加拿大四店 | S5: 9405 | T5: 1234924.7
A6: 20240630 | B6: 加拿大 | C6: 蒋冰遇 | D6: 加拿大五店 | E6: 2022-10-03 | F6: 节假日 | G6: 55 | H6: 348 | I6: 348 | J6: 342 | K6: 6.3272727 | L6: 6.2181818 | M6: 43781.85 | N6: 28 | O6: 818 | P6: 1233.62 | R6: 加拿大五店 | S6: 8958 | T6: 1121608.6
A7: 20240630 | B7: 加拿大 | C7: 蒋冰遇 | D7: 加拿大六店 | E7: 2024-01-09 | F7: 节假日 | G7: 56 | H7: 254 | I7: 253 | J7: 248 | K7: 4.5178571 | L7: 4.4285714 | M7: 34275.5 | N7: 15 | O7: 693 | P7: 1605.72 | R7: 加拿大六店 | S7: 5114 | T7: 699406.15
A8: 20240630 | B8: 加拿大 | C8: 蒋冰遇 | D8: 加拿大四店 | E8: 2020-10-30 | F8: 节假日 | G8: 70 | H8: 380 | I8: 380 | J8: 375 | K8: 5.4285714 | L8: 5.3571429 | M8: 53069.3 | N8: 8 | O8: 1072 | P8: 2028.59 | R8: 加拿大七店 | S8: 6031 | T8: 1012388.9
A9: 20240629 | B9: 加拿大 | C9: 蒋冰遇 | D9: 加拿大一店 | E9: 2018-12-18 | F9: 节假日 | G9: 53 | H9: 269 | I9: 264 | J9: 260 | K9: 4.9811321 | L9: 4.9056604 | M9: 46761.5 | N9: 5 | O9: 820 | P9: 1925.84 | R9: 总计 | S9: 49899 | T9: 6933437.8
A10: 20240629 | B10: 加拿大 | C10: 蒋冰遇 | D10: 加拿大七店 | E10: 2024-05-01 | F10: 节假日 | G10: 57 | H10: 227 | I10: 225 | J10: 224 | K10: 3.9473684 | L10: 3.9298246 | M10: 38593.82 | N10: 0 | O10: 709 | P10: 1612.22
A11: 20240629 | B11: 加拿大 | C11: 蒋冰遇 | D11: 加拿大三店 | E11: 2020-08-17 | F11: 节假日 | G11: 48 | H11: 304 | I11: 304 | J11: 302 | K11: 6.3333333 | L11: 6.2916667 | M11: 47264.2 | N11: 8 | O11: 958 | P11: 2062.25
A12: 20240629 | B12: 加拿大 | C12: 蒋冰遇 | D12: 加拿大二店 | E12: 2020-07-27 | F12: 节假日 | G12: 36 | H12: 141 | I12: 140 | J12: 138 | K12: 3.8888889 | L12: 3.8333333 | M12: 19589.6 | N12: 13 | O12: 359 | P12: 687.06 | R12: 行标签 | S12: 求和项:营业桌数(不含员工餐) | T12: 求和项:营业收入(含税) | U12: 税率 | V12: 单桌消费
A13: 20240629 | B13: 加拿大 | C13: 蒋冰遇 | D13: 加拿大五店 | E13: 2022-10-03 | F13: 节假日 | G13: 55 | H13: 315 | I13: 314 | J13: 311 | K13: 5.7090909 | L13: 5.6545455 | M13: 42643.05 | N13: 25 | O13: 735 | P13: 1178.62 | R13: 加拿大一店 | S13: 7476 | T13: 1130854.9 | U13: 1.05 | V13: =T13/S13/U13 -> 144.06163
A14: 20240629 | B14: 加拿大 | C14: 蒋冰遇 | D14: 加拿大六店 | E14: 2024-01-09 | F14: 节假日 | G14: 56 | H14: 209 | I14: 207 | J14: 205 | K14: 3.6964286 | L14: 3.6607143 | M14: 30963.4 | N14: 1 | O14: 620 | P14: 1335.85 | R14: 加拿大二店 | S14: 4012 | T14: 569212.95 | U14: 1.05 | V14: =T14/S14/U14 -> 135.12153
A15: 20240629 | B15: 加拿大 | C15: 蒋冰遇 | D15: 加拿大四店 | E15: 2020-10-30 | F15: 节假日 | G15: 70 | H15: 354 | I15: 353 | J15: 351 | K15: 5.0428571 | L15: 5.0142857 | M15: 58320.8 | N15: 7 | O15: 1039 | P15: 2039.66 | R15: 加拿大三店 | S15: 8903 | T15: 1165041.5 | U15: 1.13 | V15: =T15/S15/U15 -> 115.8048
A16: 20240628 | B16: 加拿大 | C16: 蒋冰遇 | D16: 加拿大一店 | E16: 2018-12-18 | F16: 节假日 | G16: 53 | H16: 288 | I16: 285 | J16: 280 | K16: 5.3773585 | L16: 5.2830189 | M16: 43467.85 | N16: 5 | O16: 864 | P16: 2994.88 | R16: 加拿大四店 | S16: 9405 | T16: 1234924.7 | U16: 1.13 | V16: =T16/S16/U16 -> 116.19923
A17: 20240628 | B17: 加拿大 | C17: 蒋冰遇 | D17: 加拿大七店 | E17: 2024-05-01 | F17: 节假日 | G17: 57 | H17: 225 | I17: 221 | J17: 220 | K17: 3.877193 | L17: 3.8596491 | M17: 38212.79 | N17: 0 | O17: 656 | P17: 2998.14 | R17: 加拿大五店 | S17: 8958 | T17: 1121608.6 | U17: 1.13 | V17: =T17/S17/U17 -> 110.80308
A18: 20240628 | B18: 加拿大 | C18: 蒋冰遇 | D18: 加拿大三店 | E18: 2020-08-17 | F18: 节假日 | G18: 48 | H18: 376 | I18: 373 | J18: 376 | K18: 7.7708333 | L18: 7.8333333 | M18: 42847.25 | N18: 6 | O18: 1127 | P18: 2683.08 | R18: 加拿大六店 | S18: 5114 | T18: 699406.15 | U18: 1.1495 | V18: =T18/S18/U18 -> 118.97611
A19: 20240628 | B19: 加拿大 | C19: 蒋冰遇 | D19: 加拿大二店 | E19: 2020-07-27 | F19: 节假日 | G19: 36 | H19: 150 | I19: 146 | J19: 146 | K19: 4.0555556 | L19: 4.0555556 | M19: 19647.5 | N19: 10 | O19: 374 | P19: 828.99 | R19: 加拿大七店 | S19: 6031 | T19: 1012388.9 | U19: 1.05 | V19: =T19/S19/U19 -> 159.87065
A20: 20240628 | B20: 加拿大 | C20: 蒋冰遇 | D20: 加拿大五店 | E20: 2022-10-03 | F20: 节假日 | G20: 55 | H20: 377 | I20: 374 | J20: 369 | K20: 6.8 | L20: 6.7090909 | M20: 44790.5 | N20: 21 | O20: 875 | P20: 2168.47
A21: 20240628 | B21: 加拿大 | C21: 蒋冰遇 | D21: 加拿大六店 | E21: 2024-01-09 | F21: 节假日 | G21: 56 | H21: 237 | I21: 233 | J21: 233 | K21: 4.1607143 | L21: 4.1607143 | M21: 29590.85 | N21: 4 | O21: 656 | P21: 1698.5
A22: 20240628 | B22: 加拿大 | C22: 蒋冰遇 | D22: 加拿大四店 | E22: 2020-10-30 | F22: 节假日 | G22: 70 | H22: 363 | I22: 359 | J22: 360 | K22: 5.1285714 | L22: 5.1428571 | M22: 43351.74 | N22: 5 | O22: 972 | P22: 2292.67
A23: 20240627 | B23: 加拿大 | C23: 蒋冰遇 | D23: 加拿大一店 | E23: 2018-12-18 | F23: 工作日 | G23: 53 | H23: 324 | I23: 310 | J23: 299 | K23: 5.8490566 | L23: 5.6415094 | M23: 41152.25 | N23: 2 | O23: 922 | P23: 2748.99
A24: 20240627 | B24: 加拿大 | C24: 蒋冰遇 | D24: 加拿大七店 | E24: 2024-05-01 | F24: 工作日 | G24: 57 | H24: 201 | I24: 195 | J24: 196 | K24: 3.4210526 | L24: 3.4385965 | M24: 33437.47 | N24: 0 | O24: 580 | P24: 3180.39
A25: 20240627 | B25: 加拿大 | C25: 蒋冰遇 | D25: 加拿大三店 | E25: 2020-08-17 | F25: 工作日 | G25: 48 | H25: 345 | I25: 343 | J25: 339 | K25: 7.1458333 | L25: 7.0625 | M25: 40242.1 | N25: 2 | O25: 1042 | P25: 2368
A26: 20240627 | B26: 加拿大 | C26: 蒋冰遇 | D26: 加拿大二店 | E26: 2020-07-27 | F26: 工作日 | G26: 36 | H26: 177 | I26: 175 | J26: 175 | K26: 4.8611111 | L26: 4.8611111 | M26: 23460 | N26: 16 | O26: 451 | P26: 842.2
A27: 20240627 | B27: 加拿大 | C27: 蒋冰遇 | D27: 加拿大五店 | E27: 2022-10-03 | F27: 工作日 | G27: 55 | H27: 305 | I27: 304 | J27: 302 | K27: 5.5272727 | L27: 5.4909091 | M27: 35373.75 | N27: 20 | O27: 709 | P27: 1679.58
A28: 20240627 | B28: 加拿大 | C28: 蒋冰遇 | D28: 加拿大六店 | E28: 2024-01-09 | F28: 工作日 | G28: 56 | H28: 195 | I28: 191 | J28: 184 | K28: 3.4107143 | L28: 3.2857143 | M28: 22524.4 | N28: 10 | O28: 496 | P28: 1656.82
A29: 20240627 | B29: 加拿大 | C29: 蒋冰遇 | D29: 加拿大四店 | E29: 2020-10-30 | F29: 工作日 | G29: 70 | H29: 367 | I29: 361 | J29: 359 | K29: 5.1571429 | L29: 5.1285714 | M29: 40969.15 | N29: 2 | O29: 997 | P29: 2599.18
A30: 20240626 | B30: 加拿大 | C30: 蒋冰遇 | D30: 加拿大一店 | E30: 2018-12-18 | F30: 工作日 | G30: 53 | H30: 267 | I30: 261 | J30: 256 | K30: 4.9245283 | L30: 4.8301887 | M30: 35847.55 | N30: 3 | O30: 730 | P30: 2069.01
A31: 20240626 | B31: 加拿大 | C31: 蒋冰遇 | D31: 加拿大七店 | E31: 2024-05-01 | F31: 工作日 | G31: 57 | H31: 176 | I31: 175 | J31: 174 | K31: 3.0701754 | L31: 3.0526316 | M31: 27109.66 | N31: 0 | O31: 489 | P31: 2367.53
... A211: 20240601 | B211: 加拿大 | C211: 蒋冰遇 | D211: 加拿大四店 | E211: 2020-10-30 | F211: 节假日 | G211: 70 | H211: 381 | I211: 374 | J211: 377 | K211: 5.3428571 | L211: 5.3857143 | M211: 59782 | N211: 9 | O211: 1097 | P211: 2838.53

Sheet 21号之后
A1: 日期 | B1: 月份 | C1: 国家 | D1: 国家负责人 | E1: 门店名称 | F1: 开业日期 | G1: 节假日 | H1: 所以餐位数 | I1: 营业桌数 | J1: 营业桌数(考核) | K1: 翻台率(考核) | L1: 营业收入(含税) | M1: 营业桌数(考核)(外卖) | N1: 就餐人数 | O1: 优惠总金额(含税) | Q1: 日期 | R1: (全部)
A2: 20250521 | B2: 5 | C2: 加拿大 | D2: 蒋冰遇 | E2: 加拿大一店 | F2: 2018-12-18 | G2: 工作日 | H2: 53 | I2: 197 | J2: 183.3 | K2: 3.4584906 | L2: 26102.77 | M2: 1.7 | N2: 542 | O2: 1682.32
A3: 20250521 | B3: 5 | C3: 加拿大 | D3: 蒋冰遇 | E3: 加拿大七店 | F3: 2024-05-01 | G3: 工作日 | H3: 57 | I3: 172 | J3: 163.7 | K3: 2.8719298 | L3: 24034.67 | M3: 0 | N3: 514 | O3: 1504.11 | Q3: 行标签 | R3: 求和项:营业桌数(考核) | S3: 求和项:所以餐位数 | T3: 上周同期翻台率
A4: 20250521 | B4: 5 | C4: 加拿大 | D4: 蒋冰遇 | E4: 加拿大三店 | F4: 2020-08-17 | G4: 工作日 | H4: 48 | I4: 208 | J4: 193.4 | K4: 4.0291667 | L4: 22841.66 | M4: 0.7 | N4: 589 | O4: 1862.01 | Q4: 加拿大一店 | R4: 4310.5 | S4: 1113 | T4: =R4/S4 -> 3.8728661
A5: 20250521 | B5: 5 | C5: 加拿大 | D5: 蒋冰遇 | E5: 加拿大二店 | F5: 2020-07-27 | G5: 工作日 | H5: 36 | I5: 91 | J5: 87.6 | K5: 2.4333333 | L5: 11109.3 | M5: 17 | N5: 213 | O5: 912.97 | Q5: 加拿大二店 | R5: 2439.3 | S5: 756 | T5: =R5/S5 -> 3.2265873
A6: 20250521 | B6: 5 | C6: 加拿大 | D6: 蒋冰遇 | E6: 加拿大五店 | F6: 2022-10-03 | G6: 工作日 | H6: 55 | I6: 221 | J6: 215.3 | K6: 3.9145455 | L6: 30031.64 | M6: 2 | N6: 571 | O6: 1044.08 | Q6: 加拿大三店 | R6: 4825 | S6: 1008 | T6: =R6/S6 -> 4.7867063
A7: 20250521 | B7: 5 | C7: 加拿大 | D7: 蒋冰遇 | E7: 加拿大六店 | F7: 2024-01-09 | G7: 工作日 | H7: 56 | I7: 130 | J7: 120.7 | K7: 2.1553571 | L7: 15243.3 | M7: 0 | N7: 319 | O7: 1073.22 | Q7: 加拿大四店 | R7: 5033.5 | S7: 1470 | T7: =R7/S7 -> 3.4241497
A8: 20250521 | B8: 5 | C8: 加拿大 | D8: 蒋冰遇 | E8: 加拿大四店 | F8: 2020-10-30 | G8: 工作日 | H8: 70 | I8: 181 | J8: 174.9 | K8: 2.4985714 | L8: 24267.67 | M8: 0 | N8: 499 | O8: 1183.39 | Q8: 加拿大五店 | R8: 5315.4 | S8: 1155 | T8: =R8/S8 -> 4.6020779
A9: 20250522 | B9: 5 | C9: 加拿大 | D9: 蒋冰遇 | E9: 加拿大一店 | F9: 2018-12-18 | G9: 工作日 | H9: 53 | I9: 171 | J9: 163.4 | K9: 3.0830189 | L9: 22560.54 | M9: 2.4 | N9: 473 | O9: 1927.01 | Q9: 加拿大六店 | R9: 3765.9 | S9: 1176 | T9: =R9/S9 -> 3.2022959
A10: 20250522 | B10: 5 | C10: 加拿大 | D10: 蒋冰遇 | E10: 加拿大七店 | F10: 2024-05-01 | G10: 工作日 | H10: 57 | I10: 181 | J10: 173.2 | K10: 3.0385965 | L10: 24019.98 | M10: 1 | N10: 526 | O10: 1800.28 | Q10: 加拿大七店 | R10: 4195.4 | S10: 1197 | T10: =R10/S10 -> 3.504929
A11: 20250522 | B11: 5 | C11: 加拿大 | D11: 蒋冰遇 | E11: 加拿大三店 | F11: 2020-08-17 | G11: 工作日 | H11: 48 | I11: 202 | J11: 193.6 | K11: 4.0333333 | L11: 23315.01 | M11: 3.1 | N11: 590 | O11: 1722.8 | Q11: 总计 | R11: 29885 | S11: 7875 | T11: =R11/S11 -> 3.7949206
A12: 20250522 | B12: 5 | C12: 加拿大 | D12: 蒋冰遇 | E12: 加拿大二店 | F12: 2020-07-27 | G12: 工作日 | H12: 36 | I12: 129 | J12: 124.2 | K12: 3.45 | L12: 22899.56 | M12: 18 | N12: 320 | O12: 1229.36
A13: 20250522 | B13: 5 | C13: 加拿大 | D13: 蒋冰遇 | E13: 加拿大五店 | F13: 2022-10-03 | G13: 工作日 | H13: 55 | I13: 226 | J13: 221.9 | K13: 4.0345455 | L13: 31176.25 | M13: 0 | N13: 590 | O13: 713.71
A14: 20250522 | B14: 5 | C14: 加拿大 | D14: 蒋冰遇 | E14: 加拿大六店 | F14: 2024-01-09 | G14: 工作日 | H14: 56 | I14: 169 | J14: 161.8 | K14: 2.8892857 | L14: 20822.97 | M14: 0 | N14: 433 | O14: 1031.62
A15: 20250522 | B15: 5 | C15: 加拿大 | D15: 蒋冰遇 | E15: 加拿大四店 | F15: 2020-10-30 | G15: 工作日 | H15: 70 | I15: 215 | J15: 206.3 | K15: 2.9471429 | L15: 26370.11 | M15: 0 | N15: 570 | O15: 1273.99
A16: 20250523 | B16: 5 | C16: 加拿大 | D16: 蒋冰遇 | E16: 加拿大一店 | F16: 2018-12-18 | G16: 节假日 | H16: 53 | I16: 226 | J16: 219 | K16: 4.1320755 | L16: 31041.86 | M16: 1.7 | N16: 638 | O16: 2200.79
A17: 20250523 | B17: 5 | C17: 加拿大 | D17: 蒋冰遇 | E17: 加拿大七店 | F17: 2024-05-01 | G17: 节假日 | H17: 57 | I17: 282 | J17: 271.5 | K17: 4.7631579 | L17: 37461.54 | M17: 0 | N17: 841 | O17: 3196.22
A18: 20250523 | B18: 5 | C18: 加拿大 | D18: 蒋冰遇 | E18: 加拿大三店 | F18: 2020-08-17 | G18: 节假日 | H18: 48 | I18: 307 | J18: 298.1 | K18: 6.2104167 | L18: 35751.12 | M18: 5.5 | N18: 939 | O18: 2171.74
A19: 20250523 | B19: 5 | C19: 加拿大 | D19: 蒋冰遇 | E19: 加拿大二店 | F19: 2020-07-27 | G19: 节假日 | H19: 36 | I19: 151 | J19: 144 | K19: 4 | L19: 21739.68 | M19: 2 | N19: 461 | O19: 1531.7
A20: 20250523 | B20: 5 | C20: 加拿大 | D20: 蒋冰遇 | E20: 加拿大五店 | F20: 2022-10-03 | G20: 节假日 | H20: 55 | I20: 304 | J20: 298.8 | K20: 5.4327273 | L20: 40825.44 | M20: 3 | N20: 841 | O20: 1522.01
A21: 20250523 | B21: 5 | C21: 加拿大 | D21: 蒋冰遇 | E21: 加拿大六店 | F21: 2024-01-09 | G21: 节假日 | H21: 56 | I21: 238 | J21: 229.7 | K21: 4.1017857 | L21: 30234.85 | M21: 0 | N21: 708 | O21: 1985.44
A22: 20250523 | B22: 5 | C22: 加拿大 | D22: 蒋冰遇 | E22: 加拿大四店 | F22: 2020-10-30 | G22: 节假日 | H22: 70 | I22: 333 | J22: 320.2 | K22: 4.5742857 | L22: 42877.7 | M22: 3 | N22: 950 | O22: 2543.52
A23: 20250524 | B23: 5 | C23: 加拿大 | D23: 蒋冰遇 | E23: 加拿大一店 | F23: 2018-12-18 | G23: 节假日 | H23: 53 | I23: 264 | J23: 255.1 | K23: 4.8132075 | L23: 40932.14 | M23: 3 | N23: 831 | O23: 2865.78
... A148: 20250610 | B148: 6 | C148: 加拿大 | D148: 蒋冰遇 | E148: 加拿大四店 | F148: 2020-10-30 | G148: 工作日 | H148: 70 | I148: 170 | J148: 166 | K148: 2.3714286 | L148: 19618.53 | M148: 0.7 | N148: 463 | O148: 1251.68

Sheet 分时段透视
A2: 日期 | B2: (全部)
B4: 列标签
B5: 求和项:所有餐位数 | D5: 求和项:营业桌数(考核) | F5: 求和项:所有餐位数汇总 | G5: 求和项:营业桌数(考核)汇总
A6: 行标签 | B6: 2025 | C6: 2024 | D6: 2025 | E6: 2024 | I6: 今年 | J6: 去年
A7: 加拿大一店 | B7: 2120 | C7: 2120 | D7: 2009.9 | E7: 2382 | F7: 4240 | G7: 4391.9 | I7: =D7/B8 -> 3.7922642 | J7: =E7/C8 -> 4.4943396
A8: 08:00-13:59 | B8: 530 | C8: 530 | D8: 382.9 | E8: 433 | F8: 1060 | G8: 815.9 | I8: =D8/B8 -> 0.72245283 | J8: =E8/C8 -> 0.81698113
A9: 14:00-16:59 | B9: 530 | C9: 530 | D9: 245.5 | E9: 304 | F9: 1060 | G9: 549.5 | I9: =D9/B9 -> 0.46320755 | J9: =E9/C9 -> 0.57358491
A10: 17:00-21:59 | B10: 530 | C10: 530 | D10: 980.8 | E10: 1135 | F10: 1060 | G10: 2115.8 | I10: =D10/B10 -> 1.850566 | J10: =E10/C10 -> 2.1415094
A11: 22:00-(次)07:59 | B11: 530 | C11: 530 | D11: 400.7 | E11: 510 | F11: 1060 | G11: 910.7 | I11: =D11/B11 -> 0.75603774 | J11: =E11/C11 -> 0.96226415
A12: 加拿大二店 | B12: 1440 | C12: 1440 | D12: 1032.7 | E12: 1224 | F12: 2880 | G12: 2256.7 | I12: =D12/B13 -> 2.8686111 | J12: =E12/C13 -> 3.4
A13: 08:00-13:59 | B13: 360 | C13: 360 | D13: 185.7 | E13: 250 | F13: 720 | G13: 435.7 | I13: =D13/B13 -> 0.51583333 | J13: =E13/C13 -> 0.69444444
A14: 14:00-16:59 | B14: 360 | C14: 360 | D14: 147.1 | E14: 162 | F14: 720 | G14: 309.1 | I14: =D14/B14 -> 0.40861111 | J14: =E14/C14 -> 0.45
A15: 17:00-21:59 | B15: 360 | C15: 360 | D15: 551.3 | E15: 673 | F15: 720 | G15: 1224.3 | I15: =D15/B15 -> 1.5313889 | J15: =E15/C15 -> 1.8694444
A16: 22:00-(次)07:59 | B16: 360 | C16: 360 | D16: 148.6 | E16: 139 | F16: 720 | G16: 287.6 | I16: =D16/B16 -> 0.41277778 | J16: =E16/C16 -> 0.38611111
A17: 加拿大三店 | B17: 1920 | C17: 1920 | D17: 2339 | E17: 2856 | F17: 3840 | G17: 5195 | I17: =D17/B18 -> 4.8729167 | J17: =E17/C18 -> 5.95
A18: 08:00-13:59 | B18: 480 | C18: 480 | D18: 506.7 | E18: 761 | F18: 960 | G18: 1267.7 | I18: =D18/B18 -> 1.055625 | J18: =E18/C18 -> 1.5854167
A19: 14:00-16:59 | B19: 480 | C19: 480 | D19: 385.4 | E19: 615 | F19: 960 | G19: 1000.4 | I19: =D19/B19 -> 0.80291667 | J19: =E19/C19 -> 1.28125
A20: 17:00-21:59 | B20: 480 | C20: 480 | D20: 1060.9 | E20: 1175 | F20: 960 | G20: 2235.9 | I20: =D20/B20 -> 2.2102083 | J20: =E20/C20 -> 2.4479167
A21: 22:00-(次)07:59 | B21: 480 | C21: 480 | D21: 386 | E21: 305 | F21: 960 | G21: 691 | I21: =D21/B21 -> 0.80416667 | J21: =E21/C21 -> 0.63541667
A22: 加拿大四店 | B22: 2800 | C22: 2800 | D22: 2361.5 | E22: 3111 | F22: 5600 | G22: 5472.5 | I22: =D22/B23 -> 3.3735714 | J22: =E22/C23 -> 4.4442857
A23: 08:00-13:59 | B23: 700 | C23: 700 | D23: 426.8 | E23: 641 | F23: 1400 | G23: 1067.8 | I23: =D23/B23 -> 0.60971429 | J23: =E23/C23 -> 0.91571429
A24: 14:00-16:59 | B24: 700 | C24: 700 | D24: 306.3 | E24: 485 | F24: 1400 | G24: 791.3 | I24: =D24/B24 -> 0.43757143 | J24: =E24/C24 -> 0.69285714
A25: 17:00-21:59 | B25: 700 | C25: 700 | D25: 1075.9 | E25: 1291 | F25: 1400 | G25: 2366.9 | I25: =D25/B25 -> 1.537 | J25: =E25/C25 -> 1.8442857
A26: 22:00-(次)07:59 | B26: 700 | C26: 700 | D26: 552.5 | E26: 694 | F26: 1400 | G26: 1246.5 | I26: =D26/B26 -> 0.78928571 | J26: =E26/C26 -> 0.99142857
A27: 加拿大五店 | B27: 2200 | C27: 2200 | D27: 2425 | E27: 2813 | F27: 4400 | G27: 5238 | I27: =D27/B28 -> 4.4090909 | J27: =E27/C28 -> 5.1145455
A28: 08:00-13:59 | B28: 550 | C28: 550 | D28: 368.6 | E28: 475 | F28: 1100 | G28: 843.6 | I28: =D28/B28 -> 0.67018182 | J28: =E28/C28 -> 0.86363636
A29: 14:00-16:59 | B29: 550 | C29: 550 | D29: 367.7 | E29: 475 | F29: 1100 | G29: 842.7 | I29: =D29/B29 -> 0.66854545 | J29: =E29/C29 -> 0.86363636
A30: 17:00-21:59 | B30: 550 | C30: 550 | D30: 1227.9 | E30: 1390 | F30: 1100 | G30: 2617.9 | I30: =D30/B30 -> 2.2325455 | J30: =E30/C30 -> 2.5272727
A31: 22:00-(次)07:59 | B31: 550 | C31: 550 | D31: 460.8 | E31: 473 | F31: 1100 | G31: 933.8 | I31: =D31/B31 -> 0.83781818 | J31: =E31/C31 -> 0.86
A32: 加拿大六店 | B32: 2240 | C32: 1936 | D32: 1667.8 | E32: 1482 | F32: 4176 | G32: 3149.8 | I32: =D32/B33 -> 2.9782143 | J32: =E32/C33 -> 3.0619835
A33: 08:00-13:59 | B33: 560 | C33: 484 | D33: 335.3 | E33: 288 | F33: 1044 | G33: 623.3 | I33: =D33/B33 -> 0.59875 | J33: =E33/C33 -> 0.59504132
A34: 14:00-16:59 | B34: 560 | C34: 484 | D34: 195.3 | E34: 191 | F34: 1044 | G34: 386.3 | I34: =D34/B34 -> 0.34875 | J34: =E34/C34 -> 0.3946281
A35: 17:00-21:59 | B35: 560 | C35: 484 | D35: 833.3 | E35: 800 | F35: 1044 | G35: 1633.3 | I35: =D35/B35 -> 1.4880357 | J35: =E35/C35 -> 1.6528926
A36: 22:00-(次)07:59 | B36: 560 | C36: 484 | D36: 303.9 | E36: 203 | F36: 1044 | G36: 506.9 | I36: =D36/B36 -> 0.54267857 | J36: =E36/C36 -> 0.41942149
A37: 加拿大七店 | B37: 2280 | C37: 2280 | D37: 1915.8 | E37: 1962 | F37: 4560 | G37: 3877.8 | I37: =D37/B38 -> 3.3610526 | J37: =E37/C38 -> 3.4421053
A38: 08:00-13:59 | B38: 570 | C38: 570 | D38: 423.5 | E38: 387 | F38: 1140 | G38: 810.5 | I38: =D38/B38 -> 0.74298246 | J38: =E38/C38 -> 0.67894737
A39: 14:00-16:59 | B39: 570 | C39: 570 | D39: 253.9 | E39: 348 | F39: 1140 | G39: 601.9 | I39: =D39/B39 -> 0.4454386 | J39: =E39/C39 -> 0.61052632
A40: 17:00-21:59 | B40: 570 | C40: 570 | D40: 924.6 | E40: 1100 | F40: 1140 | G40: 2024.6 | I40: =D40/B40 -> 1.6221053 | J40: =E40/C40 -> 1.9298246
A41: 22:00-(次)07:59 | B41: 570 | C41: 570 | D41: 313.8 | E41: 127 | F41: 1140 | G41: 440.8 | I41: =D41/B41 -> 0.55052632 | J41: =E41/C41 -> 0.22280702
A42: 总计 | B42: 15000 | C42: 14696 | D42: 13751.7 | E42: 15830 | F42: 29696 | G42: 29581.7 | I42: =D42/SUM(B8,B13,B18,B23,B28,B33,B38) -> 3.66712 | J42: =E42/SUM(C8,C13,C18,C23,C28,C33,C38) -> 4.3086554

Sheet 分时段基础表
A1: 日期 | B1: 年份 | C1: 日期 | D1: 国家 | E1: 国家负责人 | F1: 门店名称 | G1: 分时段 | H1: 节假日 | I1: 所有餐位数 | J1: 营业桌数(考核) | K1: 翻台率(考核)
A2: 20240601 | B2: 2024 | C2: 01号 | D2: 加拿大 | E2: 蒋冰遇 | F2: 加拿大一店 | G2: 08:00-13:59 | H2: 节假日 | I2: 53 | J2: 65 | K2: 1.2264151
A3: 20240601 | B3: 2024 | C3: 01号 | D3: 加拿大 | E3: 蒋冰遇 | F3: 加拿大一店 | G3: 14:00-16:59 | H3: 节假日 | I3: 53 | J3: 43 | K3: 0.81132075
A4: 20240601 | B4: 2024 | C4: 01号 | D4: 加拿大 | E4: 蒋冰遇 | F4: 加拿大一店 | G4: 17:00-21:59 | H4: 节假日 | I4: 53 | J4: 136 | K4: 2.5660377
A5: 20240601 | B5: 2024 | C5: 01号 | D5: 加拿大 | E5: 蒋冰遇 | F5: 加拿大一店 | G5: 22:00-(次)07:59 | H5: 节假日 | I5: 53 | J5: 59 | K5: 1.1132075
A6: 20240601 | B6: 2024 | C6: 01号 | D6: 加拿大 | E6: 蒋冰遇 | F6: 加拿大七店 | G6: 08:00-13:59 | H6: 节假日 | I6: 57 | J6: 62 | K6: 1.0877193
A7: 20240601 | B7: 2024 | C7: 01号 | D7: 加拿大 | E7: 蒋冰遇 | F7: 加拿大七店 | G7: 14:00-16:59 | H7: 节假日 | I7: 57 | J7: 53 | K7: 0.92982456
A8: 20240601 | B8: 2024 | C8: 01号 | D8: 加拿大 | E8: 蒋冰遇 | F8: 加拿大七店 | G8: 17:00-21:59 | H8: 节假日 | I8: 57 | J8: 127 | K8: 2.2280702
A9: 20240601 | B9: 2024 | C9: 01号 | D9: 加拿大 | E9: 蒋冰遇 | F9: 加拿大七店 | G9: 22:00-(次)07:59 | H9: 节假日 | I9: 57 | J9: 0 | K9: 0
A10: 20240601 | B10: 2024 | C10: 01号 | D10: 加拿大 | E10: 蒋冰遇 | F10: 加拿大三店 | G10: 08:00-13:59 | H10: 节假日 | I10: 48 | J10: 77 | K10: 1.6041667
A11: 20240601 | B11: 2024 | C11: 01号 | D11: 加拿大 | E11: 蒋冰遇 | F11: 加拿大三店 | G11: 14:00-16:59 | H11: 节假日 | I11: 48 | J11: 79 | K11: 1.6458333
A12: 20240601 | B12: 2024 | C12: 01号 | D12: 加拿大 | E12: 蒋冰遇 | F12: 加拿大三店 | G12: 17:00-21:59 | H12: 节假日 | I12: 48 | J12: 125 | K12: 2.6041667
A13: 20240601 | B13: 2024 | C13: 01号 | D13: 加拿大 | E13: 蒋冰遇 | F13: 加拿大三店 | G13: 22:00-(次)07:59 | H13: 节假日 | I13: 48 | J13: 30 | K13: 0.625
... A29: 20240601 | B29: 2024 | C29: 01号 | D29: 加拿大 | E29: 蒋冰遇 | F29: 加拿大四店 | G29: 22:00-(次)07:59 | H29: 节假日 | I29: 70 | J29: 80 | K29: 1.1428571
A30: 20250501 | B30: 2025 | C30: 01号 | D30: 加拿大 | E30: 蒋冰遇 | F30: 加拿大一店 | G30: 08:00-13:59 | H30: 工作日 | I30: 53 | J30: 35.5 | K30: 0.66981132
A31: 20250501 | B31: 2025 | C31: 01号 | D31: 加拿大 | E31: 蒋冰遇 | F31: 加拿大一店 | G31: 14:00-16:59 | H31: 工作日 | I31: 53 | J31: 22.5 | K31: 0.4245283
A32: 20250501 | B32: 2025 | C32: 01号 | D32: 加拿大 | E32: 蒋冰遇 | F32: 加拿大一店 | G32: 17:00-21:59 | H32: 工作日 | I32: 53 | J32: 104.7 | K32: 1.9754717
A33: 20250501 | B33: 2025 | C33: 01号 | D33: 加拿大 | E33: 蒋冰遇 | F33: 加拿大一店 | G33: 22:00-(次)07:59 | H33: 工作日 | I33: 53 | J33: 42.6 | K33: 0.80377358
A34: 20250501 | B34: 2025 | C34: 01号 | D34: 加拿大 | E34: 蒋冰遇 | F34: 加拿大七店 | G34: 08:00-13:59 | H34: 工作日 | I34: 57 | J34: 41.3 | K34: 0.7245614
A35: 20250501 | B35: 2025 | C35: 01号 | D35: 加拿大 | E35: 蒋冰遇 | F35: 加拿大七店 | G35: 14:00-16:59 | H35: 工作日 | I35: 57 | J35: 29.8 | K35: 0.52280702
A36: 20250501 | B36: 2025 | C36: 01号 | D36: 加拿大 | E36: 蒋冰遇 | F36: 加拿大七店 | G36: 17:00-21:59 | H36: 工作日 | I36: 57 | J36: 85.4 | K36: 1.4982456
A37: 20250501 | B37: 2025 | C37: 01号 | D37: 加拿大 | E37: 蒋冰遇 | F37: 加拿大七店 | G37: 22:00-(次)07:59 | H37: 工作日 | I37: 57 | J37: 40 | K37: 0.70175439
A38: 20250501 | B38: 2025 | C38: 01号 | D38: 加拿大 | E38: 蒋冰遇 | F38: 加拿大三店 | G38: 08:00-13:59 | H38: 工作日 | I38: 48 | J38: 56.8 | K38: 1.1833333
A39: 20250501 | B39: 2025 | C39: 01号 | D39: 加拿大 | E39: 蒋冰遇 | F39: 加拿大三店 | G39: 14:00-16:59 | H39: 工作日 | I39: 48 | J39: 47.1 | K39: 0.98125
A40: 20250501 | B40: 2025 | C40: 01号 | D40: 加拿大 | E40: 蒋冰遇 | F40: 加拿大三店 | G40: 17:00-21:59 | H40: 工作日 | I40: 48 | J40: 104.6 | K40: 2.1791667
A41: 20250501 | B41: 2025 | C41: 01号 | D41: 加拿大 | E41: 蒋冰遇 | F41: 加拿大三店 | G41: 22:00-(次)07:59 | H41: 工作日 | I41: 48 | J41: 33.9 | K41: 0.70625
... A57: 20250501 | B57: 2025 | C57: 01号 | D57: 加拿大 | E57: 蒋冰遇 | F57: 加拿大四店 | G57: 22:00-(次)07:59 | H57: 工作日 | I57: 70 | J57: 59.6 | K57: 0.85142857
A58: 20250601 | B58: 2025 | C58: 01号 | D58: 加拿大 | E58: 蒋冰遇 | F58: 加拿大一店 | G58: 08:00-13:59 | H58: 节假日 | I58: 53 | J58: 52.6 | K58: 0.99245283
A59: 20250601 | B59: 2025 | C59: 01号 | D59: 加拿大 | E59: 蒋冰遇 | F59: 加拿大一店 | G59: 14:00-16:59 | H59: 节假日 | I59: 53 | J59: 38.2 | K59: 0.72075472
A60: 20250601 | B60: 2025 | C60: 01号 | D60: 加拿大 | E60: 蒋冰遇 | F60: 加拿大一店 | G60: 17:00-21:59 | H60: 节假日 | I60: 53 | J60: 116.9 | K60: 2.2056604
A61: 20250601 | B61: 2025 | C61: 01号 | D61: 加拿大 | E61: 蒋冰遇 | F61: 加拿大一店 | G61: 22:00-(次)07:59 | H61: 节假日 | I61: 53 | J61: 31.7 | K61: 0.59811321
A62: 20250601 | B62: 2025 | C62: 01号 | D62: 加拿大 | E62: 蒋冰遇 | F62: 加拿大七店 | G62: 08:00-13:59 | H62: 节假日 | I62: 57 | J62: 62.5 | K62: 1.0964912
A63: 20250601 | B63: 2025 | C63: 01号 | D63: 加拿大 | E63: 蒋冰遇 | F63: 加拿大七店 | G63: 14:00-16:59 | H63: 节假日 | I63: 57 | J63: 41.4 | K63: 0.72631579
A64: 20250601 | B64: 2025 | C64: 01号 | D64: 加拿大 | E64: 蒋冰遇 | F64: 加拿大七店 | G64: 17:00-21:59 | H64: 节假日 | I64: 57 | J64: 117.2 | K64: 2.0561404
A65: 20250601 | B65: 2025 | C65: 01号 | D65: 加拿大 | E65: 蒋冰遇 | F65: 加拿大七店 | G65: 22:00-(次)07:59 | H65: 节假日 | I65: 57 | J65: 26 | K65: 0.45614035
A66: 20250601 | B66: 2025 | C66: 01号 | D66: 加拿大 | E66: 蒋冰遇 | F66: 加拿大三店 | G66: 08:00-13:59 | H66: 节假日 | I66: 48 | J66: 70.2 | K66: 1.4625
A67: 20250601 | B67: 2025 | C67: 01号 | D67: 加拿大 | E67: 蒋冰遇 | F67: 加拿大三店 | G67: 14:00-16:59 | H67: 节假日 | I67: 48 | J67: 60.9 | K67: 1.26875
A68: 20250601 | B68: 2025 | C68: 01号 | D68: 加拿大 | E68: 蒋冰遇 | F68: 加拿大三店 | G68: 17:00-21:59 | H68: 节假日 | I68: 48 | J68: 125.9 | K68: 2.6229167
A69: 20250601 | B69: 2025 | C69: 01号 | D69: 加拿大 | E69: 蒋冰遇 | F69: 加拿大三店 | G69: 22:00-(次)07:59 | H69: 节假日 | I69: 48 | J69: 43.7 | K69: 0.91041667
... A141: 20240602 | B141: 2024 | C141: 02号 | D141: 加拿大 | E141: 蒋冰遇 | F141: 加拿大四店 | G141: 22:00-(次)07:59 | H141: 节假日 | I141: 70 | J141: 71 | K141: 1.0142857
...

Sheet 月经营目标
K1: 美金 | L1: 美金
B2: 大区经理 | C2: 国家负责人 | D2: 门店 | E2: 翻台率 | F2: 单桌消费 | G2: 收入（加币） | H2: 人工占比 | I2: 经营净利润 | J2: 汇率 | K2: 单桌消费 | L2: 收入
B3: 蒋冰遇 | C3: 蒋冰遇 | D3: 加拿大一店 | E3: 4.2 | F3: 151.97664 | G3: 1014900 | H3: 0.41 | I3: 50000 | J3: 0.695265 | K3: 105.66404 | L3: 705624.45
B4: 蒋冰遇 | C4: 蒋冰遇 | D4: 加拿大二店 | E4: 3.5 | F4: 140.21164 | G4: 530000 | H4: 0.42 | I4: 10000 | J4: 0.695265 | K4: 97.484246 | L4: 368490.45
B5: 蒋冰遇 | C5: 蒋冰遇 | D5: 加拿大三店 | E5: 5.2 | F5: 123.9984 | G5: 928500 | H5: 0.385 | I5: 80000 | J5: 0.695265 | K5: 86.211746 | L5: 645553.55
B6: 蒋冰遇 | C6: 蒋冰遇 | D6: 加拿大四店 | E6: 4 | F6: 130.95238 | G6: 1100000 | H6: 0.385 | I6: 121002 | J6: 0.695265 | K6: 91.046607 | L6: 764791.5
B7: 蒋冰遇 | C7: 蒋冰遇 | D7: 加拿大五店 | E7: 5.1 | F7: 135.94771 | G7: 1144000 | H7: 0.385 | I7: 122350.8 | J7: 0.695265 | K7: 94.519686 | L7: 795383.16
B8: 蒋冰遇 | C8: 蒋冰遇 | D8: 加拿大六店 | E8: 3.6 | F8: 117.39418 | G8: 710000 | H8: 0.39 | I8: 30000 | J8: 0.695265 | K8: 81.620064 | L8: 493638.15
B9: 蒋冰遇 | C9: 蒋冰遇 | D9: 加拿大七店 | E9: 3.85 | F9: 148.85699 | G9: 980000 | H9: 0.41 | I9: 50000 | J9: 0.695265 | K9: 103.49506 | L9: 681359.7

Sheet 上月数据
A2: 20240731 | B2: 加拿大一店 | C2: 加拿大二店 | D2: 加拿大三店 | E2: 加拿大四店 | F2: 加拿大五店 | G2: 加拿大六店 | H2: 加拿大七店 | I2: 加拿大片区
A3: 今日总桌数
A4: 今日外卖桌数（考核）
A5: 今日未计入考核桌数
A6: 今日营业收入（不含税-万加币）
A7: 本月截止目前营业收入（不含税-万加元）
A8: 本月营业收入目标（不含税-万加元）
A9: 营业收入目标完成率（截至目前收入/收入目标）
A10: 时间进度(目前日期/本月天数）
A11: 优惠总金额（不含税-万加元）
A12: 优惠占比
A13: 本月截至目前单桌消费 | B13: 147.36359 | C13: 140.39085 | D13: 126.06659 | E13: 134.17736 | F13: 137.78599 | G13: 126.16302 | H13: 144.23054 | I13: 136.38968
A14: 去年同期月份单桌消费
A15: 对比去年同期
A16: 上月单桌消费
A17: 环比上月
A18: 今日单桌消费
A19: 今日消费客数
A20: 今日人均消费
A21: 本月截至目前翻台率
A22: 上月翻台率
A23: 对比上月
A24: 今日翻台率
A25: 上周同期翻台率
... A34: 7月31日翻台率排名
A35: 0
A36: 7月平均翻台率排名
A37: 0
