Workbook

Sheet CA07-本月-盘点结果
A1: 行号 | B1: 物料编码 | C1: 物料名称 | D1: 库存数量 | E1: 盘点数量 | F1: 单位 | G1: 单位编码 | H1: 单位描述 | I1: 使用数量 | J1: 单价 | K1: 本月使用金额 | L1: 上月使用金额 | M1: 对比 | N1: 备注（每月刷新） | O1: 回复 | P1: 分类
A2: 1 | B2: 4509073 | C2: "猪骨膏（SOMI，2.2LB*10包/箱）" | D2: 737 | E2: 330 | F2: 磅（美国） | G2: LB | H2: 磅（美国） | I2: =D2-E2 -> 407 | J2: =VLOOKUP(B2,本月系统单价mb5b!$B:$P,15,0) -> 9.6444776 | K2: =I2*J2 -> 3925.3024 | L2: =IFERROR(VLOOKUP(B2,上月数量需更新!A:C,3,0),0) -> 1540.02 | M2: =K2-L2 -> 2385.2824 | P2: =VLOOKUP(B2,物料分类!B:F,5,0) -> 成本-锅底类
A3: 201 | B3: 8011286 | C3: 易拉罐PET瓶（小口盖，100个/箱） | D3: 6400 | E3: 1900 | F3: 个 | G3: Z05 | H3: 个 | I3: =D3-E3 -> 4500 | J3: =VLOOKUP(B3,本月系统单价mb5b!$B:$P,15,0) -> 0.54213437 | K3: =I3*J3 -> 2439.6047 | L3: =IFERROR(VLOOKUP(B3,上月数量需更新!A:C,3,0),0) -> 2607.27 | M3: =K3-L3 -> -167.66531 | P3: =VLOOKUP(B3,物料分类!B:F,5,0) -> 物料消耗
A4: 3 | B4: 8014686 | C4: 320咖啡杯（30个/箱） | D4: 30 | E4: 30 | F4: 个 | G4: Z05 | H4: 个 | I4: =D4-E4 -> 0 | J4: =VLOOKUP(B4,本月系统单价mb5b!$B:$P,15,0) -> 8.3946667 | K4: =I4*J4 -> 0 | L4: =IFERROR(VLOOKUP(B4,上月数量需更新!A:C,3,0),0) -> 251.84 | M4: =K4-L4 -> -251.84 | P4: =VLOOKUP(B4,物料分类!B:F,5,0) -> 服务费
A5: 4 | B5: 8014689 | C5: 320折叠椅（30个/箱） | D5: 50 | E5: 50 | F5: 个 | G5: Z05 | H5: 个 | I5: =D5-E5 -> 0 | J5: =VLOOKUP(B5,本月系统单价mb5b!$B:$P,15,0) -> 12.5544 | K5: =I5*J5 -> 0 | L5: =IFERROR(VLOOKUP(B5,上月数量需更新!A:C,3,0),0) -> 125.55 | M5: =K5-L5 -> -125.55 | P5: =VLOOKUP(B5,物料分类!B:F,5,0) -> 服务费
A6: 5 | B6: 8014621 | C6: 320毛绒骰子（配套地贴使用，4个/套） | D6: 19 | E6: 19 | F6: 套 | G6: Z16 | H6: 套 | I6: =D6-E6 -> 0 | J6: =VLOOKUP(B6,本月系统单价mb5b!$B:$P,15,0) -> 62.245789 | K6: =I6*J6 -> 0 | L6: =IFERROR(VLOOKUP(B6,上月数量需更新!A:C,3,0),0) -> 0 | M6: =K6-L6 -> 0 | P6: =VLOOKUP(B6,物料分类!B:F,5,0) -> 服务费
A7: 197 | B7: 8011401 | C7: 无纺布打包袋（27.5*17*24CM） | D7: 11000 | E7: 3000 | F7: 个 | G7: Z05 | H7: 个 | I7: =D7-E7 -> 8000 | J7: =VLOOKUP(B7,本月系统单价mb5b!$B:$P,15,0) -> 0.24741273 | K7: =I7*J7 -> 1979.3018 | L7: =IFERROR(VLOOKUP(B7,上月数量需更新!A:C,3,0),0) -> 378.13 | M7: =K7-L7 -> 1601.1718 | P7: =VLOOKUP(B7,物料分类!B:F,5,0) -> 物料消耗
A8: 450 | B8: 8704096 | C8: 酒精湿巾（海底捞，独立包装，100片*14包/箱） | D8: 490 | E8: 84 | F8: 包 | G8: Z07 | H8: 包 | I8: =D8-E8 -> 406 | J8: =VLOOKUP(B8,本月系统单价mb5b!$B:$P,15,0) -> 4.0438367 | K8: =I8*J8 -> 1641.7977 | L8: =IFERROR(VLOOKUP(B8,上月数量需更新!A:C,3,0),0) -> 1687.01 | M8: =K8-L8 -> -45.212286 | P8: =VLOOKUP(B8,物料分类!B:F,5,0) -> 物料消耗
A9: 8 | B9: 1500911 | C9: ASAKI啤酒（330ML*24瓶/箱） | D9: 3217 | E9: 3070 | F9: 瓶 | G9: BOT | H9: 瓶 | I9: =D9-E9 -> 147 | J9: =VLOOKUP(B9,本月系统单价mb5b!$B:$P,15,0) -> 2.1549829 | K9: =I9*J9 -> 316.78249 | L9: =IFERROR(VLOOKUP(B9,上月数量需更新!A:C,3,0),0) -> 249.98 | M9: =K9-L9 -> 66.802487 | N9: =VLOOKUP(B9,计算!R:X,7,0) -> 多使用1瓶 | O9: 盤點无誤 | P9: =VLOOKUP(B9,物料分类!B:F,5,0) -> 成本-酒水类
A10: 9 | B10: 1501193 | C10: BC肉蟹（LB） | D10: 10.84 | E10: 2.288 | F10: 磅 | G10: CL5 | H10: 美 | I10: =D10-E10 -> 8.552 | J10: =VLOOKUP(B10,本月系统单价mb5b!$B:$P,15,0) -> 19.607011 | K10: =I10*J10 -> 167.67916 | L10: =IFERROR(VLOOKUP(B10,上月数量需更新!A:C,3,0),0) -> 74.34 | M10: =K10-L10 -> 93.339159 | P10: =VLOOKUP(B10,物料分类!B:F,5,0) -> 成本-荤菜类
A11: 26 | B11: 8011001 | C11: 一次性无纺布围裙（成人款，50条*20袋/箱） | D11: 11000 | E11: 5000 | F11: 条 | G11: Z19 | H11: 条 | I11: =D11-E11 -> 6000 | J11: =VLOOKUP(B11,本月系统单价mb5b!$B:$P,15,0) -> 0.19297545 | K11: =I11*J11 -> 1157.8527 | L11: =IFERROR(VLOOKUP(B11,上月数量需更新!A:C,3,0),0) -> 1929.76 | M11: =K11-L11 -> -771.90727 | P11: =VLOOKUP(B11,物料分类!B:F,5,0) -> 物料消耗
A12: 49 | B12: 8703542 | C12: 儿童餐盘（硅胶，40个/件） | D12: 200 | E12: 100 | F12: 个 | G12: Z05 | H12: 个 | I12: =D12-E12 -> 100 | J12: =VLOOKUP(B12,本月系统单价mb5b!$B:$P,15,0) -> 9.12505 | K12: =I12*J12 -> 912.505 | L12: =IFERROR(VLOOKUP(B12,上月数量需更新!A:C,3,0),0) -> 0 | M12: =K12-L12 -> 912.505 | P12: =VLOOKUP(B12,物料分类!B:F,5,0) -> 物料消耗
A13: 12 | B13: 4521260 | C13: CAESAR酱（3.78L*2瓶/箱） | D13: 22.68 | E13: 7.56 | F13: 升 | G13: L | H13: 公升 | I13: =D13-E13 -> 15.12 | J13: =VLOOKUP(B13,本月系统单价mb5b!$B:$P,15,0) -> 9.5952381 | K13: =I13*J13 -> 145.08 | L13: =IFERROR(VLOOKUP(B13,上月数量需更新!A:C,3,0),0) -> 74.69 | M13: =K13-L13 -> 70.39 | P13: =VLOOKUP(B13,物料分类!B:F,5,0) -> 成本-小料台类
A14: 13 | B14: 4505451 | C14: GLENFIDDICH 18（750ML/瓶） | D14: 1 | E14: 1 | F14: 瓶 | G14: BOT | H14: 瓶 | I14: =D14-E14 -> 0 | J14: =VLOOKUP(B14,本月系统单价mb5b!$B:$P,15,0) -> 57.31 | K14: =I14*J14 -> 0 | L14: =IFERROR(VLOOKUP(B14,上月数量需更新!A:C,3,0),0) -> 0 | M14: =K14-L14 -> 0 | P14: =VLOOKUP(B14,物料分类!B:F,5,0) -> 成本-酒水类
A15: 14 | B15: 4505448 | C15: JACK DANIELS （750ML/瓶） | D15: 1 | E15: 1 | F15: 瓶 | G15: BOT | H15: 瓶 | I15: =D15-E15 -> 0 | J15: =VLOOKUP(B15,本月系统单价mb5b!$B:$P,15,0) -> 29.25 | K15: =I15*J15 -> 0 | L15: =IFERROR(VLOOKUP(B15,上月数量需更新!A:C,3,0),0) -> 0 | M15: =K15-L15 -> 0 | P15: =VLOOKUP(B15,物料分类!B:F,5,0) -> 成本-酒水类
A16: 15 | B16: 4518902 | C16: KIRKLAND矿泉水（500ML*35瓶/箱） | D16: 35 | E16: 0 | F16: 瓶 | G16: BOT | H16: 瓶 | I16: =D16-E16 -> 35 | J16: =VLOOKUP(B16,本月系统单价mb5b!$B:$P,15,0) -> 0.21171429 | K16: =I16*J16 -> 7.41 | L16: =IFERROR(VLOOKUP(B16,上月数量需更新!A:C,3,0),0) -> 37.03 | M16: =K16-L16 -> -29.62 | P16: =VLOOKUP(B16,物料分类!B:F,5,0) -> 成本-酒水类
A17: 16 | B17: 4518131 | C17: KOOKSOONDANG（750ML*20瓶/箱） | D17: 716 | E17: 675 | F17: 瓶 | G17: BOT | H17: 瓶 | I17: =D17-E17 -> 41 | J17: =VLOOKUP(B17,本月系统单价mb5b!$B:$P,15,0) -> 5.38 | K17: =I17*J17 -> 220.58 | L17: =IFERROR(VLOOKUP(B17,上月数量需更新!A:C,3,0),0) -> 182.92 | M17: =K17-L17 -> 37.66 | N17: =VLOOKUP(B17,计算!R:X,7,0) -> 多使用26瓶 | O17: 少算了一箱,是695 | P17: =VLOOKUP(B17,物料分类!B:F,5,0) -> 成本-酒水类
A18: 17 | B18: 4528292 | C18: MALIBUCOCONUTRUMLIQUEUR（750ML/瓶） | D18: 3 | E18: 3 | F18: 瓶 | G18: BOT | H18: 瓶 | I18: =D18-E18 -> 0 | J18: =VLOOKUP(B18,本月系统单价mb5b!$B:$P,15,0) -> 19.97 | K18: =I18*J18 -> 0 | L18: =IFERROR(VLOOKUP(B18,上月数量需更新!A:C,3,0),0) -> 0 | M18: =K18-L18 -> 0 | P18: =VLOOKUP(B18,物料分类!B:F,5,0) -> 成本-酒水类
A19: 18 | B19: 4528291 | C19: MIDORI-MELON（750ML/瓶） | D19: 1 | E19: 0 | F19: 瓶 | G19: BOT | H19: 瓶 | I19: =D19-E19 -> 1 | J19: =VLOOKUP(B19,本月系统单价mb5b!$B:$P,15,0) -> 24.43 | K19: =I19*J19 -> 24.43 | L19: =IFERROR(VLOOKUP(B19,上月数量需更新!A:C,3,0),0) -> 0 | M19: =K19-L19 -> 24.43 | P19: =VLOOKUP(B19,物料分类!B:F,5,0) -> 成本-酒水类
A20: 264 | B20: 1500919 | C20: 洗碗液（红色， 20L/桶） | D20: 11 | E20: 0 | F20: 桶 | G20: Z36 | H20: 桶 | I20: =D20-E20 -> 11 | J20: =VLOOKUP(B20,本月系统单价mb5b!$B:$P,15,0) -> 82.12 | K20: =I20*J20 -> 903.32 | L20: =IFERROR(VLOOKUP(B20,上月数量需更新!A:C,3,0),0) -> 574.84 | M20: =K20-L20 -> 328.48 | P20: =VLOOKUP(B20,物料分类!B:F,5,0) -> 物料消耗
A21: 20 | B21: 4514744 | C21: SALSA辣酱（3.7L*2瓶/箱） | D21: 18 | E21: 11.1 | F21: 瓶 | G21: BOT | H21: 瓶 | I21: =D21-E21 -> 6.9 | J21: =VLOOKUP(B21,本月系统单价mb5b!$B:$P,15,0) -> 27.696111 | K21: =I21*J21 -> 191.10317 | L21: =IFERROR(VLOOKUP(B21,上月数量需更新!A:C,3,0),0) -> 525.99 | M21: =K21-L21 -> -334.88683 | P21: =VLOOKUP(B21,物料分类!B:F,5,0) -> 成本-小料台类
A22: 21 | B22: 4515975 | C22: SOHO LYCHEE荔枝酒（750ML/瓶） | D22: 8 | E22: 4 | F22: 瓶 | G22: BOT | H22: 瓶 | I22: =D22-E22 -> 4 | J22: =VLOOKUP(B22,本月系统单价mb5b!$B:$P,15,0) -> 26.76 | K22: =I22*J22 -> 107.04 | L22: =IFERROR(VLOOKUP(B22,上月数量需更新!A:C,3,0),0) -> 53.56 | M22: =K22-L22 -> 53.48 | P22: =VLOOKUP(B22,物料分类!B:F,5,0) -> 成本-酒水类
A23: 22 | B23: 4528183 | C23: UN-CHILLFILTEREDWHISKY（KAIYO，750ML/瓶） | D23: 1 | E23: 1 | F23: 瓶 | G23: BOT | H23: 瓶 | I23: =D23-E23 -> 0 | J23: =VLOOKUP(B23,本月系统单价mb5b!$B:$P,15,0) -> 96.72 | K23: =I23*J23 -> 0 | L23: =IFERROR(VLOOKUP(B23,上月数量需更新!A:C,3,0),0) -> 0 | M23: =K23-L23 -> 0 | P23: =VLOOKUP(B23,物料分类!B:F,5,0) -> 成本-酒水类
A24: 263 | B24: 1501010 | C24: 洗洁精（4L*4桶/箱） | D24: 148 | E24: 28 | F24: 桶 | G24: Z36 | H24: 桶 | I24: =D24-E24 -> 120 | J24: =VLOOKUP(B24,本月系统单价mb5b!$B:$P,15,0) -> 7.5 | K24: =I24*J24 -> 900 | L24: =IFERROR(VLOOKUP(B24,上月数量需更新!A:C,3,0),0) -> 810 | M24: =K24-L24 -> 90 | P24: =VLOOKUP(B24,物料分类!B:F,5,0) -> 物料消耗
A25: 151 | B25: 4003246 | C25: 客人围裙（黑色红边，20条/捆） | D25: 400 | E25: 20 | F25: 条 | G25: Z19 | H25: 条 | I25: =D25-E25 -> 380 | J25: =VLOOKUP(B25,本月系统单价mb5b!$B:$P,15,0) -> 2.16645 | K25: =I25*J25 -> 823.251 | L25: =IFERROR(VLOOKUP(B25,上月数量需更新!A:C,3,0),0) -> 433.29 | M25: =K25-L25 -> 389.961 | P25: =VLOOKUP(B25,物料分类!B:F,5,0) -> 物料消耗
A26: 282 | B26: 4529698 | C26: 漂白水（餐具专用，4L*4桶/箱） | D26: 76 | E26: 16 | F26: 桶 | G26: Z36 | H26: 桶 | I26: =D26-E26 -> 60 | J26: =VLOOKUP(B26,本月系统单价mb5b!$B:$P,15,0) -> 9.25 | K26: =I26*J26 -> 555 | L26: =IFERROR(VLOOKUP(B26,上月数量需更新!A:C,3,0),0) -> 342.25 | M26: =K26-L26 -> 212.75 | P26: =VLOOKUP(B26,物料分类!B:F,5,0) -> 物料消耗
A27: 104 | B27: 4000642 | C27: 双层抽纸（清风，130抽*96包/件） | D27: 1728 | E27: 288 | F27: 包 | G27: Z07 | H27: 包 | I27: =D27-E27 -> 1440 | J27: =VLOOKUP(B27,本月系统单价mb5b!$B:$P,15,0) -> 0.36471065 | K27: =I27*J27 -> 525.18333 | L27: =IFERROR(VLOOKUP(B27,上月数量需更新!A:C,3,0),0) -> 560.2 | M27: =K27-L27 -> -35.016667 | P27: =VLOOKUP(B27,物料分类!B:F,5,0) -> 物料消耗
A28: 27 | B28: 1501000 | C28: 一次性汤勺（1000个/箱） | D28: 19000 | E28: 6000 | F28: 个 | G28: Z05 | H28: 个 | I28: =D28-E28 -> 13000 | J28: =VLOOKUP(B28,本月系统单价mb5b!$B:$P,15,0) -> 0.039278947 | K28: =I28*J28 -> 510.62632 | L28: =IFERROR(VLOOKUP(B28,上月数量需更新!A:C,3,0),0) -> 698.4 | M28: =K28-L28 -> -187.77368 | P28: =VLOOKUP(B28,物料分类!B:F,5,0) -> 物料消耗
A29: 47 | B29: 1500979 | C29: 保鲜膜（762M*27.9CM/卷） | D29: 39 | E29: 13 | F29: 卷 | G29: Z08 | H29: 卷 | I29: =D29-E29 -> 26 | J29: =VLOOKUP(B29,本月系统单价mb5b!$B:$P,15,0) -> 19.276667 | K29: =I29*J29 -> 501.19333 | L29: =IFERROR(VLOOKUP(B29,上月数量需更新!A:C,3,0),0) -> 386.98 | M29: =K29-L29 -> 114.21333 | P29: =VLOOKUP(B29,物料分类!B:F,5,0) -> 物料消耗
... A102: 101 | B102: 4515419 | C102: 去肥黄瓜条（LB） | D102: 414.42 | E102: 94.6 | F102: 磅 | G102: CL5 | H102: 美 | I102: =D102-E102 -> 319.82 | J102: =VLOOKUP(B102,本月系统单价mb5b!$B:$P,15,0) -> 6.3235606 | K102: =I102*J102 -> 2022.4012 | L102: =IFERROR(VLOOKUP(B102,上月数量需更新!A:C,3,0),0) -> 2397.15 | M102: =K102-L102 -> -374.74884 | P102: =VLOOKUP(B102,物料分类!B:F,5,0) -> 成本-荤菜类
A103: 102 | B103: 4522918 | C103: 去骨牛小排（LB） | D103: 714.41 | E103: 103.67 | F103: 磅 | G103: CL5 | H103: 美 | I103: =D103-E103 -> 610.74 | J103: =VLOOKUP(B103,本月系统单价mb5b!$B:$P,15,0) -> 21.414034 | K103: =I103*J103 -> 13078.407 | L103: =IFERROR(VLOOKUP(B103,上月数量需更新!A:C,3,0),0) -> 10291.88 | M103: =K103-L103 -> 2786.5271 | N103: =VLOOKUP(B103,计算!R:X,7,0) -> 多使用105磅 | O103: 麻辣燙和烤肉套餐使用 | P103: =VLOOKUP(B103,物料分类!B:F,5,0) -> 成本-荤菜类
A104: 6 | B104: 8011411 | C104: 59G热敏收银纸（80*60MM，120卷/箱） | D104: 480 | E104: 120 | F104: 卷 | G104: Z08 | H104: 卷 | I104: =D104-E104 -> 360 | J104: =VLOOKUP(B104,本月系统单价mb5b!$B:$P,15,0) -> 0.64783333 | K104: =I104*J104 -> 233.22 | L104: =IFERROR(VLOOKUP(B104,上月数量需更新!A:C,3,0),0) -> 162.56 | M104: =K104-L104 -> 70.66 | P104: =VLOOKUP(B104,物料分类!B:F,5,0) -> 物料消耗
A105: 28 | B105: 4021486 | C105: 一次性纸杯（海底捞门店专用，50个*20提/件） | D105: 13000 | E105: 5000 | F105: 个 | G105: Z05 | H105: 个 | I105: =D105-E105 -> 8000 | J105: =VLOOKUP(B105,本月系统单价mb5b!$B:$P,15,0) -> 0.026607692 | K105: =I105*J105 -> 212.86154 | L105: =IFERROR(VLOOKUP(B105,上月数量需更新!A:C,3,0),0) -> 53.21 | M105: =K105-L105 -> 159.65154 | P105: =VLOOKUP(B105,物料分类!B:F,5,0) -> 物料消耗
A106: 105 | B106: 8014496 | C106: 变形车玩具（加拿大，3岁及以上，火箭人款，50个/件） | D106: 1000 | E106: 0 | F106: 个 | G106: Z05 | H106: 个 | I106: =D106-E106 -> 1000 | J106: =VLOOKUP(B106,本月系统单价mb5b!$B:$P,15,0) -> 0.80881 | K106: =I106*J106 -> 808.81 | L106: =IFERROR(VLOOKUP(B106,上月数量需更新!A:C,3,0),0) -> 0 | M106: =K106-L106 -> 808.81 | P106: =VLOOKUP(B106,物料分类!B:F,5,0) -> 服务费
A107: 106 | B107: 1500902 | C107: 可口可乐（355ML*32听/箱） | D107: 1259 | E107: 323 | F107: 听 | G107: Z01 | H107: 听 | I107: =D107-E107 -> 936 | J107: =VLOOKUP(B107,本月系统单价mb5b!$B:$P,15,0) -> 0.50996823 | K107: =I107*J107 -> 477.33026 | L107: =IFERROR(VLOOKUP(B107,上月数量需更新!A:C,3,0),0) -> 344.44 | M107: =K107-L107 -> 132.89026 | P107: =VLOOKUP(B107,物料分类!B:F,5,0) -> 成本-酒水类
A108: 175 | B108: 4505865 | C108: 打包盒盖子（1.5L，300个/箱） | D108: 3000 | E108: 900 | F108: 个 | G108: Z05 | H108: 个 | I108: =D108-E108 -> 2100 | J108: =VLOOKUP(B108,本月系统单价mb5b!$B:$P,15,0) -> 0.1 | K108: =I108*J108 -> 210 | L108: =IFERROR(VLOOKUP(B108,上月数量需更新!A:C,3,0),0) -> 240 | M108: =K108-L108 -> -30 | P108: =VLOOKUP(B108,物料分类!B:F,5,0) -> 物料消耗
A109: 285 | B109: 8010886 | C109: 潜心碟（华南，白瓷，6寸，100个/件） | D109: 200 | E109: 0 | F109: 个 | G109: Z05 | H109: 个 | I109: =D109-E109 -> 200 | J109: =VLOOKUP(B109,本月系统单价mb5b!$B:$P,15,0) -> 0.89215 | K109: =I109*J109 -> 178.43 | L109: =IFERROR(VLOOKUP(B109,上月数量需更新!A:C,3,0),0) -> 0 | M109: =K109-L109 -> 178.43 | P109: =VLOOKUP(B109,物料分类!B:F,5,0) -> 物料消耗
A110: 109 | B110: 4526645 | C110: 君度（750ML/瓶） | D110: 2 | E110: 2 | F110: 瓶 | G110: BOT | H110: 瓶 | I110: =D110-E110 -> 0 | J110: =VLOOKUP(B110,本月系统单价mb5b!$B:$P,15,0) -> 33.85 | K110: =I110*J110 -> 0 | L110: =IFERROR(VLOOKUP(B110,上月数量需更新!A:C,3,0),0) -> 0 | M110: =K110-L110 -> 0 | P110: =VLOOKUP(B110,物料分类!B:F,5,0) -> 成本-酒水类
A111: 110 | B111: 4501989 | C111: 味精（50LB/包） | D111: 80 | E111: 45 | F111: 磅 | G111: CL5 | H111: 美 | I111: =D111-E111 -> 35 | J111: =VLOOKUP(B111,本月系统单价mb5b!$B:$P,15,0) -> 1.2 | K111: =I111*J111 -> 42 | L111: =IFERROR(VLOOKUP(B111,上月数量需更新!A:C,3,0),0) -> 36 | M111: =K111-L111 -> 6 | P111: =VLOOKUP(B111,物料分类!B:F,5,0) -> 成本-小料台类
A112: 527 | B112: 4516323 | C112: 黑色手套L号（100个*10盒/箱） | D112: 4000 | E112: 0 | F112: 个 | G112: Z05 | H112: 个 | I112: =D112-E112 -> 4000 | J112: =VLOOKUP(B112,本月系统单价mb5b!$B:$P,15,0) -> 0.0429875 | K112: =I112*J112 -> 171.95 | L112: =IFERROR(VLOOKUP(B112,上月数量需更新!A:C,3,0),0) -> 0 | M112: =K112-L112 -> 171.95 | P112: =VLOOKUP(B112,物料分类!B:F,5,0) -> 物料消耗
...

Sheet 上月数量需更新
B3: 值
A4: 物料 | B4: 求和项:单价1 | C4: 求和项:系统发出金额
A5: 1000049 | B5: 2.3469388 | C5: 483
A6: 1000096 | B6: 7.2468944 | C6: 46.67
A7: 1000132 | B7: 8.5 | C7: 994.5
A8: 1004576 | B8: 0.11872587 | C8: 1611.11
A9: 1500009 | B9: 3.125 | C9: 288.75
A10: 1500059 | B10: 4.1660909 | C10: 458.27
A11: 1500612 | B11: 17.5 | C11: 105
A12: 1500677 | B12: 4.6104407 | C12: 25458.07
A13: 1500678 | B13: 6.2500182 | C13: 5139.89
A14: 1500679 | B14: 6.3786553 | C14: 11192.18
A15: 1500680 | B15: 3.7884829 | C15: 2529.57
A16: 1500681 | B16: 4.2043122 | C16: 2195.66
... A156: 4726198 | B156: 22 | C156: 440
A157: (空白) | B157: #DIV/0!
A158: 1500688 | B158: 4.38 | C158: 65.7
A159: 1500713 | B159: 3.5 | C159: 133
A160: 1500721 | B160: 0.6 | C160: 396
A161: 1500728 | B161: 1.3 | C161: 78
A162: 1500741 | B162: 22.99 | C162: 275.88
A163: 1500750 | B163: 3.6471154 | C163: 37.93
A164: 1500783 | B164: 1.8 | C164: 52.2
A165: 1500784 | B165: 0.9 | C165: 22.77
A166: 1500795 | B166: 19.53 | C166: 117.18
A167: 1500831 | B167: 12.5 | C167: 75
A168: 1500837 | B168: 12.5 | C168: 12.5
A169: 1500838 | B169: 8.3288752 | C169: 242.87
... A482: 8704092 | B482: 0.21196667 | C482: 63.59
A483: 总计 | B483: 1.1857183 | C483: 345104.2

Sheet 上月数量zfi0156
A1: 开始日期 | B1: 结束日期 | C1: 工厂 | D1: 工厂描述 | E1: 物料 | F1: 物料描述 | G1: Bun | H1: 单位描述 | I1: 大类 | J1: 系统发出单价 | K1: 数量 | L1: 系统发出金额 | M1: 物料分类 | N1: 物料分类描述
A2: 45748 | B2: 45777 | C2: CA07 | D2: 加拿大七店 | E2: 1000049 | F2: 金标生抽（海天，4.9L*2桶/件） | G2: L | H2: 升 | I2: 成本类 | J2: 2.35 | K2: 205.8 | L2: 483 | M2: Z05 | N2: 成本-其他类 | O2: 1 | P2: 成本类 | Q2: 成本-小料台类
A3: 45748 | B3: 45777 | C3: CA07 | D3: 加拿大七店 | E3: 1000096 | F3: 辣椒酱（辣妹子，920G*12瓶/件） | G3: KG | H3: 公斤 | I3: 成本类 | J3: 7.25 | K3: 6.44 | L3: 46.67 | M3: Z05 | N3: 成本-其他类 | O3: 1 | P3: 成本类 | Q3: 成本-小料台类
A4: 45748 | B4: 45777 | C4: CA07 | D4: 加拿大七店 | E4: 1000103 | F4: 大块腐乳（王致和，340G*15瓶/件） | G4: KG | H4: 公斤 | I4: 成本类 | J4: 7.31 | K4: 54.06 | L4: 395.12 | M4: Z05 | N4: 成本-其他类 | O4: 1 | P4: 成本类 | Q4: 成本-小料台类
A5: 45748 | B5: 45777 | C5: CA07 | D5: 加拿大七店 | E5: 1000132 | F5: 沙茶酱（牛头，3KG*6瓶/件） | G5: KG | H5: 公斤 | I5: 成本类 | J5: 8.5 | K5: 117 | L5: 994.5 | M5: Z05 | N5: 成本-其他类 | O5: 1 | P5: 成本类 | Q5: 成本-小料台类
A6: 45748 | B6: 45777 | C6: CA07 | D6: 加拿大七店 | E6: 1001413 | F6: 卤水汁（李锦记，410ML*12瓶/件） | G6: L | H6: 升 | I6: 成本类 | J6: 14.37 | K6: 2.46 | L6: 35.34 | M6: Z05 | N6: 成本-其他类 | O6: 1 | P6: 成本类 | Q6: 成本-荤菜类
A7: 45748 | B7: 45777 | C7: CA07 | D7: 加拿大七店 | E7: 1003028 | F7: 牛油（20KG/件） | G7: KG | H7: 公斤 | I7: 成本类 | J7: 4.18 | K7: 500 | L7: 2092.49 | M7: Z02 | N7: 成本-荤菜类 | O7: 1 | P7: 成本类 | Q7: 成本-锅底类
A8: 45748 | B8: 45777 | C8: CA07 | D8: 加拿大七店 | E8: 1004576 | F8: 虎牙脆（20G*230包/件） | G8: Z07 | H8: 包 | I8: 成本类 | J8: 0.12 | K8: 13570 | L8: 1611.11 | M8: Z10 | N8: 服务费-其他类 | O8: 1 | P8: 成本类 | Q8: 成本-小料台类
A9: 45748 | B9: 45777 | C9: CA07 | D9: 加拿大七店 | E9: 1500009 | F9: 蚝油（李锦记，2.2KG*6桶/件） | G9: KG | H9: 公斤 | I9: 成本类 | J9: 3.13 | K9: 92.4 | L9: 288.75 | M9: Z02 | N9: 成本-荤菜类 | O9: 1 | P9: 成本类 | Q9: 成本-小料台类
A10: 45748 | B10: 45777 | C10: CA07 | D10: 加拿大七店 | E10: 1500059 | F10: 三鲜粉TLTF-20（10KG*2包/件） | G10: KG | H10: 公斤 | I10: 成本类 | J10: 4.17 | K10: 110 | L10: 458.27 | M10: Z05 | N10: 成本-其他类 | O10: 1 | P10: 成本类 | Q10: 成本-锅底类
A11: 45748 | B11: 45777 | C11: CA07 | D11: 加拿大七店 | E11: 1500529 | F11: 果糖（环泰，5KG*4桶/件） | G11: KG | H11: 公斤 | I11: 成本类 | J11: 2.75 | K11: 165 | L11: 453.75 | M11: Z05 | N11: 成本-其他类 | O11: 1 | P11: 成本类 | Q11: 成本-酒水类
A12: 45748 | B12: 45777 | C12: CA07 | D12: 加拿大七店 | E12: 1500612 | F12: 花椒油（川老汇，1.8L*6包/件） | G12: Z07 | H12: 包 | I12: 成本类 | J12: 17.5 | K12: 6 | L12: 105 | M12: Z05 | N12: 成本-其他类 | O12: 1 | P12: 成本类 | Q12: 成本-小料台类
A13: 45748 | B13: 45777 | C13: CA07 | D13: 加拿大七店 | E13: 1500677 | F13: 牛腩肉（LB） | G13: CL5 | H13: 磅-美 | I13: 费用类 | J13: 4.61 | K13: 130 | L13: 599.13 | M13: Z02 | N13: 成本-荤菜类 | O13: 1 | P13: 成本类 | Q13: 成本-荤菜类
... A18: 45748 | B18: 45777 | C18: CA07 | D18: 加拿大七店 | E18: 1500680 | F18: 带皮去骨鸡腿肉（LB） | G18: CL5 | H18: 磅-美 | I18: 成本类 | J18: 3.79 | K18: 513.7 | L18: 1946.28 | M18: Z02 | N18: 成本-荤菜类 | O18: 1 | P18: 成本类 | Q18: 成本-荤菜类
A19: 45748 | B19: 45777 | C19: CA07 | D19: 加拿大七店 | E19: 1500681 | F19: 去皮五花肉（LB） | G19: CL5 | H19: 磅-美 | I19: 费用类 | J19: 4.2 | K19: 54 | L19: 227.03 | M19: Z02 | N19: 成本-荤菜类 | O19: 1 | P19: 成本类 | Q19: 成本-小吃类 | S19: 240911更新
A20: 45748 | B20: 45777 | C20: CA07 | D20: 加拿大七店 | E20: 1500681 | F20: 去皮五花肉（LB） | G20: CL5 | H20: 磅-美 | I20: 成本类 | J20: 4.2 | K20: 468.24 | L20: 1968.63 | M20: Z02 | N20: 成本-荤菜类 | O20: 1 | P20: 成本类 | Q20: 成本-小吃类 | S20: 240911更新
A21: 45748 | B21: 45777 | C21: CA07 | D21: 加拿大七店 | E21: 1500682 | F21: 梅花猪肉（LB） | G21: CL5 | H21: 磅-美 | I21: 费用类 | J21: 3.02 | K21: 22 | L21: 66.36 | M21: Z02 | N21: 成本-荤菜类 | O21: 1 | P21: 成本类 | Q21: 成本-荤菜类
A22: 45748 | B22: 45777 | C22: CA07 | D22: 加拿大七店 | E22: 1500682 | F22: 梅花猪肉（LB） | G22: CL5 | H22: 磅-美 | I22: 成本类 | J22: 3.02 | K22: 69.81 | L22: 210.58 | M22: Z02 | N22: 成本-荤菜类 | O22: 1 | P22: 成本类 | Q22: 成本-荤菜类
A23: 45748 | B23: 45777 | C23: CA07 | D23: 加拿大七店 | E23: 1500684 | F23: 毛肚（LB） | G23: CL5 | H23: 磅-美 | I23: 成本类 | J23: 6.8 | K23: 154.3 | L23: 1049.24 | M23: Z02 | N23: 成本-荤菜类 | O23: 1 | P23: 成本类 | Q23: 成本-荤菜类
A24: 45748 | B24: 45777 | C24: CA07 | D24: 加拿大七店 | E24: 1500685 | F24: 牛黄喉（LB） | G24: CL5 | H24: 磅-美 | I24: 成本类 | J24: 6.99 | K24: 232.5 | L24: 1625.17 | M24: Z02 | N24: 成本-荤菜类 | O24: 1 | P24: 成本类 | Q24: 成本-荤菜类
A25: 45748 | B25: 45777 | C25: CA07 | D25: 加拿大七店 | E25: 1500686 | F25: 牛舌（LB） | G25: CL5 | H25: 磅-美 | I25: 成本类 | J25: 14.99 | K25: 437.94 | L25: 6564.73 | M25: Z02 | N25: 成本-荤菜类 | O25: 1 | P25: 成本类 | Q25: 成本-荤菜类
A26: 45748 | B26: 45777 | C26: CA07 | D26: 加拿大七店 | E26: 1500687 | F26: 猪棒骨（LB） | G26: CL5 | H26: 磅-美 | I26: 成本类 | J26: 1.08 | K26: 1585.376 | L26: 1716.99 | M26: Z02 | N26: 成本-荤菜类 | O26: 1 | P26: 成本类 | Q26: 成本-锅底类
A27: 45748 | B27: 45777 | C27: CA07 | D27: 加拿大七店 | E27: 1500688 | F27: 带皮带骨鸡腿（冻） | G27: KG | H27: 公斤 | I27: 费用类 | J27: 4.38 | K27: 15 | L27: 65.7 | M27: Z02 | N27: 成本-荤菜类 | O27: 1 | P27: 成本类 | Q27: 成本-荤菜类
A28: 45748 | B28: 45777 | C28: CA07 | D28: 加拿大七店 | E28: 1500694 | F28: 猪排骨（员工餐， LB） | G28: CL5 | H28: 磅-美 | I28: 费用类 | J28: 2.69 | K28: 123 | L28: 330.87 | M28: Z02 | N28: 成本-荤菜类 | O28: 2 | P28: 费用类 | Q28: 员工餐
A29: 45748 | B29: 45777 | C29: CA07 | D29: 加拿大七店 | E29: 1500695 | F29: 白虾仁（41-50，4LB*6包/箱 ） | G29: CL5 | H29: 磅-美 | I29: 费用类 | J29: 5.21 | K29: 120 | L29: 625 | M29: Z02 | N29: 成本-荤菜类 | O29: 2 | P29: 费用类 | Q29: 员工餐
A30: 45748 | B30: 45777 | C30: CA07 | D30: 加拿大七店 | E30: 1500700 | F30: 冷冻巴沙鱼（12-14 ，10KG/箱） | G30: KG | H30: 公斤 | I30: 费用类 | J30: 3.65 | K30: 40 | L30: 146 | M30: Z02 | N30: 成本-荤菜类 | O30: 1 | P30: 成本类 | Q30: 成本-荤菜类
A31: 45748 | B31: 45777 | C31: CA07 | D31: 加拿大七店 | E31: 1500700 | F31: 冷冻巴沙鱼（12-14 ，10KG/箱） | G31: KG | H31: 公斤 | I31: 成本类 | J31: 3.65 | K31: 313.27 | L31: 1143.44 | M31: Z02 | N31: 成本-荤菜类 | O31: 1 | P31: 成本类 | Q31: 成本-荤菜类
A32: 45748 | B32: 45777 | C32: CA07 | D32: 加拿大七店 | E32: 1500703 | F32: 带头南美白虾（30-40，4LB*6包/箱 ） | G32: CL5 | H32: 磅-美 | I32: 成本类 | J32: 4.33 | K32: 344 | L32: 1490.67 | M32: Z02 | N32: 成本-荤菜类 | O32: 1 | P32: 成本类 | Q32: 成本-荤菜类
... A138: 45748 | B138: 45777 | C138: CA07 | D138: 加拿大七店 | E138: 1500918 | F138: 牛栏山二锅头（100ML/瓶） | G138: BOT | H138: 瓶 | I138: 成本类 | J138: 4.38 | K138: 33 | L138: 144.54 | M138: Z04 | N138: 成本-酒水类 | O138: 1 | P138: 成本类 | Q138: 成本-酒水类
A139: 45748 | B139: 45777 | C139: CA07 | D139: 加拿大七店 | E139: 1500919 | F139: 洗碗液（红色， 20L/桶） | G139: Z36 | H139: 桶 | I139: 费用类 | J139: 82.12 | K139: 7 | L139: 574.84 | M139: Z11 | N139: 物料消耗-清洁类 | O139: 2 | P139: 费用类 | Q139: 物料消耗 | R139: 清洁类
A140: 45748 | B140: 45777 | C140: CA07 | D140: 加拿大七店 | E140: 1500920 | F140: 快干剂（蓝色， 20L/桶） | G140: Z36 | H140: 桶 | I140: 费用类 | J140: 127.7 | K140: 4 | L140: 510.8 | M140: Z11 | N140: 物料消耗-清洁类 | O140: 2 | P140: 费用类 | Q140: 物料消耗 | R140: 清洁类
A141: 45748 | B141: 45777 | C141: CA07 | D141: 加拿大七店 | E141: 1500923 | F141: 洗杯红药水（4L*4桶/箱） | G141: Z36 | H141: 桶 | I141: 费用类 | J141: 18.6 | K141: 1 | L141: 18.6 | M141: Z15 | N141: 物料消耗-其他类 | O141: 2 | P141: 费用类 | Q141: 物料消耗 | R141: 清洁类
A142: 45748 | B142: 45777 | C142: CA07 | D142: 加拿大七店 | E142: 1500924 | F142: 洗杯快干剂（4L*4桶/箱） | G142: Z36 | H142: 桶 | I142: 费用类 | J142: 28.33 | K142: 1 | L142: 28.33 | M142: Z11 | N142: 物料消耗-清洁类 | O142: 2 | P142: 费用类 | Q142: 物料消耗
A143: 45748 | B143: 45777 | C143: CA07 | D143: 加拿大七店 | E143: 1500925 | F143: 洗地苏打（25KG/包） | G143: KG | H143: 公斤 | I143: 费用类 | J143: 2.4 | K143: 5 | L143: 11.99 | M143: Z11 | N143: 物料消耗-清洁类 | O143: 2 | P143: 费用类 | Q143: 物料消耗 | R143: 清洁类
A144: 45748 | B144: 45777 | C144: CA07 | D144: 加拿大七店 | E144: 1500938 | F144: 洗手液（4L*4桶/箱） | G144: Z36 | H144: 桶 | I144: 费用类 | J144: 8.25 | K144: 1 | L144: 8.25 | M144: Z11 | N144: 物料消耗-清洁类 | O144: 2 | P144: 费用类 | Q144: 物料消耗 | R144: 清洁类
A145: 45748 | B145: 45777 | C145: CA07 | D145: 加拿大七店 | E145: 1500944 | F145: 咖色单张擦手纸（4000张/箱） | G145: Z34 | H145: 箱 | I145: 费用类 | J145: 33.5 | K145: 8 | L145: 268 | M145: Z13 | N145: 物料消耗-纸巾类 | O145: 2 | P145: 费用类 | Q145: 物料消耗 | R145: 纸巾类
A146: 45748 | B146: 45777 | C146: CA07 | D146: 加拿大七店 | E146: 1500957 | F146: 8.5" 8MM 纸吸管（500根*2包/箱） | G146: Z07 | H146: 包 | I146: 费用类 | J146: 10 | K146: 20 | L146: 200 | M146: Z15 | N146: 物料消耗-其他类 | O146: 2 | P146: 费用类 | Q146: 物料消耗 | R146: 餐具类
A147: 45748 | B147: 45777 | C147: CA07 | D147: 加拿大七店 | E147: 1500960 | F147: 卷袋（12MM*20MM， 4卷/箱） | G147: Z08 | H147: 卷 | I147: 费用类 | J147: 9.53 | K147: 26 | L147: 247.66 | M147: Z15 | N147: 物料消耗-其他类 | O147: 2 | P147: 费用类 | Q147: 物料消耗 | R147: 其他类
A148: 45748 | B148: 45777 | C148: CA07 | D148: 加拿大七店 | E148: 1500961 | F148: 卷袋（8.5MM*12MM， 4卷/箱） | G148: Z08 | H148: 卷 | I148: 费用类 | J148: 9.5 | K148: 14 | L148: 133 | M148: Z15 | N148: 物料消耗-其他类 | O148: 2 | P148: 费用类 | Q148: 物料消耗 | R148: 其他类
A149: 45748 | B149: 45777 | C149: CA07 | D149: 加拿大七店 | E149: 1500963 | F149: 一次性叉（1000个/箱） | G149: Z05 | H149: 个 | I149: 费用类 | J149: 0.04 | K149: 3000 | L149: 118.5 | M149: Z15 | N149: 物料消耗-其他类 | O149: 2 | P149: 费用类 | Q149: 物料消耗 | R149: 餐具类
...

Sheet 本月系统单价mb5b
A1: ValA | B1: 物料 | C1: 开始日期 | D1: 结束日期 | E1: 期初库存 | F1: 总收货数量 | G1: 总发货数量 | H1: 期末库存 | I1: 计 | J1: 期初金额 | K1: 总收货金额 | L1: 总发货金额 | M1: 期末金额 | N1: 货币 | O1: 物料描述 | P1: 单价
A2: CA07 | B2: 1000049 | C2: 2025.05.01 | D2: 2025.05.31 | E2: 49 | F2: 215.6 | G2: 0 | H2: 264.6 | I2: L | J2: 115 | K2: 506 | L2: 0 | M2: 621 | N2: CAD | O2: 金标生抽（海天，4.9L*2桶/件） | P2: =M2/H2 -> 2.3469388
A3: CA07 | B3: 1000096 | C3: 2025.05.01 | D3: 2025.05.31 | E3: 12.88 | F3: 0 | G3: 0 | H3: 12.88 | I3: KG | J3: 93.33 | K3: 0 | L3: 0 | M3: 93.33 | N3: CAD | O3: 辣椒酱（辣妹子，920G*12瓶/件） | P3: =M3/H3 -> 7.246118
A4: CA07 | B4: 1000103 | C4: 2025.05.01 | D4: 2025.05.31 | E4: 15.3 | F4: 0 | G4: 0 | H4: 15.3 | I4: KG | J4: 111.83 | K4: 0 | L4: 0 | M4: 111.83 | N4: CAD | O4: 大块腐乳（王致和，340G*15瓶/件） | P4: =M4/H4 -> 7.3091503
A5: CA07 | B5: 1000132 | C5: 2025.05.01 | D5: 2025.05.31 | E5: 36 | F5: 108 | G5: 0 | H5: 144 | I5: KG | J5: 306 | K5: 918 | L5: 0 | M5: 1224 | N5: CAD | O5: 沙茶酱（牛头，3KG*6瓶/件） | P5: =M5/H5 -> 8.5
A6: CA07 | B6: 1000233 | C6: 2025.05.01 | D6: 2025.05.31 | E6: 0 | F6: 0 | G6: 0 | H6: 0 | I6: KG | J6: 0 | K6: 0 | L6: 0 | M6: 0 | N6: CAD | O6: 甜面酱（散装，4KG*4包/件） | P6: =M6/H6 -> #DIV/0!
A7: CA07 | B7: 1000266 | C7: 2025.05.01 | D7: 2025.05.31 | E7: 0 | F7: 0 | G7: 0 | H7: 0 | I7: L | J7: 0 | K7: 0 | L7: 0 | M7: 0 | N7: CAD | O7: 特级头抽（500ML*12瓶/件） | P7: =M7/H7 -> #DIV/0!
A8: CA07 | B8: 1001170 | C8: 2025.05.01 | D8: 2025.05.31 | E8: 0 | F8: 0 | G8: 0 | H8: 0 | I8: KG | J8: 0 | K8: 0 | L8: 0 | M8: 0 | N8: CAD | O8: 墨鱼仔（越南，12KG/件） | P8: =M8/H8 -> #DIV/0!
A9: CA07 | B9: 1001268 | C9: 2025.05.01 | D9: 2025.05.31 | E9: 0 | F9: 0 | G9: 0 | H9: 0 | I9: KG | J9: 0 | K9: 0 | L9: 0 | M9: 0 | N9: CAD | O9: 辣椒酱（辣妹子，248G*24瓶/件） | P9: =M9/H9 -> #DIV/0!
A10: CA07 | B10: 1001413 | C10: 2025.05.01 | D10: 2025.05.31 | E10: 1.23 | F10: 4.92 | G10: 0 | H10: 6.15 | I10: L | J10: 17.67 | K10: 70.68 | L10: 0 | M10: 88.35 | N10: CAD | O10: 卤水汁（李锦记，410ML*12瓶/件） | P10: =M10/H10 -> 14.365854
A11: CA07 | B11: 1003028 | C11: 2025.05.01 | D11: 2025.05.31 | E11: 20 | F11: 500 | G11: 0 | H11: 520 | I11: KG | J11: 83.7 | K11: 2092.5 | L11: 0 | M11: 2176.2 | N11: CAD | O11: 牛油（20KG/件） | P11: =M11/H11 -> 4.185
A12: CA07 | B12: 1004576 | C12: 2025.05.01 | D12: 2025.05.31 | E12: 0 | F12: 10120 | G12: 0 | H12: 10120 | I12: Z07 | J12: 0 | K12: 1069.61 | L12: 0 | M12: 1069.61 | N12: CAD | O12: 虎牙脆（20G*230包/件） | P12: =M12/H12 -> 0.10569269
A13: CA07 | B13: 1500009 | C13: 2025.05.01 | D13: 2025.05.31 | E13: 15.4 | F13: 105.6 | G13: 0 | H13: 121 | I13: KG | J13: 48.12 | K13: 330 | L13: 0 | M13: 378.12 | N13: CAD | O13: 蚝油（李锦记，2.2KG*6桶/件） | P13: =M13/H13 -> 3.1249587
... A2236: CA07 | B2236: 8704096 | C2236: 2025.05.01 | D2236: 2025.05.31 | E2236: 98 | F2236: 392 | G2236: 0 | H2236: 490 | I2236: Z07 | J2236: 407.21 | K2236: 1574.27 | L2236: 0 | M2236: 1981.48 | N2236: CAD | O2236: 酒精湿巾（海底捞，独立包装，100片*14包/箱） | P2236: =M2236/H2236 -> 4.0438367
A2237: CA07 | B2237: 8704101 | C2237: 2025.05.01 | D2237: 2025.05.31 | E2237: 0 | F2237: 0 | G2237: 0 | H2237: 0 | I2237: Z05 | J2237: 0 | K2237: 0 | L2237: 0 | M2237: 0 | N2237: CAD | O2237: 208012 | P2237: =M2237/H2237 -> #DIV/0!
A2238: CA07 | B2238: 8704102 | C2238: 2025.05.01 | D2238: 2025.05.31 | E2238: 0 | F2238: 0 | G2238: 0 | H2238: 0 | I2238: Z11 | J2238: 0 | K2238: 0 | L2238: 0 | M2238: 0 | N2238: CAD | O2238: 长胶手套（出口） | P2238: =M2238/H2238 -> #DIV/0!
A2239: CA07 | B2239: 8704109 | C2239: 2025.05.01 | D2239: 2025.05.31 | E2239: 0 | F2239: 0 | G2239: 0 | H2239: 0 | I2239: Z06 | J2239: 0 | K2239: 0 | L2239: 0 | M2239: 0 | N2239: CAD | O2239: 五双装家庭筷（定制，礼品，120盒/箱） | P2239: =M2239/H2239 -> #DIV/0!
A2240: CA07 | B2240: 8704126 | C2240: 2025.05.01 | D2240: 2025.05.31 | E2240: 0 | F2240: 0 | G2240: 0 | H2240: 0 | I2240: Z05 | J2240: 0 | K2240: 0 | L2240: 0 | M2240: 0 | N2240: CAD | O2240: 小嗨-生日快乐手提袋（100个/件） | P2240: =M2240/H2240 -> #DIV/0!
A2241: CA07 | B2241: 8704127 | C2241: 2025.05.01 | D2241: 2025.05.31 | E2241: 0 | F2241: 0 | G2241: 0 | H2241: 0 | I2241: Z05 | J2241: 0 | K2241: 0 | L2241: 0 | M2241: 0 | N2241: CAD | O2241: 大打包纸袋（加拿大，法语专用，200个/件） | P2241: =M2241/H2241 -> #DIV/0!
A2242: CA07 | B2242: 8704128 | C2242: 2025.05.01 | D2242: 2025.05.31 | E2242: 0 | F2242: 0 | G2242: 0 | H2242: 0 | I2242: Z05 | J2242: 0 | K2242: 0 | L2242: 0 | M2242: 0 | N2242: CAD | O2242: 小打包纸袋（加拿大，法语专用，300个/件） | P2242: =M2242/H2242 -> #DIV/0!
A2243: CA07 | B2243: 8704129 | C2243: 2025.05.01 | D2243: 2025.05.31 | E2243: 0 | F2243: 0 | G2243: 0 | H2243: 0 | I2243: Z05 | J2243: 0 | K2243: 0 | L2243: 0 | M2243: 0 | N2243: CAD | O2243: 零食打包袋（加拿大，法语专用，1000个/件） | P2243: =M2243/H2243 -> #DIV/0!
P2244: =M2244/H2244 -> #DIV/0!
P2245: =M2245/H2245 -> #DIV/0!
P2246: =M2246/H2246 -> #DIV/0!
P2247: =M2247/H2247 -> #DIV/0!
P2248: =M2248/H2248 -> #DIV/0!
P2249: =M2249/H2249 -> #DIV/0!
P2250: =M2250/H2250 -> #DIV/0!
P2251: =M2251/H2251 -> #DIV/0!
P2252: =M2252/H2252 -> #DIV/0!
P2253: =M2253/H2253 -> #DIV/0!
P2254: =M2254/H2254 -> #DIV/0!
P2255: =M2255/H2255 -> #DIV/0!
... P2646: =M2646/H2646 -> #DIV/0!

Sheet 透视表
A1: 大类名称 | B1: (多项)
A3: 菜品编码 | B3: 菜品名称 | C3: 求和项:折算数量计算
A4: 01010106 | B4: 清水锅 | C4: 57942
A5: 01060061 | B5: 麻辣火锅（有渣） | C5: 34272
A6: 01060062 | B6: 猪骨汤 | C6: 116270
A7: 01060063 | B7: 菌汤火锅 | C7: 41922
A8: 01060064 | B8: 经典麻辣火锅 | C8: 45243
A9: 01060066 | B9: 番茄火锅 | C9: 162348
A10: 01060115 | B10: 胡椒猪肚鸡火锅 | C10: 20800
A11: 01060204 | B11: 酸菜鲜锅 | C11: 6262
A12: 01060227 | B12: 麻辣火锅（无渣） | C12: 41800
A13: 01310005 | B13: 叻沙火锅 | C13: 17424
A14: 12010002 | B14: 柠檬冰红茶 341ML | C14: 741
A15: 12010003 | B15: 甜豆浆（1L） | C15: 1728
... A50: 70000539 | B50: Peller family 红酒 | C50: 66
A51: 总计 | C51: 10800543

Sheet 红火台销售汇总
A1: 检索 | B1: 门店名称 | C1: 编码 | D1: 菜品编码 | E1: 菜品短编码 | F1: 菜品名称 | G1: 规格 | H1: 出品数量 | I1: 退菜数量 | J1: 实际出品数据（出品数量-退菜数量） | K1: 大类名称 | L1: 子类名称
A2: =B2&D2&E2&G2 -> 加拿大七店906001343013整份 | B2: 加拿大七店 | D2: 9060013 | E2: 43013 | F2: 黑猪肉 | G2: 整份 | H2: 960 | I2: 2 | J2: =H2-I2 -> 958 | K2: 荤菜 | L2: 牛/羊肉
A3: =B3&D3&E3&G3 -> 加拿大七店110102621002693半份 | B3: 加拿大七店 | D3: 11010262 | E3: 1002693 | F3: 白米饭(半） | G3: 半份 | H3: 239 | I3: 1 | J3: =H3-I3 -> 238 | K3: 小吃甜品 | L3: 主食类
A4: =B4&D4&E4&G4 -> 加拿大七店1101026250303整份 | B4: 加拿大七店 | D4: 11010262 | E4: 50303 | F4: 白米饭 | G4: 整份 | H4: 931 | I4: 6 | J4: =H4-I4 -> 925 | K4: 小吃甜品 | L4: 主食类
A5: =B5&D5&E5&G5 -> 加拿大七店1002013841184半份 | B5: 加拿大七店 | D5: 10020138 | E5: 41184 | F5: 芋头(半) | G5: 半份 | H5: 245 | I5: 3 | J5: =H5-I5 -> 242 | K5: 素菜 | L5: 根茎类
A6: =B6&D6&E6&G6 -> 加拿大七店1002013841183整份 | B6: 加拿大七店 | D6: 10020138 | E6: 41183 | F6: 芋头 | G6: 整份 | H6: 84 | I6: 1 | J6: =H6-I6 -> 83 | K6: 素菜 | L6: 根茎类
A7: =B7&D7&E7&G7 -> 加拿大七店1002001741017整份 | B7: 加拿大七店 | C7: =D7&G7 -> 10020017整份 | D7: 10020017 | E7: 41017 | F7: 菌类拼盘 | G7: 整份 | H7: 673 | I7: 1 | J7: =H7-I7 -> 672 | K7: 素菜 | L7: 菌类
A8: =B8&D8&E8&G8 -> 加拿大七店1301004170041冰镇 | B8: 加拿大七店 | C8: =D8&G8 -> 13010041冰镇 | D8: 13010041 | E8: 70041 | F8: 雪碧 | G8: 冰镇 | H8: 192 | I8: 0 | J8: =H8-I8 -> 192 | K8: 酒水饮料 | L8: 饮料
A9: =B9&D9&E9&G9 -> 加拿大七店700004077864份 | B9: 加拿大七店 | D9: 70000407 | E9: 7864 | F9: 肉汁奶酪薯条 | G9: 份 | H9: 100 | I9: 0 | J9: =H9-I9 -> 100 | K9: 小吃甜品 | L9: 小吃类
A10: =B10&D10&E10&G10 -> 加拿大七店90000413拼锅 | B10: 加拿大七店 | D10: 90000413 | F10: 冬阴功锅底 | G10: 拼锅 | H10: 331 | I10: 10 | J10: =H10-I10 -> 321 | K10: 锅底类 | L10: 拼锅类
A11: =B11&D11&E11&G11 -> 加拿大七店90000413四宫格 | B11: 加拿大七店 | C11: =D11&G11 -> 90000413四宫格 | D11: 90000413 | F11: 冬阴功锅底 | G11: 四宫格 | H11: 634 | I11: 6 | J11: =H11-I11 -> 628 | K11: 锅底类 | L11: 四宫格类
A12: =B12&D12&E12&G12 -> 加拿大七店70000769四宫格 | B12: 加拿大七店 | C12: =D12&G12 -> 70000769四宫格 | D12: 70000769 | F12: 寿喜锅底 | G12: 四宫格 | H12: 701 | I12: 11 | J12: =H12-I12 -> 690 | K12: 锅底类 | L12: 四宫格类
A13: =B13&D13&E13&G13 -> 加拿大七店70000769拼锅 | B13: 加拿大七店 | C13: =D13&G13 -> 70000769拼锅 | D13: 70000769 | F13: 寿喜锅底 | G13: 拼锅 | H13: 268 | I13: 7 | J13: =H13-I13 -> 261 | K13: 锅底类 | L13: 拼锅类
A14: =B14&D14&E14&G14 -> 加拿大七店7000064877308整份 | B14: 加拿大七店 | C14: =D14&G14 -> 70000648整份 | D14: 70000648 | E14: 77308 | F14: 澳洲青边鲍 | G14: 整份 | H14: 40 | I14: 1 | J14: =H14-I14 -> 39 | K14: 荤菜 | L14: 河/海鲜类
A15: =B15&D15&E15&G15 -> 加拿大七店1301004770047冰镇 | B15: 加拿大七店 | C15: =D15&G15 -> 13010047冰镇 | D15: 13010047 | E15: 70047 | F15: 椰汁 | G15: 冰镇 | H15: 88 | I15: 9 | J15: =H15-I15 -> 79 | K15: 酒水饮料 | L15: 饮料
A16: =B16&D16&E16&G16 -> 加拿大七店900017381003592整份 | B16: 加拿大七店 | C16: =D16&G16 -> 90001738整份 | D16: 90001738 | E16: 1003592 | F16: 炸馒头【金砖】 | G16: 整份 | H16: 1689 | I16: 6 | J16: =H16-I16 -> 1683 | K16: 火锅周边 | L16: 赠送及其他
A17: =B17&D17&E17&G17 -> 加拿大七店70002428拼锅 | B17: 加拿大七店 | C17: =D17&G17 -> 70002428拼锅 | D17: 70002428 | F17: 麻辣牛奶火锅 | G17: 拼锅 | H17: 306 | I17: 11 | J17: =H17-I17 -> 295 | K17: 锅底类 | L17: 拼锅类
A18: =B18&D18&E18&G18 -> 加拿大七店70002428四宫格 | B18: 加拿大七店 | D18: 70002428 | F18: 麻辣牛奶火锅 | G18: 四宫格 | H18: 630 | I18: 10 | J18: =H18-I18 -> 620 | K18: 锅底类 | L18: 四宫格类
A19: =B19&D19&E19&G19 -> 加拿大七店906009043251整份 | B19: 加拿大七店 | C19: =D19&G19 -> 9060090整份 | D19: 9060090 | E19: 43251 | F19: 港式鱼腐 | G19: 整份 | H19: 118 | I19: 0 | J19: =H19-I19 -> 118 | K19: 荤菜 | L19: 其他荤菜
A20: =B20&D20&E20&G20 -> 加拿大七店906009043252半份 | B20: 加拿大七店 | C20: =D20&G20 -> 9060090半份 | D20: 9060090 | E20: 43252 | F20: 港式鱼腐(半) | G20: 半份 | H20: 273 | I20: 1 | J20: =H20-I20 -> 272 | K20: 荤菜 | L20: 其他荤菜
A21: =B21&D21&E21&G21 -> 加拿大七店1001004440051整份 | B21: 加拿大七店 | C21: =D21&G21 -> 10010044整份 | D21: 10010044 | E21: 40051 | F21: 油条 | G21: 整份 | H21: 415 | I21: 5 | J21: =H21-I21 -> 410 | K21: 小吃甜品 | L21: 小吃类
A22: =B22&D22&E22&G22 -> 加拿大七店904036433429整份 | B22: 加拿大七店 | C22: =D22&G22 -> 9040364整份 | D22: 9040364 | E22: 33429 | F22: 芝士风味脆皮肠 | G22: 整份 | H22: 293 | I22: 1 | J22: =H22-I22 -> 292 | K22: 经典火锅菜 | L22: 经典火锅菜类
A23: =B23&D23&E23&G23 -> 加拿大七店1101037950485整份 | B23: 加拿大七店 | C23: =D23&G23 -> 11010379整份 | D23: 11010379 | E23: 50485 | F23: 乌冬面 | G23: 整份 | H23: 1050 | I23: 4 | J23: =H23-I23 -> 1046 | K23: 素菜 | L23: 豆面制品
A24: =B24&D24&E24&G24 -> 加拿大七店7000118278433整份 | B24: 加拿大七店 | D24: 70001182 | E24: 78433 | F24: Prime级去骨牛小排 | G24: 整份 | H24: 1315 | I24: 9 | J24: =H24-I24 -> 1306 | K24: 荤菜 | L24: 牛/羊肉
A25: =B25&D25&E25&G25 -> 加拿大七店1002002541025整份 | B25: 加拿大七店 | D25: 10020025 | E25: 41025 | F25: 冬瓜 | G25: 整份 | H25: 390 | I25: 1 | J25: =H25-I25 -> 389 | K25: 素菜 | L25: 根茎类
A26: =B26&D26&E26&G26 -> 加拿大七店1201000160001整份 | B26: 加拿大七店 | D26: 12010001 | E26: 60001 | F26: 自选小料/每位 | G26: 整份 | H26: 17793 | I26: 74 | J26: =H26-I26 -> 17719 | K26: 火锅周边 | L26: 自选调料
A27: =B27&D27&E27&G27 -> 加拿大七店1101003050055整份 | B27: 加拿大七店 | D27: 11010030 | E27: 50055 | F27: 长寿面 | G27: 整份 | H27: 247 | I27: 4 | J27: =H27-I27 -> 243 | K27: 火锅周边 | L27: 赠送及其他
A28: =B28&D28&E28&G28 -> 加拿大七店1002002771120份 | B28: 加拿大七店 | D28: 10020027 | E28: 71120 | F28: 山药 | G28: 份 | H28: 140 | I28: 0 | J28: =H28-I28 -> 140 | K28: 素菜 | L28: 根茎类
A29: =B29&D29&E29&G29 -> 加拿大七店901002130022半份 | B29: 加拿大七店 | D29: 9010021 | E29: 30022 | F29: 捞派羊肉(半) | G29: 半份 | H29: 239 | I29: 1 | J29: =H29-I29 -> 238 | K29: 经典火锅菜 | L29: 经典火锅菜类
A30: =B30&D30&E30&G30 -> 加拿大七店901002130021整份 | B30: 加拿大七店 | D30: 9010021 | E30: 30021 | F30: 捞派羊肉 | G30: 整份 | H30: 193 | I30: 1 | J30: =H30-I30 -> 192 | K30: 经典火锅菜 | L30: 经典火锅菜类
A31: =B31&D31&E31&G31 -> 加拿大七店903033032331整份 | B31: 加拿大七店 | D31: 9030330 | E31: 32331 | F31: 脆皖鱼 | G31: 整份 | H31: 179 | I31: 1 | J31: =H31-I31 -> 178 | K31: 荤菜 | L31: 河/海鲜类
A32: =B32&D32&E32&G32 -> 加拿大七店903033032332半份 | B32: 加拿大七店 | D32: 9030330 | E32: 32332 | F32: 脆皖鱼(半) | G32: 半份 | H32: 308 | I32: 3 | J32: =H32-I32 -> 305 | K32: 荤菜 | L32: 河/海鲜类
A33: =B33&D33&E33&G33 -> 加拿大七店1002002341023整份 | B33: 加拿大七店 | D33: 10020023 | E33: 41023 | F33: 茼蒿 | G33: 整份 | H33: 535 | I33: 2 | J33: =H33-I33 -> 533 | K33: 素菜 | L33: 蔬菜类
A34: =B34&D34&E34&G34 -> 加拿大七店1002002341024半份 | B34: 加拿大七店 | D34: 10020023 | E34: 41024 | F34: 茼蒿(半) | G34: 半份 | H34: 638 | I34: 4 | J34: =H34-I34 -> 634 | K34: 素菜 | L34: 蔬菜类
A35: =B35&D35&E35&G35 -> 加拿大七店1201000260002冰镇 | B35: 加拿大七店 | D35: 12010002 | E35: 60002 | F35: 柠檬冰红茶 341ML | G35: 冰镇 | H35: 134 | I35: 1 | J35: =H35-I35 -> 133 | K35: 酒水饮料 | L35: 饮料
... A40: =B40&D40&E40&G40 -> 加拿大七店7000120678510半份 | B40: 加拿大七店 | D40: 70001206 | E40: 78510 | F40: 8秒劲道油豆皮（半） | G40: 半份 | H40: 294 | I40: 0 | J40: =H40-I40 -> 294 | K40: 素菜 | L40: 豆面制品
A41: =B41&D41&E41&G41 -> 加拿大七店7000120678509整份 | B41: 加拿大七店 | C41: =D41&G41 -> 70001206整份 | D41: 70001206 | E41: 78509 | F41: 8秒劲道油豆皮 | G41: 整份 | H41: 180 | I41: 0 | J41: =H41-I41 -> 180 | K41: 素菜 | L41: 豆面制品
A42: =B42&D42&E42&G42 -> 加拿大七店1202004261045整份 | B42: 加拿大七店 | C42: =D42&G42 -> 12020042整份 | D42: 12020042 | E42: 61045 | F42: 未使用小料 | G42: 整份 | H42: 4355 | I42: 7 | J42: =H42-I42 -> 4348 | K42: 火锅周边 | L42: 赠送及其他
A43: =B43&D43&E43&G43 -> 加拿大七店7000169879583半份 | B43: 加拿大七店 | C43: =D43&G43 -> 70001698半份 | D43: 70001698 | E43: 79583 | F43: 手工现做牛筋丸（半） | G43: 半份 | H43: 245 | I43: 1 | J43: =H43-I43 -> 244 | K43: 荤菜 | L43: 丸滑类
A44: =B44&D44&E44&G44 -> 加拿大七店7000169879582整份 | B44: 加拿大七店 | C44: =D44&G44 -> 70001698整份 | D44: 70001698 | E44: 79582 | F44: 手工现做牛筋丸 | G44: 整份 | H44: 178 | I44: 0 | J44: =H44-I44 -> 178 | K44: 荤菜 | L44: 丸滑类
...

Sheet Sheet3
A2: 每月需更新数据
A3: 求和项:实际出品数据（出品数量-退菜数量）
A4: 检索 | B4: 汇总
A5: (空白)
A6: 1412000184001整份 | B6: 32
A7: 加拿大七店1301044570445冰镇 | B7: 156
A8: 加拿大七店906001343013整份 | B8: 958
A9: 加拿大七店110102621002693半份 | B9: 238
A10: 加拿大七店1101026250303整份 | B10: 925
A11: 加拿大七店1002013841184半份 | B11: 242
A12: 加拿大七店1002013841183整份 | B12: 83
A13: 加拿大七店1002001741017整份 | B13: 672
A14: 加拿大七店1301004170041冰镇 | B14: 192
A15: 加拿大七店700004077864份 | B15: 100
A16: 加拿大七店7000064877308整份 | B16: 39
A17: 加拿大七店902051831869磅 | B17: 1
... A262: 1304028473284常温 | B262: 3
A263: 130101471108213扎
A264: 910050181109547份
A265: 加拿大七店2601037008套餐 | B265: 907
A266: 加拿大七店910057161111214份 | B266: 696
A267: 加拿大七店910059501111493份 | B267: 3303
A268: 加拿大七店910057321111186瓶 | B268: 59
A269: 加拿大七店1002058041625整份 | B269: 84
A270: 加拿大七店1401008580055整份 | B270: 94
A271: 加拿大七店901014730175整份 | B271: 156
A272: 加拿大七店1010681单锅 | B272: 1
A273: 加拿大七店1310005四宫格 | B273: 328
A274: 1310005拼锅 | B274: 145
A275: 903049832583整份 | B275: 46
A276: 902051831869磅 | B276: 1
... A279: 1000000305套餐 | B279: 25
A280: 1310005单锅
A281: 910059741111526瓶
A282: 900002051001819个
A283: 900021311004528整份
A284: 910059091111487份
A285: 7000069377384整份
A286: 902026831273整份
A287: 总计 | B287: 128781

Sheet 计算
A1: 检索 | B1: 区域名称 | C1: 门店名称 | D1: 大类名称 | E1: 子类名称 | F1: 菜品编码 | G1: 菜品短编码 | H1: 菜品名称 | I1: 菜品名称（系统） | J1: 规格 | K1: 菜品单价 | L1: 菜品单位 | M1: 实收数量 | N1: 出品分量 | O1: 损耗 | P1: 物料单位 | Q1: 红火台理论量 | R1: 物料号 | S1: 物料描述 | T1: 物料用量 | U1: 差异 | V1: 备注1 | W1: 套餐 | X1: 备注 | Y1: 单位 | Z1: 差异绝对值
A2: =C2&F2&G2&J2 -> 加拿大七店1060061单锅 | B2: 加拿大 | C2: 加拿大七店 | D2: 锅底类 | E2: 锅底类 | F2: 1060061 | H2: 清油麻辣火锅 | I2: 清油麻辣火锅 | J2: 单锅 | K2: 28.95 | L2: 锅 | M2: =IFERROR(VLOOKUP(A2,Sheet3!$A:$B,2,0),0) -> 3 | N2: 1 | O2: 1 | Q2: =M2*N2*O2 -> 3 | R2: 3000759 | S2: =VLOOKUP(R2,'CA07-本月-盘点结果'!$B:$C,2,0) -> 清油底料（300G*40包/件） | T2: =VLOOKUP(R2,'CA07-本月-盘点结果'!B:I,8,0) -> 480 | U2: =T2-Q2-Q3-Q4-Q23-Q24-Q25-W2 -> -124.15 | W2: =325*0.3 -> 97.5 | X2: 少使用了97kg | Y2: 公斤 | Z2: 120.4
A3: =C3&F3&G3&J3 -> 加拿大七店1060061拼锅 | B3: 加拿大 | C3: 加拿大七店 | D3: 锅底类 | E3: 锅底类 | F3: 1060061 | H3: 清油麻辣火锅 | I3: 清油麻辣火锅 | J3: 拼锅 | K3: 14.95 | L3: 锅 | M3: =IFERROR(VLOOKUP(A3,Sheet3!$A:$B,2,0),0) -> 265 | N3: 0.5 | O3: 1 | Q3: =M3*N3*O3 -> 132.5 | R3: 3000759 | S3: =VLOOKUP(R3,'CA07-本月-盘点结果'!$B:$C,2,0) -> 清油底料（300G*40包/件） | Y3: 公斤 | Z3: 0
A4: =C4&F4&G4&J4 -> 加拿大七店1060061四宫格 | B4: 加拿大 | C4: 加拿大七店 | D4: 锅底类 | E4: 锅底类 | F4: 1060061 | H4: 清油麻辣火锅 | I4: 清油麻辣火锅 | J4: 四宫格 | K4: 5.95 | L4: 锅 | M4: =IFERROR(VLOOKUP(A4,Sheet3!$A:$B,2,0),0)+18 -> 507 | N4: 0.25 | O4: 1 | Q4: =M4*N4*O4 -> 126.75 | R4: 3000759 | S4: =VLOOKUP(R4,'CA07-本月-盘点结果'!$B:$C,2,0) -> 清油底料（300G*40包/件） | Y4: 公斤 | Z4: 0
A5: =C5&F5&G5&J5 -> 加拿大七店1060062单锅 | B5: 加拿大 | C5: 加拿大七店 | D5: 锅底类 | E5: 锅底类 | F5: 1060062 | H5: 三鲜猪骨火锅 | I5: 三鲜火锅 | J5: 单锅 | K5: 24.95 | L5: 锅 | M5: =IFERROR(VLOOKUP(A5,Sheet3!$A:$B,2,0),0) -> 46 | N5: 0.15 | O5: 1 | P5: 0.354 | Q5: =M5*N5*O5 -> 6.9 | R5: 1500882 | S5: =VLOOKUP(R5,'CA07-本月-盘点结果'!$B:$C,2,0) -> 三花淡奶（354ML*48瓶/箱） | T5: =VLOOKUP(R5,'CA07-本月-盘点结果'!B:I,8,0) -> 974 | U5: =T5-(Q5+Q6+Q7+Q186+Q187+Q188+Q189+Q190+Q191)/P5 -> 564.4661 | Y5: 瓶 | Z5: 9.82
A6: =C6&F6&G6&J6 -> 加拿大七店1060062拼锅 | B6: 加拿大 | C6: 加拿大七店 | D6: 锅底类 | E6: 锅底类 | F6: 1060062 | H6: 三鲜猪骨火锅 | I6: 三鲜火锅 | J6: 拼锅 | K6: 12.95 | L6: 锅 | M6: =IFERROR(VLOOKUP(A6,Sheet3!$A:$B,2,0),0) -> 1164 | N6: 0.075 | O6: 1 | P6: 0.354 | Q6: =M6*N6*O6 -> 87.3 | R6: 1500882 | S6: =VLOOKUP(R6,'CA07-本月-盘点结果'!$B:$C,2,0) -> 三花淡奶（354ML*48瓶/箱） | Y6: 瓶 | Z6: 0
A7: =C7&F7&G7&J7 -> 加拿大七店1060062四宫格 | B7: 加拿大 | C7: 加拿大七店 | D7: 锅底类 | E7: 锅底类 | F7: 1060062 | H7: 三鲜猪骨火锅 | I7: 三鲜火锅 | J7: 四宫格 | K7: 4.95 | L7: 锅 | M7: =IFERROR(VLOOKUP(A7,Sheet3!$A:$B,2,0),0) -> 1354 | N7: 0.0375 | O7: 1 | P7: 0.354 | Q7: =M7*N7*O7 -> 50.775 | R7: 1500882 | S7: =VLOOKUP(R7,'CA07-本月-盘点结果'!$B:$C,2,0) -> 三花淡奶（354ML*48瓶/箱） | Y7: 瓶 | Z7: 0
A8: =C8&F8&G8&J8 -> 加拿大七店1060063单锅 | B8: 加拿大 | C8: 加拿大七店 | D8: 锅底类 | E8: 锅底类 | F8: 1060063 | H8: 菌汤火锅 | I8: 菌汤火锅 | J8: 单锅 | K8: 24.95 | L8: 锅 | M8: =IFERROR(VLOOKUP(A8,Sheet3!$A:$B,2,0),0) -> 7 | N8: 0.42 | O8: 1 | Q8: =M8*N8*O8 -> 2.94 | R8: 4514602 | S8: =VLOOKUP(R8,'CA07-本月-盘点结果'!$B:$C,2,0) -> 菌汤火锅底料（105G*60袋/箱） | T8: =VLOOKUP(R8,'CA07-本月-盘点结果'!B:I,8,0) -> 214.2 | U8: =T8-Q8-Q9-Q10-W8 -> 41.025 | W8: =216*0.11 -> 23.76 | X8: 多使用41kg | Y8: 公斤 | Z8: 31.71
A9: =C9&F9&G9&J9 -> 加拿大七店1060063拼锅 | B9: 加拿大 | C9: 加拿大七店 | D9: 锅底类 | E9: 锅底类 | F9: 1060063 | H9: 菌汤火锅 | I9: 菌汤火锅 | J9: 拼锅 | K9: 12.95 | L9: 锅 | M9: =IFERROR(VLOOKUP(A9,Sheet3!$A:$B,2,0),0) -> 349 | N9: 0.21 | O9: 1 | Q9: =M9*N9*O9 -> 73.29 | R9: 4514602 | S9: =VLOOKUP(R9,'CA07-本月-盘点结果'!$B:$C,2,0) -> 菌汤火锅底料（105G*60袋/箱） | Y9: 公斤 | Z9: 0
A10: =C10&F10&G10&J10 -> 加拿大七店1060063四宫格 | B10: 加拿大 | C10: 加拿大七店 | D10: 锅底类 | E10: 锅底类 | F10: 1060063 | H10: 菌汤火锅 | I10: 菌汤火锅 | J10: 四宫格 | K10: 5.95 | L10: 锅 | M10: =IFERROR(VLOOKUP(A10,Sheet3!$A:$B,2,0),0) -> 697 | N10: 0.105 | O10: 1 | Q10: =M10*N10*O10 -> 73.185 | R10: 4514602 | S10: =VLOOKUP(R10,'CA07-本月-盘点结果'!$B:$C,2,0) -> 菌汤火锅底料（105G*60袋/箱） | Y10: 公斤 | Z10: 0
A11: =C11&F11&G11&J11 -> 加拿大七店1060064单锅 | B11: 加拿大 | C11: 加拿大七店 | D11: 锅底类 | E11: 锅底类 | F11: 1060064 | H11: 经典麻辣火锅 | I11: 经典麻辣火锅 | J11: 单锅 | K11: 36.95 | L11: 锅 | M11: =IFERROR(VLOOKUP(A11,Sheet3!$A:$B,2,0),0) -> 8 | N11: 1 | O11: 1 | Q11: =M11*N11*O11 -> 8 | R11: 3003393 | S11: =VLOOKUP(R11,'CA07-本月-盘点结果'!$B:$C,2,0) -> 清油麻辣火锅底料（250G*30包/件）_加拿大版 | T11: =VLOOKUP(R11,'CA07-本月-盘点结果'!B:I,8,0) -> 705 | U11: =T11-Q11-Q12-Q13 -> 5.25 | Y11: 公斤 | Z11: 17.25
A12: =C12&F12&G12&J12 -> 加拿大七店1060064拼锅 | B12: 加拿大 | C12: 加拿大七店 | D12: 锅底类 | E12: 锅底类 | F12: 1060064 | H12: 经典麻辣火锅 | I12: 经典麻辣火锅 | J12: 拼锅 | K12: 18.95 | L12: 锅 | M12: =IFERROR(VLOOKUP(A12,Sheet3!$A:$B,2,0),0) -> 777 | N12: 0.5 | O12: 1 | Q12: =M12*N12*O12 -> 388.5 | R12: 3003393 | S12: =VLOOKUP(R12,'CA07-本月-盘点结果'!$B:$C,2,0) -> 清油麻辣火锅底料（250G*30包/件）_加拿大版 | Y12: 公斤 | Z12: 0
A13: =C13&F13&G13&J13 -> 加拿大七店1060064四宫格 | B13: 加拿大 | C13: 加拿大七店 | D13: 锅底类 | E13: 锅底类 | F13: 1060064 | H13: 经典麻辣火锅 | I13: 经典麻辣火锅 | J13: 四宫格 | K13: 9.95 | L13: 锅 | M13: =IFERROR(VLOOKUP(A13,Sheet3!$A:$B,2,0),0) -> 1213 | N13: 0.25 | O13: 1 | Q13: =M13*N13*O13 -> 303.25 | R13: 3003393 | S13: =VLOOKUP(R13,'CA07-本月-盘点结果'!$B:$C,2,0) -> 清油麻辣火锅底料（250G*30包/件）_加拿大版 | Y13: 公斤 | Z13: 0
A14: =C14&F14&G14&J14 -> 加拿大七店1060066单锅 | B14: 加拿大 | C14: 加拿大七店 | D14: 锅底类 | E14: 锅底类 | F14: 1060066 | H14: 番茄火锅 | I14: 番茄火锅 | J14: 单锅 | K14: 24.95 | L14: 锅 | M14: =IFERROR(VLOOKUP(A14,Sheet3!$A:$B,2,0),0) -> 41 | N14: 1.2 | O14: 1 | Q14: =M14*N14*O14 -> 49.2 | R14: 3002745 | S14: =VLOOKUP(R14,'CA07-本月-盘点结果'!$B:$C,2,0) -> 番茄火锅底料（300G*40包/件，加拿大内用） | T14: =VLOOKUP(R14,'CA07-本月-盘点结果'!B:I,8,0) -> 2268 | U14: =T14-Q14-Q15-Q16-W14 -> 677.4 | W14: =444*0.3 -> 133.2 | X14: 多使用677kg | Y14: 公斤 | Z14: 626.4
A15: =C15&F15&G15&J15 -> 加拿大七店1060066拼锅 | B15: 加拿大 | C15: 加拿大七店 | D15: 锅底类 | E15: 锅底类 | F15: 1060066 | H15: 番茄火锅 | I15: 番茄火锅 | J15: 拼锅 | K15: 12.95 | L15: 锅 | M15: =IFERROR(VLOOKUP(A15,Sheet3!$A:$B,2,0),0) -> 1299 | N15: 0.6 | O15: 1 | Q15: =M15*N15*O15 -> 779.4 | R15: 3002745 | S15: =VLOOKUP(R15,'CA07-本月-盘点结果'!$B:$C,2,0) -> 番茄火锅底料（300G*40包/件，加拿大内用） | Y15: 公斤 | Z15: 0
A16: =C16&F16&G16&J16 -> 加拿大七店1060066四宫格 | B16: 加拿大 | C16: 加拿大七店 | D16: 锅底类 | E16: 锅底类 | F16: 1060066 | H16: 番茄火锅 | I16: 番茄火锅 | J16: 四宫格 | K16: 6.95 | L16: 锅 | M16: =IFERROR(VLOOKUP(A16,Sheet3!$A:$B,2,0),0)+35 -> 2096 | N16: 0.3 | O16: 1 | Q16: =M16*N16*O16 -> 628.8 | R16: 3002745 | S16: =VLOOKUP(R16,'CA07-本月-盘点结果'!$B:$C,2,0) -> 番茄火锅底料（300G*40包/件，加拿大内用） | Y16: 公斤 | Z16: 0
A17: =C17&F17&G17&J17 -> 加拿大七店1060115单锅 | B17: 加拿大 | C17: 加拿大七店 | D17: 锅底类 | E17: 锅底类 | F17: 1060115 | H17: 胡椒猪肚鸡火锅 | I17: 胡椒猪肚鸡火锅 | J17: 单锅 | K17: 40.95 | L17: 锅 | M17: =IFERROR(VLOOKUP(A17,Sheet3!$A:$B,2,0),0) -> 5 | N17: 0.2 | O17: 1 | P17: 2.2 | Q17: =M17*N17*O17 -> 1 | R17: 4504167 | S17: =VLOOKUP(R17,'CA07-本月-盘点结果'!$B:$C,2,0) -> 猪肚（LB） | T17: =VLOOKUP(R17,'CA07-本月-盘点结果'!B:I,8,0) -> 264 | U17: =T17-Q17*P17-Q18*P18-Q19*P19-Q135*P135-Q136*P136 -> 83.82 | Y17: 磅 | Z17: 115.94
A18: =C18&F18&G18&J18 -> 加拿大七店1060115四宫格 | B18: 加拿大 | C18: 加拿大七店 | D18: 锅底类 | E18: 锅底类 | F18: 1060115 | H18: 胡椒猪肚鸡火锅 | I18: 胡椒猪肚鸡火锅 | J18: 四宫格 | K18: 9.95 | L18: 锅 | M18: =IFERROR(VLOOKUP(A18,Sheet3!$A:$B,2,0),0) -> 670 | N18: 0.1 | O18: 1 | P18: 2.2 | Q18: =M18*N18*O18 -> 67 | R18: 4504167 | S18: =VLOOKUP(R18,'CA07-本月-盘点结果'!$B:$C,2,0) -> 猪肚（LB） | Y18: 磅 | Z18: 0
A19: =C19&F19&G19&J19 -> 加拿大七店1060115拼锅 | B19: 加拿大 | C19: 加拿大七店 | D19: 锅底类 | E19: 锅底类 | F19: 1060115 | H19: 胡椒猪肚鸡火锅 | I19: 胡椒猪肚鸡火锅 | J19: 拼锅 | K19: 18.95 | L19: 锅 | M19: =IFERROR(VLOOKUP(A19,Sheet3!$A:$B,2,0),0) -> 278 | N19: 0.05 | O19: 1 | P19: 2.2 | Q19: =M19*N19*O19 -> 13.9 | R19: 4504167 | S19: =VLOOKUP(R19,'CA07-本月-盘点结果'!$B:$C,2,0) -> 猪肚（LB） | Y19: 磅 | Z19: 0
A20: =C20&F20&G20&J20 -> 加拿大七店70000769四宫格 | B20: 加拿大 | C20: 加拿大七店 | D20: 锅底类 | E20: 锅底类 | F20: 70000769 | H20: 寿喜锅底 | I20: 寿喜锅底 | J20: 四宫格 | K20: 6.95 | L20: 锅 | M20: =IFERROR(VLOOKUP(A20,Sheet3!$A:$B,2,0),0) -> 690 | N20: 0.129 | O20: 1 | Q20: =M20*N20*O20 -> 89.01 | R20: 1501618 | S20: =VLOOKUP(R20,'CA07-本月-盘点结果'!$B:$C,2,0) -> 日式味淋MIRIN（20L/箱） | T20: =VLOOKUP(R20,'CA07-本月-盘点结果'!B:I,8,0) -> 185 | U20: =T20-Q20-Q21-Q22-W20 -> 24.524 | Y20: 升 | Z20: 19.98
A21: =C21&F21&G21&J21 -> 加拿大七店70000769单锅 | B21: 加拿大 | C21: 加拿大七店 | D21: 锅底类 | E21: 锅底类 | F21: 70000769 | H21: 寿喜锅底 | I21: 寿喜锅底 | J21: 单锅 | K21: 24.95 | L21: 锅 | M21: =IFERROR(VLOOKUP(A21,Sheet3!$A:$B,2,0),0) -> 8 | N21: 0.516 | O21: 1 | Q21: =M21*N21*O21 -> 4.128 | R21: 1501618 | S21: =VLOOKUP(R21,'CA07-本月-盘点结果'!$B:$C,2,0) -> 日式味淋MIRIN（20L/箱） | Y21: 升 | Z21: 0
A22: =C22&F22&G22&J22 -> 加拿大七店70000769拼锅 | B22: 加拿大 | C22: 加拿大七店 | D22: 锅底类 | E22: 锅底类 | F22: 70000769 | H22: 寿喜锅底 | I22: 寿喜锅底 | J22: 拼锅 | K22: 12.95 | L22: 锅 | M22: =IFERROR(VLOOKUP(A22,Sheet3!$A:$B,2,0),0) -> 261 | N22: 0.258 | O22: 1 | Q22: =M22*N22*O22 -> 67.338 | R22: 1501618 | S22: =VLOOKUP(R22,'CA07-本月-盘点结果'!$B:$C,2,0) -> 日式味淋MIRIN（20L/箱） | Y22: 升 | Z22: 0
A23: =C23&F23&G23&J23 -> 加拿大七店70002428四宫格 | B23: 加拿大 | C23: 加拿大七店 | D23: 锅底类 | E23: 锅底类 | F23: 70002428 | H23: 麻辣牛奶火锅 | I23: 麻辣牛奶火鍋 | J23: 四宫格 | K23: 5.95 | L23: 锅 | M23: =IFERROR(VLOOKUP(A23,Sheet3!$A:$B,2,0),0) -> 620 | N23: 0.2 | O23: 1 | P23: 20 | Q23: =M23*N23*O23 -> 124 | R23: 3000759 | S23: =VLOOKUP(R23,'CA07-本月-盘点结果'!$B:$C,2,0) -> 清油底料（300G*40包/件） | Y23: 公斤 | Z23: 0
A24: =C24&F24&G24&J24 -> 加拿大七店70002428拼锅 | B24: 加拿大 | C24: 加拿大七店 | D24: 锅底类 | E24: 锅底类 | F24: 70002428 | H24: 麻辣牛奶火锅 | I24: 麻辣牛奶火鍋 | J24: 拼锅 | K24: 11.95 | L24: 锅 | M24: =IFERROR(VLOOKUP(A24,Sheet3!$A:$B,2,0),0) -> 295 | N24: 0.4 | O24: 1 | P24: 20 | Q24: =M24*N24*O24 -> 118 | R24: 3000759 | S24: =VLOOKUP(R24,'CA07-本月-盘点结果'!$B:$C,2,0) -> 清油底料（300G*40包/件） | Y24: 公斤 | Z24: 0
A25: =C25&F25&G25&J25 -> 加拿大七店70002428单锅 | B25: 加拿大 | C25: 加拿大七店 | D25: 锅底类 | E25: 锅底类 | F25: 70002428 | H25: 麻辣牛奶火锅 | I25: 麻辣牛奶火鍋 | J25: 单锅 | K25: 24.95 | L25: 锅 | M25: =IFERROR(VLOOKUP(A25,Sheet3!$A:$B,2,0),0) -> 3 | N25: 0.8 | O25: 1 | P25: 20 | Q25: =M25*N25*O25 -> 2.4 | R25: 3000759 | S25: =VLOOKUP(R25,'CA07-本月-盘点结果'!$B:$C,2,0) -> 清油底料（300G*40包/件） | Y25: 公斤 | Z25: 0
A26: =C26&F26&G26&J26 -> 加拿大七店90000413单锅 | B26: 加拿大 | C26: 加拿大七店 | D26: 锅底类 | E26: 锅底类 | F26: 90000413 | H26: 冬阴功锅底 | I26: 冬阴功锅底 | J26: 单锅 | K26: 24.95 | L26: 锅 | M26: =IFERROR(VLOOKUP(A26,Sheet3!$A:$B,2,0),0) -> 7 | N26: 0.6 | O26: 1 | P26: 3 | Q26: =M26*N26*O26 -> 4.2 | R26: 4505163 | S26: =VLOOKUP(R26,'CA07-本月-盘点结果'!$B:$C,2,0) -> 冬阴功酱（PENTA，3KG*6包/件） | T26: =VLOOKUP(R26,'CA07-本月-盘点结果'!B:I,8,0) -> 55 | U26: =(T26*P26-Q26-Q27-Q28)/P26 -> -9.9 | Y26: 包 | Z26: 12.4
A27: =C27&F27&G27&J27 -> 加拿大七店90000413拼锅 | B27: 加拿大 | C27: 加拿大七店 | D27: 锅底类 | E27: 锅底类 | F27: 90000413 | H27: 冬阴功锅底 | I27: 冬阴功锅底 | J27: 拼锅 | K27: 11.95 | L27: 锅 | M27: =IFERROR(VLOOKUP(A27,Sheet3!$A:$B,2,0),0) -> 321 | N27: 0.3 | O27: 1 | P27: 3 | Q27: =M27*N27*O27 -> 96.3 | R27: 4505163 | S27: =VLOOKUP(R27,'CA07-本月-盘点结果'!$B:$C,2,0) -> 冬阴功酱（PENTA，3KG*6包/件） | Y27: 包 | Z27: 0
A28: =C28&F28&G28&J28 -> 加拿大七店90000413四宫格 | B28: 加拿大 | C28: 加拿大七店 | D28: 锅底类 | E28: 锅底类 | F28: 90000413 | H28: 冬阴功锅底 | I28: 冬阴功锅底 | J28: 四宫格 | K28: 5.95 | L28: 锅 | M28: =IFERROR(VLOOKUP(A28,Sheet3!$A:$B,2,0),0) -> 628 | N28: 0.15 | O28: 1 | P28: 3 | Q28: =M28*N28*O28 -> 94.2 | R28: 4505163 | S28: =VLOOKUP(R28,'CA07-本月-盘点结果'!$B:$C,2,0) -> 冬阴功酱（PENTA，3KG*6包/件） | Y28: 包 | Z28: 0
A29: =C29&F29&G29&J29 -> 加拿大七店90000659单锅 | B29: 加拿大 | C29: 加拿大七店 | D29: 锅底类 | E29: 锅底类 | F29: 90000659 | H29: 海底捞椰子鸡火锅 | I29: 椰子鸡火锅 | J29: 单锅 | K29: 39.95 | L29: 锅 | M29: =IFERROR(VLOOKUP(A29,Sheet3!$A:$B,2,0),0) -> 0 | N29: 0.14 | O29: 1 | Q29: =M29*N29*O29 -> 0 | R29: 4519135 | S29: =VLOOKUP(R29,'CA07-本月-盘点结果'!$B:$C,2,0) -> #N/A | T29: =VLOOKUP(R29,'CA07-本月-盘点结果'!B:I,8,0) -> #N/A | U29: =IFERROR(T29-Q29-Q30-Q31,0) -> 0 | Y29: #N/A | Z29: 0
A30: =C30&F30&G30&J30 -> 加拿大七店90000659拼锅 | B30: 加拿大 | C30: 加拿大七店 | D30: 锅底类 | E30: 锅底类 | F30: 90000659 | H30: 海底捞椰子鸡火锅 | I30: 椰子鸡火锅 | J30: 拼锅 | K30: 19.95 | L30: 锅 | M30: =IFERROR(VLOOKUP(A30,Sheet3!$A:$B,2,0),0) -> 0 | N30: 0.07 | O30: 1 | Q30: =M30*N30*O30 -> 0 | R30: 4519135 | S30: =VLOOKUP(R30,'CA07-本月-盘点结果'!$B:$C,2,0) -> #N/A | Y30: #N/A | Z30: 0
A31: =C31&F31&G31&J31 -> 加拿大七店90000659四宫格 | B31: 加拿大 | C31: 加拿大七店 | D31: 锅底类 | E31: 锅底类 | F31: 90000659 | H31: 海底捞椰子鸡火锅 | I31: 椰子鸡火锅 | J31: 四宫格 | K31: 9.95 | L31: 锅 | M31: =IFERROR(VLOOKUP(A31,Sheet3!$A:$B,2,0),0) -> 0 | N31: 0.035 | O31: 1 | Q31: =M31*N31*O31 -> 0 | R31: 4519135 | S31: =VLOOKUP(R31,'CA07-本月-盘点结果'!$B:$C,2,0) -> #N/A | Y31: #N/A | Z31: 0
A32: =C32&F32&G32&J32 -> 加拿大七店902007131071整份 | B32: 加拿大 | C32: 加拿大七店 | D32: 荤菜 | E32: 丸滑类 | F32: 9020071 | G32: 31071 | H32: 香菇猪肉丸 | I32: 香菇贡丸 | J32: 整份 | K32: 5.95 | L32: 份 | M32: =IFERROR(VLOOKUP(A32,Sheet3!$A:$B,2,0),0) -> 157 | N32: 0.1 | O32: 1 | P32: 2.2 | Q32: =M32*N32*O32 -> 15.7 | R32: 1500682 | S32: =VLOOKUP(R32,'CA07-本月-盘点结果'!$B:$C,2,0) -> 梅花猪肉（LB） | T32: =VLOOKUP(R32,'CA07-本月-盘点结果'!B:I,8,0) -> 84.69 | U32: =T32-Q32*P32-Q132*P132 -> 50.15 | Y32: 磅 | Z32: 29.59
A33: =C33&F33&G33&J33 -> 加拿大七店902024331247整份 | B33: 加拿大 | C33: 加拿大七店 | D33: 荤菜 | E33: 丸滑类 | F33: 9020243 | G33: 31247 | H33: 芝士牛肉丸 | I33: 芝士牛肉丸 | J33: 整份 | K33: 6.95 | L33: 份 | M33: =IFERROR(VLOOKUP(A33,Sheet3!$A:$B,2,0),0) -> 0 | N33: 0.1 | O33: 1 | Q33: =M33*N33*O33 -> 0 | S33: =VLOOKUP(R33,'CA07-本月-盘点结果'!$B:$C,2,0) -> #N/A | Y33: #N/A | Z33: 0
A34: =C34&F34&G34&J34 -> 加拿大七店902026331267整份 | B34: 加拿大 | C34: 加拿大七店 | D34: 荤菜 | E34: 丸滑类 | F34: 9020263 | G34: 31267 | H34: 蟹籽鱼包蛋 | I34: 蟹籽鱼包蛋 | J34: 整份 | K34: 8.95 | L34: 份 | M34: =IFERROR(VLOOKUP(A34,Sheet3!$A:$B,2,0),0) -> 0 | N34: 0.1 | O34: 1 | Q34: =M34*N34*O34 -> 0 | R34: 1500731 | S34: =VLOOKUP(R34,'CA07-本月-盘点结果'!$B:$C,2,0) -> #N/A | Y34: #N/A | Z34: 0
A35: =C35&F35&G35&J35 -> 加拿大七店902030531315整份 | B35: 加拿大 | C35: 加拿大七店 | D35: 荤菜 | E35: 丸滑类 | F35: 9020305 | G35: 31315 | H35: 鱼籽福袋 | I35: 鱼籽福袋 | J35: 整份 | K35: 9.95 | L35: 份 | M35: =IFERROR(VLOOKUP(A35,Sheet3!$A:$B,2,0),0) -> 119 | N35: 0.15 | O35: 1 | Q35: =M35*N35*O35 -> 17.85 | R35: 1501608 | S35: =VLOOKUP(R35,'CA07-本月-盘点结果'!$B:$C,2,0) -> 鲜虾福袋（1KG*10包/箱） | T35: =VLOOKUP(R35,'CA07-本月-盘点结果'!B:I,8,0) -> 69 | U35: =T35-Q35-Q36-W35 -> 25.15 | Y35: 公斤 | Z35: 13.58
A36: =C36&F36&G36&J36 -> 加拿大七店902030531316半份 | B36: 加拿大 | C36: 加拿大七店 | D36: 荤菜 | E36: 丸滑类 | F36: 9020305 | G36: 31316 | H36: 鱼籽福袋(半） | I36: 鱼籽福袋 | J36: 半份 | K36: 5.95 | L36: 份 | M36: =IFERROR(VLOOKUP(A36,Sheet3!$A:$B,2,0),0) -> 260 | N36: 0.1 | O36: 1 | Q36: =M36*N36*O36 -> 26 | R36: 1501608 | S36: =VLOOKUP(R36,'CA07-本月-盘点结果'!$B:$C,2,0) -> 鲜虾福袋（1KG*10包/箱） | T36: =VLOOKUP(R36,'CA07-本月-盘点结果'!B:I,8,0) -> 69 | Y36: 公斤 | Z36: 0
A37: =C37&F37&G37&J37 -> 加拿大七店700009771004157半份 | B37: 加拿大 | C37: 加拿大七店 | D37: 荤菜 | E37: 丸滑类 | F37: 70000977 | G37: 1004157 | H37: 脆爽Q弹竹荪虾滑(半) | I37: 脆爽Q弹竹荪虾滑 | J37: 半份 | K37: 9.95 | L37: 份 | M37: =IFERROR(VLOOKUP(A37,Sheet3!$A:$B,2,0),0) -> 0 | N37: 0.09 | O37: 1 | Q37: =M37*N37*O37 -> 0 | R37: 1501633 | S37: =VLOOKUP(R37,'CA07-本月-盘点结果'!$B:$C,2,0) -> 竹笙（1.125KG*4包/箱） | Y37: 公斤 | Z37: 0
A38: =C38&F38&G38&J38 -> 加拿大七店1003023642239整份 | B38: 加拿大 | C38: 加拿大七店 | D38: 素菜 | E38: 菌类 | F38: 10030236 | G38: 42239 | H38: 竹笙 | I38: 整份 | J38: 整份 | K38: 14.95 | L38: 份 | M38: =IFERROR(VLOOKUP(A38,Sheet3!$A:$B,2,0),0) -> 310 | N38: 0.13 | O38: 1 | Q38: =M38*N38*O38 -> 40.3 | R38: 1501633 | S38: =VLOOKUP(R38,'CA07-本月-盘点结果'!$B:$C,2,0) -> 竹笙（1.125KG*4包/箱） | T38: =VLOOKUP(R38,'CA07-本月-盘点结果'!B:I,8,0) -> 17.275 | U38: =T38-Q38/5 -> 9.215 | Y38: 公斤 | Z38: 10.03
A39: =C39&F39&G39&J39 -> 加拿大七店9000042997732份 | B39: 加拿大 | C39: 加拿大七店 | D39: 荤菜 | E39: 丸滑类 | F39: 90000429 | G39: 97732 | H39: 糯米鱼豆腐 | I39: 糯米鱼豆腐 | J39: 份 | K39: 5.95 | L39: 份 | M39: =IFERROR(VLOOKUP(A39,Sheet3!$A:$B,2,0),0) -> 417 | N39: 0.09 | O39: 1 | Q39: =M39*N39*O39 -> 37.53 | R39: 4513296 | S39: =VLOOKUP(R39,'CA07-本月-盘点结果'!$B:$C,2,0) -> 麻薯（2.5KG*4包/箱） | T39: =VLOOKUP(R39,'CA07-本月-盘点结果'!B:I,8,0) -> 32.5 | U39: =T39-Q39 -> -5.03 | Y39: #N/A | Z39: #N/A
A40: =C40&F40&G40&J40 -> 加拿大七店903001932019整份 | B40: 加拿大 | C40: 加拿大七店 | D40: 荤菜 | E40: 河/海鲜类 | F40: 9030019 | G40: 32019 | H40: 冰鲜白虾 | I40: 冻虾 | J40: 整份 | K40: 9.95 | L40: 份 | M40: =IFERROR(VLOOKUP(A40,Sheet3!$A:$B,2,0),0) -> 155 | N40: 0.28 | O40: 1 | P40: 2.2 | Q40: =M40*N40*O40 -> 43.4 | R40: 1500703 | S40: =VLOOKUP(R40,'CA07-本月-盘点结果'!$B:$C,2,0) -> 带头南美白虾（30-40，4LB*6包/箱 ） | T40: =VLOOKUP(R40,'CA07-本月-盘点结果'!B:I,8,0) -> 588 | U40: =T40-Q40*P40-Q41*P41-W40*P40*O40-Q197*P197-Q198*P198-Q199*P199 -> 444.472 | Y40: 磅 | Z40: 65.71
...

Sheet BI套餐
A1: 月份 | B1: 国家 | C1: 门店名称 | D1: 销售模式 | E1: 大类名称 | F1: 小类名称 | G1: 套餐编码 | H1: 套餐名称 | I1: 套餐规格 | J1: 套餐单价 | K1: 菜品编码 | L1: 菜品名称 | M1: 菜品规格名称 | N1: 菜品单价 | O1: 菜品单位 | P1: 出品数量 | Q1: 出品金额 | R1: 退菜数量 | S1: 退菜金额 | T1: 应收数量 | U1: 应收金额 | V1: 套餐折扣 | W1: 实收金额 | X1: 销售产品净收入 | Y1: 税额 | Z1: 净额 | AA1: 实际出品数量（出品数量-退菜数量）
A2: 202505 | B2: 加拿大 | C2: 加拿大七店 | D2: 堂食 | E2: 套餐 | F2: 套餐类 | G2: 03010184 | H2: 儿童套餐 | I2: 整份 | J2: 10.95 | K2: 09030119 | L2: 捞派巴沙鱼片 | M2: 整份 | N2: 4.78 | O2: 克 | P2: 656 | Q2: 3138.96 | R2: 6 | S2: 28.71 | T2: 650 | U2: 3110.25 | V2: 0.60696766 | W2: 1887.8212 | X2: 1879.6015 | Y2: 89.509379 | Z2: 1790.0921
A3: 202505 | B3: 加拿大 | C3: 加拿大七店 | D3: 堂食 | E3: 套餐 | F3: 套餐类 | G3: 03010184 | H3: 儿童套餐 | I3: 整份 | J3: 10.95 | K3: 09040055 | L3: 午餐肉 | M3: 整份 | N3: 6.97 | O3: 个 | P3: 656 | Q3: 4575.6 | R3: 6 | S3: 41.85 | T3: 650 | U3: 4533.75 | V3: 0.60696766 | W3: 2751.8396 | X3: 2739.8579 | Y3: 130.47605 | Z3: 2609.3819
A4: 202505 | B4: 加拿大 | C4: 加拿大七店 | D4: 堂食 | E4: 套餐 | F4: 套餐类 | G4: 03010184 | H4: 儿童套餐 | I4: 整份 | J4: 10.95 | K4: 09040063 | L4: 鹌鹑蛋 | M4: 整份 | N4: 1.96 | O4: 个 | P4: 656 | Q4: 1288.056 | R4: 6 | S4: 11.781 | T4: 650 | U4: 1276.275 | V4: 0.60696766 | W4: 774.65765 | X4: 771.28474 | Y4: 36.729711 | Z4: 734.55503
A5: 202505 | B5: 加拿大 | C5: 加拿大七店 | D5: 堂食 | E5: 套餐 | F5: 套餐类 | G5: 03010184 | H5: 儿童套餐 | I5: 整份 | J5: 10.95 | K5: 09040065 | L5: 蟹味棒 | M5: 整份 | N5: 3.28 | O5: 个 | P5: 656 | Q5: 2153.976 | R5: 6 | S5: 19.701 | T5: 650 | U5: 2134.275 | V5: 0.60696766 | W5: 1295.4359 | X5: 1289.7955 | Y5: 61.421953 | Z5: 1228.3735
A6: 202505 | B6: 加拿大 | C6: 加拿大七店 | D6: 堂食 | E6: 套餐 | F6: 套餐类 | G6: 03010184 | H6: 儿童套餐 | I6: 整份 | J6: 10.95 | K6: 10020069 | L6: 菠菜 | M6: 整份 | N6: 1.03 | O6: 克 | P6: 656 | Q6: 677.976 | R6: 6 | S6: 6.201 | T6: 650 | U6: 671.775 | V6: 0.60696766 | W6: 407.7457 | X6: 405.97035 | Y6: 19.332903 | Z6: 386.63745
A7: 202505 | B7: 加拿大 | C7: 加拿大七店 | D7: 堂食 | E7: 套餐 | F7: 套餐类 | G7: 03010184 | H7: 儿童套餐 | I7: 整份 | J7: 10.95 | K7: 11010086 | L7: 生面条 | M7: 整份 | N7: - | O7: 克 | P7: 656 | Q7: - | R7: 6 | S7: - | T7: 650 | U7: - | V7: 0.60696766 | W7: - | X7: 0 | Y7: 0 | Z7: 0
A8: 202505 | B8: 加拿大 | C8: 加拿大七店 | D8: 堂食 | E8: 套餐 | F8: 套餐类 | G8: 1000000303 | H8: 超值单人套餐（2人份） | I8: 套餐 | J8: 33.9 | K8: 01010106 | L8: 清水火锅 | M8: 四宫格 | N8: 0 | O8: 锅 | P8: 348 | Q8: 0 | R8: 6 | S8: 0 | T8: 342 | U8: 0 | V8: 1.0713018 | W8: 0 | X8: 0 | Y8: 0 | Z8: 0
A9: 202505 | B9: 加拿大 | C9: 加拿大七店 | D9: 堂食 | E9: 套餐 | F9: 套餐类 | G9: 1000000303 | H9: 超值单人套餐（2人份） | I9: 套餐 | J9: 33.9 | K9: 01060061 | L9: 清油麻辣火锅 | M9: 四宫格 | N9: 7.95 | O9: 锅 | P9: 73 | Q9: 580.35 | R9: 2 | S9: 15.9 | T9: 71 | U9: 564.45 | V9: 1.0713018 | W9: 604.69633 | X9: 631.14 | Y9: 30.02 | Z9: 601.12
A10: 202505 | B10: 加拿大 | C10: 加拿大七店 | D10: 堂食 | E10: 套餐 | F10: 套餐类 | G10: 1000000303 | H10: 超值单人套餐（2人份） | I10: 套餐 | J10: 33.9 | K10: 01060062 | L10: 三鲜猪骨火锅 | M10: 四宫格 | N10: 6.95 | O10: 锅 | P10: 105 | Q10: 729.75 | R10: 1 | S10: 6.95 | T10: 104 | U10: 722.8 | V10: 1.0713018 | W10: 774.33698 | X10: 820.09 | Y10: 39.1 | Z10: 780.99
A11: 202505 | B11: 加拿大 | C11: 加拿大七店 | D11: 堂食 | E11: 套餐 | F11: 套餐类 | G11: 1000000303 | H11: 超值单人套餐（2人份） | I11: 套餐 | J11: 33.9 | K11: 01060063 | L11: 菌汤火锅 | M11: 四宫格 | N11: 6.95 | O11: 锅 | P11: 62 | Q11: 430.9 | R11: 0 | S11: 0 | T11: 62 | U11: 430.9 | V11: 1.0713018 | W11: 461.62397 | X11: 489.25 | Y11: 23.29 | Z11: 465.96
A12: 202505 | B12: 加拿大 | C12: 加拿大七店 | D12: 堂食 | E12: 套餐 | F12: 套餐类 | G12: 1000000303 | H12: 超值单人套餐（2人份） | I12: 套餐 | J12: 33.9 | K12: 01060066 | L12: 番茄火锅 | M12: 四宫格 | N12: 6.95 | O12: 锅 | P12: 108 | Q12: 750.6 | R12: 3 | S12: 20.85 | T12: 105 | U12: 729.75 | V12: 1.0713018 | W12: 781.78252 | X12: 826.89 | Y12: 39.42 | Z12: 787.47
A13: 202505 | B13: 加拿大 | C13: 加拿大七店 | D13: 堂食 | E13: 套餐 | F13: 套餐类 | G13: 1000000303 | H13: 超值单人套餐（2人份） | I13: 套餐 | J13: 33.9 | K13: 10020113 | L13: 粉丝 | M13: 整份 | N13: 5.95 | O13: 份 | P13: 94 | Q13: 559.3 | R13: 2 | S13: 11.9 | T13: 92 | U13: 547.4 | V13: 1.0713018 | W13: 586.43063 | X13: 591.98 | Y13: 28.3 | Z13: 563.68
A14: 202505 | B14: 加拿大 | C14: 加拿大七店 | D14: 堂食 | E14: 套餐 | F14: 套餐类 | G14: 1000000303 | H14: 超值单人套餐（2人份） | I14: 套餐 | J14: 33.9 | K14: 11010262 | L14: 白米饭 | M14: 整份 | N14: 1.5 | O14: 碗 | P14: 54 | Q14: 81 | R14: 0 | S14: 0 | T14: 54 | U14: 81 | V14: 1.0713018 | W14: 86.77545 | X14: 102.63 | Y14: 4.93 | Z14: 97.7
A15: 202505 | B15: 加拿大 | C15: 加拿大七店 | D15: 堂食 | E15: 套餐 | F15: 套餐类 | G15: 1000000303 | H15: 超值单人套餐（2人份） | I15: 套餐 | J15: 33.9 | K15: 12010006 | L15: 自选饮料 | M15: 位 | N15: 3.99 | O15: 位 | P15: 348 | Q15: 1388.52 | R15: 6 | S15: 23.94 | T15: 342 | U15: 1364.58 | V15: 1.0713018 | W15: 1461.8771 | X15: 1541.1 | Y15: 73.33 | Z15: 1467.77
A16: 202505 | B16: 加拿大 | C16: 加拿大七店 | D16: 堂食 | E16: 套餐 | F16: 套餐类 | G16: 1000000303 | H16: 超值单人套餐（2人份） | I16: 套餐 | J16: 33.9 | K16: 26010234 | L16: 套餐拼盘 | M16: 整份 | N16: 0 | O16: 份 | P16: 348 | Q16: 0 | R16: 6 | S16: 0 | T16: 342 | U16: 0 | V16: 1.0713018 | W16: 0 | X16: 0 | Y16: 0 | Z16: 0
A17: 202505 | B17: 加拿大 | C17: 加拿大七店 | D17: 堂食 | E17: 套餐 | F17: 套餐类 | G17: 1000000303 | H17: 超值单人套餐（2人份） | I17: 套餐 | J17: 33.9 | K17: 91003653 | L17: 双色营养面 | M17: 整份 | N17: 4.95 | O17: 份 | P17: 200 | Q17: 990 | R17: 4 | S17: 19.8 | T17: 196 | U17: 970.2 | V17: 1.0713018 | W17: 1039.3771 | X17: 1080.54 | Y17: 51.77 | Z17: 1028.77
A18: 202505 | B18: 加拿大 | C18: 加拿大七店 | D18: 堂食 | E18: 套餐 | F18: 套餐类 | G18: 1000000304 | H18: 超值单人套餐（3人份） | I18: 套餐 | J18: 50.85 | K18: 01010106 | L18: 清水火锅 | M18: 四宫格 | N18: 0 | O18: 锅 | P18: 36 | Q18: 0 | R18: 1 | S18: 0 | T18: 35 | U18: 0 | V18: 1.0631403 | W18: 0 | X18: 0 | Y18: 0 | Z18: 0
A19: 202505 | B19: 加拿大 | C19: 加拿大七店 | D19: 堂食 | E19: 套餐 | F19: 套餐类 | G19: 1000000304 | H19: 超值单人套餐（3人份） | I19: 套餐 | J19: 50.85 | K19: 01060061 | L19: 清油麻辣火锅 | M19: 四宫格 | N19: 7.95 | O19: 锅 | P19: 19 | Q19: 151.05 | R19: 0 | S19: 0 | T19: 19 | U19: 151.05 | V19: 1.0631403 | W19: 160.58734 | X19: 166.42 | Y19: 7.96 | Z19: 158.46
... A47: 202505 | B47: 加拿大 | C47: 加拿大七店 | D47: 堂食 | E47: 套餐 | F47: 套餐类 | G47: 2601037008 | H47: 超值单人套餐 | I47: 套餐 | J47: 16.95 | K47: 91003653 | L47: 双色营养面 | M47: 整份 | N47: 4.95 | O47: 份 | P47: 567 | Q47: 2806.65 | R47: 13 | S47: 64.35 | T47: 554 | U47: 2742.3 | V47: 1.0748414 | W47: 2947.5376 | X47: 3025.39 | Y47: 142.62 | Z47: 2882.77
AA85: =P85-R85 -> 0
AA86: =P86-R86 -> 0
AA87: =P87-R87 -> 0
AA88: =P88-R88 -> 0
AA89: =P89-R89 -> 0
AA90: =P90-R90 -> 0
AA91: =P91-R91 -> 0
AA92: =P92-R92 -> 0
AA93: =P93-R93 -> 0
AA94: =P94-R94 -> 0
AA95: =P95-R95 -> 0
